Workbook

Sheet Country-Vehicle Progress
A1: Country | B1: Ethiopia | D1: Nigeria | F1: India
A2: Vehicle | B2: Salt | D2: Bouillon | F2: Rice
A3: Wealth | B3: Overall | C3: Quintile | D3: Overall | E3: Quintile | F3: Overall | G3: Quintile
A4: Data need
A5: Vehicle consumption by WRA -- any | B5: =IF(COUNTIFS('Country-Vehicle Extraction'!$A$2:$A$1024, B$1, 'Country-Vehicle Extraction'!$B$2:$B$1024, B$2, 'Country-Vehicle Extraction'!$C$2:$C$1024, "All", 'Country-Vehicle Extraction'!$D$2:$D$1024, $A5, 'Country-Vehicle Extraction'!$I$2:$I$1024, "<>") = 0, "Missing", "Complete") -> Complete | C5: =IF(COUNTIFS('Country-Vehicle Extraction'!$A$2:$A$1024, B$1, 'Country-Vehicle Extraction'!$B$2:$B$1024, B$2, 'Country-Vehicle Extraction'!$C$2:$C$1024, "<>All", 'Country-Vehicle Extraction'!D$2:D$1024, $A5, 'Country-Vehicle Extraction'!$I$2:$I$1024, "<>") = 0, "Missing", "Complete") -> Complete | D5: =IF(COUNTIFS('Country-Vehicle Extraction'!$A$2:$A$1024, D$1, 'Country-Vehicle Extraction'!$B$2:$B$1024, D$2, 'Country-Vehicle Extraction'!$C$2:$C$1024, "All", 'Country-Vehicle Extraction'!$D$2:$D$1024, $A5, 'Country-Vehicle Extraction'!$I$2:$I$1024, "<>") = 0, "Missing", "Complete") -> Complete | E5: =IF(COUNTIFS('Country-Vehicle Extraction'!$A$2:$A$1024, D$1, 'Country-Vehicle Extraction'!$B$2:$B$1024, D$2, 'Country-Vehicle Extraction'!$C$2:$C$1024, "<>All", 'Country-Vehicle Extraction'!$D$2:$D$1024, $A5, 'Country-Vehicle Extraction'!$I$2:$I$1024, "<>") = 0, "Missing", "Complete") -> Complete | F5: Microdata: HCES | G5: Microdata: HCES
A6: Vehicle consumption by WRA -- amount | B6: =IF(COUNTIFS('Country-Vehicle Extraction'!$A$2:$A$1024, B$1, 'Country-Vehicle Extraction'!$B$2:$B$1024, B$2, 'Country-Vehicle Extraction'!$C$2:$C$1024, "All", 'Country-Vehicle Extraction'!$D$2:$D$1024, $A6, 'Country-Vehicle Extraction'!$I$2:$I$1024, "<>") = 0, "Missing", "Complete") -> Complete | C6: =IF(COUNTIFS('Country-Vehicle Extraction'!$A$2:$A$1024, B$1, 'Country-Vehicle Extraction'!$B$2:$B$1024, B$2, 'Country-Vehicle Extraction'!$C$2:$C$1024, "<>All", 'Country-Vehicle Extraction'!D$2:D$1024, $A6, 'Country-Vehicle Extraction'!$I$2:$I$1024, "<>") = 0, "Missing", "Complete") -> Complete | D6: =IF(COUNTIFS('Country-Vehicle Extraction'!$A$2:$A$1024, D$1, 'Country-Vehicle Extraction'!$B$2:$B$1024, D$2, 'Country-Vehicle Extraction'!$C$2:$C$1024, "All", 'Country-Vehicle Extraction'!$D$2:$D$1024, $A6, 'Country-Vehicle Extraction'!$I$2:$I$1024, "<>") = 0, "Missing", "Complete") -> Complete | E6: =IF(COUNTIFS('Country-Vehicle Extraction'!$A$2:$A$1024, D$1, 'Country-Vehicle Extraction'!$B$2:$B$1024, D$2, 'Country-Vehicle Extraction'!$C$2:$C$1024, "<>All", 'Country-Vehicle Extraction'!$D$2:$D$1024, $A6, 'Country-Vehicle Extraction'!$I$2:$I$1024, "<>") = 0, "Missing", "Complete") -> Complete | F6: Microdata: HCES | G6: Microdata: HCES
A7: Vehicle consumption by U5 children -- any | B7: =IF(COUNTIFS('Country-Vehicle Extraction'!$A$2:$A$1024, B$1, 'Country-Vehicle Extraction'!$B$2:$B$1024, B$2, 'Country-Vehicle Extraction'!$C$2:$C$1024, "All", 'Country-Vehicle Extraction'!$D$2:$D$1024, $A7, 'Country-Vehicle Extraction'!$I$2:$I$1024, "<>") = 0, "Missing", "Complete") -> Complete | C7: =IF(COUNTIFS('Country-Vehicle Extraction'!$A$2:$A$1024, B$1, 'Country-Vehicle Extraction'!$B$2:$B$1024, B$2, 'Country-Vehicle Extraction'!$C$2:$C$1024, "<>All", 'Country-Vehicle Extraction'!D$2:D$1024, $A7, 'Country-Vehicle Extraction'!$I$2:$I$1024, "<>") = 0, "Missing", "Complete") -> Complete | D7: =IF(COUNTIFS('Country-Vehicle Extraction'!$A$2:$A$1024, D$1, 'Country-Vehicle Extraction'!$B$2:$B$1024, D$2, 'Country-Vehicle Extraction'!$C$2:$C$1024, "All", 'Country-Vehicle Extraction'!$D$2:$D$1024, $A7, 'Country-Vehicle Extraction'!$I$2:$I$1024, "<>") = 0, "Missing", "Complete") -> Complete | E7: =IF(COUNTIFS('Country-Vehicle Extraction'!$A$2:$A$1024, D$1, 'Country-Vehicle Extraction'!$B$2:$B$1024, D$2, 'Country-Vehicle Extraction'!$C$2:$C$1024, "<>All", 'Country-Vehicle Extraction'!$D$2:$D$1024, $A7, 'Country-Vehicle Extraction'!$I$2:$I$1024, "<>") = 0, "Missing", "Complete") -> Complete | F7: Microdata: HCES | G7: Microdata: HCES
A8: Vehicle consumption by U5 children -- amount | B8: =IF(COUNTIFS('Country-Vehicle Extraction'!$A$2:$A$1024, B$1, 'Country-Vehicle Extraction'!$B$2:$B$1024, B$2, 'Country-Vehicle Extraction'!$C$2:$C$1024, "All", 'Country-Vehicle Extraction'!$D$2:$D$1024, $A8, 'Country-Vehicle Extraction'!$I$2:$I$1024, "<>") = 0, "Missing", "Complete") -> Complete | C8: =IF(COUNTIFS('Country-Vehicle Extraction'!$A$2:$A$1024, B$1, 'Country-Vehicle Extraction'!$B$2:$B$1024, B$2, 'Country-Vehicle Extraction'!$C$2:$C$1024, "<>All", 'Country-Vehicle Extraction'!D$2:D$1024, $A8, 'Country-Vehicle Extraction'!$I$2:$I$1024, "<>") = 0, "Missing", "Complete") -> Complete | D8: =IF(COUNTIFS('Country-Vehicle Extraction'!$A$2:$A$1024, D$1, 'Country-Vehicle Extraction'!$B$2:$B$1024, D$2, 'Country-Vehicle Extraction'!$C$2:$C$1024, "All", 'Country-Vehicle Extraction'!$D$2:$D$1024, $A8, 'Country-Vehicle Extraction'!$I$2:$I$1024, "<>") = 0, "Missing", "Complete") -> Complete | E8: =IF(COUNTIFS('Country-Vehicle Extraction'!$A$2:$A$1024, D$1, 'Country-Vehicle Extraction'!$B$2:$B$1024, D$2, 'Country-Vehicle Extraction'!$C$2:$C$1024, "<>All", 'Country-Vehicle Extraction'!$D$2:$D$1024, $A8, 'Country-Vehicle Extraction'!$I$2:$I$1024, "<>") = 0, "Missing", "Complete") -> Complete | F8: Microdata: HCES | G8: Microdata: HCES
A9: Vehicle "fortifiability" (essentially amount industrially produced) | B9: =IF(COUNTIFS('Country-Vehicle Extraction'!$A$2:$A$1024, B$1, 'Country-Vehicle Extraction'!$B$2:$B$1024, B$2, 'Country-Vehicle Extraction'!$C$2:$C$1024, "All", 'Country-Vehicle Extraction'!$D$2:$D$1024, $A9, 'Country-Vehicle Extraction'!$I$2:$I$1024, "<>") = 0, "Missing", "Complete") -> Complete | C9: =IF(COUNTIFS('Country-Vehicle Extraction'!$A$2:$A$1024, B$1, 'Country-Vehicle Extraction'!$B$2:$B$1024, B$2, 'Country-Vehicle Extraction'!$C$2:$C$1024, "<>All", 'Country-Vehicle Extraction'!D$2:D$1024, $A9, 'Country-Vehicle Extraction'!$I$2:$I$1024, "<>") = 0, "Missing", "Complete") -> Complete | D9: =IF(COUNTIFS('Country-Vehicle Extraction'!$A$2:$A$1024, D$1, 'Country-Vehicle Extraction'!$B$2:$B$1024, D$2, 'Country-Vehicle Extraction'!$C$2:$C$1024, "All", 'Country-Vehicle Extraction'!$D$2:$D$1024, $A9, 'Country-Vehicle Extraction'!$I$2:$I$1024, "<>") = 0, "Missing", "Complete") -> Complete | E9: =IF(COUNTIFS('Country-Vehicle Extraction'!$A$2:$A$1024, D$1, 'Country-Vehicle Extraction'!$B$2:$B$1024, D$2, 'Country-Vehicle Extraction'!$C$2:$C$1024, "<>All", 'Country-Vehicle Extraction'!$D$2:$D$1024, $A9, 'Country-Vehicle Extraction'!$I$2:$I$1024, "<>") = 0, "Missing", "Complete") -> Complete | F9: =IF(COUNTIFS('Country-Vehicle Extraction'!$A$2:$A$1024, F$1, 'Country-Vehicle Extraction'!$B$2:$B$1024, F$2, 'Country-Vehicle Extraction'!$C$2:$C$1024, "All", 'Country-Vehicle Extraction'!$D$2:$D$1024, $A9, 'Country-Vehicle Extraction'!$I$2:$I$1024, "<>") = 0, "Missing", "Complete") -> Complete | G9: Microdata: HCES

Sheet Country-Vehicle Extraction
A1: Country | B1: Vehicle | C1: Quintile | D1: Data need | E1: Data point name | F1: Units | G1: Year | H1: Data source | I1: Value | J1: CI | K1: SE | L1: Notes
A2: Ethiopia | B2: Salt | C2: All | D2: Vehicle consumption by WRA -- any | E2: percentage | F2: % | H2: EPHI data sent by Andy Garcia | I2: 0.97 | L2: Total population (?), not WRA specifically
A3: Ethiopia | B3: Salt | C3: Lowest | D3: Vehicle consumption by WRA -- any | E3: percentage | F3: % | I3: 0.97 | L3: Not stratified by wealth quintile
A4: Ethiopia | B4: Salt | C4: Second | D4: Vehicle consumption by WRA -- any | E4: percentage | F4: % | I4: 0.97
A5: Ethiopia | B5: Salt | C5: Middle | D5: Vehicle consumption by WRA -- any | E5: percentage | F5: % | I5: 0.97
A6: Ethiopia | B6: Salt | C6: Fourth | D6: Vehicle consumption by WRA -- any | E6: percentage | F6: % | I6: 0.97
A7: Ethiopia | B7: Salt | C7: Highest | D7: Vehicle consumption by WRA -- any | E7: percentage | F7: % | I7: 0.97
A8: Ethiopia | B8: Salt | C8: All | D8: Vehicle consumption by WRA -- amount | E8: mean | F8: g/day | H8: EPHI data sent by Andy Garcia | I8: 7.1 | L8: 2022 National Nutrition Survey; Total population (?), not WRA specifically
A9: Ethiopia | B9: Salt | C9: Lowest | D9: Vehicle consumption by WRA -- amount | E9: mean | F9: g/day | H9: EPHI data sent by Andy Garcia | I9: 7.1
A10: Ethiopia | B10: Salt | C10: Second | D10: Vehicle consumption by WRA -- amount | E10: mean | F10: g/day | H10: EPHI data sent by Andy Garcia | I10: 7.2
A11: Ethiopia | B11: Salt | C11: Middle | D11: Vehicle consumption by WRA -- amount | E11: mean | F11: g/day | H11: EPHI data sent by Andy Garcia | I11: 7.7
A12: Ethiopia | B12: Salt | C12: Fourth | D12: Vehicle consumption by WRA -- amount | E12: mean | F12: g/day | H12: EPHI data sent by Andy Garcia | I12: 7.2
A13: Ethiopia | B13: Salt | C13: Highest | D13: Vehicle consumption by WRA -- amount | E13: mean | F13: g/day | H13: EPHI data sent by Andy Garcia | I13: 6.5
A14: Ethiopia | B14: Salt | C14: All | D14: Vehicle consumption by WRA -- amount | E14: standard deviation | F14: g/day | H14: Survey in Addis Ababa | I14: 2.2 | L14: https://www.ncbi.nlm.nih.gov/pmc/articles/PMC10195378/; among all adults
A15: Ethiopia | B15: Salt | C15: Lowest | D15: Vehicle consumption by WRA -- amount | E15: standard deviation | F15: g/day | H15: Assumption | I15: 2.2 | L15: Assumed same by quintile
A16: Ethiopia | B16: Salt | C16: Second | D16: Vehicle consumption by WRA -- amount | E16: standard deviation | F16: g/day | H16: Assumption | I16: 2.2
A17: Ethiopia | B17: Salt | C17: Middle | D17: Vehicle consumption by WRA -- amount | E17: standard deviation | F17: g/day | H17: Assumption | I17: 2.2
A18: Ethiopia | B18: Salt | C18: Fourth | D18: Vehicle consumption by WRA -- amount | E18: standard deviation | F18: g/day | H18: Assumption | I18: 2.2
A19: Ethiopia | B19: Salt | C19: Highest | D19: Vehicle consumption by WRA -- amount | E19: standard deviation | F19: g/day | H19: Assumption | I19: 2.2
A20: Ethiopia | B20: Salt | C20: All | D20: Vehicle consumption by U5 children -- any | E20: percentage | F20: % | I20: 0.97 | L20: Total population (?), not U5 specifically
A21: Ethiopia | B21: Salt | C21: Lowest | D21: Vehicle consumption by U5 children -- any | E21: percentage | F21: % | I21: 0.97 | L21: Not stratified by wealth quintile
A22: Ethiopia | B22: Salt | C22: Second | D22: Vehicle consumption by U5 children -- any | E22: percentage | F22: % | I22: 0.97
A23: Ethiopia | B23: Salt | C23: Middle | D23: Vehicle consumption by U5 children -- any | E23: percentage | F23: % | I23: 0.97
A24: Ethiopia | B24: Salt | C24: Fourth | D24: Vehicle consumption by U5 children -- any | E24: percentage | F24: % | I24: 0.97
A25: Ethiopia | B25: Salt | C25: Highest | D25: Vehicle consumption by U5 children -- any | E25: percentage | F25: % | I25: 0.97
A26: Ethiopia | B26: Salt | C26: All | D26: Vehicle consumption by U5 children -- amount | E26: mean | F26: g/day | H26: EPHI data sent by Andy Garcia | I26: 7.1 | L26: 2022 National Nutrition Survey; Total population (?), not U5 specifically
A27: Ethiopia | B27: Salt | C27: Lowest | D27: Vehicle consumption by U5 children -- amount | E27: mean | F27: g/day | H27: EPHI data sent by Andy Garcia | I27: 7.1
A28: Ethiopia | B28: Salt | C28: Second | D28: Vehicle consumption by U5 children -- amount | E28: mean | F28: g/day | H28: EPHI data sent by Andy Garcia | I28: 7.2
A29: Ethiopia | B29: Salt | C29: Middle | D29: Vehicle consumption by U5 children -- amount | E29: mean | F29: g/day | H29: EPHI data sent by Andy Garcia | I29: 7.7
A30: Ethiopia | B30: Salt | C30: Fourth | D30: Vehicle consumption by U5 children -- amount | E30: mean | F30: g/day | H30: EPHI data sent by Andy Garcia | I30: 7.2
A31: Ethiopia | B31: Salt | C31: Highest | D31: Vehicle consumption by U5 children -- amount | E31: mean | F31: g/day | H31: EPHI data sent by Andy Garcia | I31: 6.5
A32: Ethiopia | B32: Salt | C32: All | D32: Vehicle consumption by U5 children -- amount | E32: standard deviation | F32: g/day | H32: Survey in Addis Ababa | I32: 2.2 | L32: https://www.ncbi.nlm.nih.gov/pmc/articles/PMC10195378/; among all adults
A33: Ethiopia | B33: Salt | C33: Lowest | D33: Vehicle consumption by U5 children -- amount | E33: standard deviation | F33: g/day | H33: Assumption | I33: 2.2 | L33: Assumed same by quintile
A34: Ethiopia | B34: Salt | C34: Second | D34: Vehicle consumption by U5 children -- amount | E34: standard deviation | F34: g/day | H34: Assumption | I34: 2.2
A35: Ethiopia | B35: Salt | C35: Middle | D35: Vehicle consumption by U5 children -- amount | E35: standard deviation | F35: g/day | H35: Assumption | I35: 2.2
A36: Ethiopia | B36: Salt | C36: Fourth | D36: Vehicle consumption by U5 children -- amount | E36: standard deviation | F36: g/day | H36: Assumption | I36: 2.2
A37: Ethiopia | B37: Salt | C37: Highest | D37: Vehicle consumption by U5 children -- amount | E37: standard deviation | F37: g/day | H37: Assumption | I37: 2.2
A38: Ethiopia | B38: Salt | C38: All | D38: Vehicle "fortifiability" (essentially amount industrially produced) | E38: percentage | F38: % | H38: Assumption | I38: 1 | L38: "Almost all households in Ethiopia have access to iodized salt." ~ National Food and Nutrition Strategy Baseline Survey
A39: Ethiopia | B39: Salt | C39: Lowest | D39: Vehicle "fortifiability" (essentially amount industrially produced) | E39: percentage | F39: % | H39: Assumption | I39: 1
A40: Ethiopia | B40: Salt | C40: Second | D40: Vehicle "fortifiability" (essentially amount industrially produced) | E40: percentage | F40: % | H40: Assumption | I40: 1
...

Sheet Country-Vehicle-Fortif Progress
A1: Country | B1: Ethiopia | F1: Nigeria | J1: India
A2: Vehicle | B2: Salt | F2: Bouillon | J2: Rice
A3: Fortificant | B3: Folate | D3: Iron | F3: Folate | H3: Iron | J3: Folate | L3: Iron
A4: Wealth | B4: Overall | C4: Quintile | D4: Overall | E4: Quintile | F4: Overall | G4: Quintile | H4: Overall | I4: Quintile | J4: Overall | K4: Quintile | L4: Overall | M4: Quintile
A5: Data need
A6: Vehicle fortification at baseline -- any | B6: Zero | C6: Zero | D6: Not modeled | E6: Not modeled | F6: Zero | G6: Zero | H6: =IF(COUNTIFS('Country-Vehicle-Fort Extraction'!$A$2:$A$973, F$1, 'Country-Vehicle-Fort Extraction'!$B$2:$B$973, F$2, 'Country-Vehicle-Fort Extraction'!$C$2:$C$973, H$3, 'Country-Vehicle-Fort Extraction'!$D$2:$D$973, "All", 'Country-Vehicle-Fort Extraction'!$E$2:$E$973, $A6, 'Country-Vehicle-Fort Extraction'!$J$2:$J$973, "<>") = 0, "Missing", "Complete") -> Complete | I6: =IF(COUNTIFS('Country-Vehicle-Fort Extraction'!$A$2:$A$973, F$1, 'Country-Vehicle-Fort Extraction'!$B$2:$B$973, F$2, 'Country-Vehicle-Fort Extraction'!$C$2:$C$973, H$3, 'Country-Vehicle-Fort Extraction'!$D$2:$D$973, "<>All", 'Country-Vehicle-Fort Extraction'!$E$2:$E$973, $A6, 'Country-Vehicle-Fort Extraction'!$J$2:$J$973, "<>") < 5, "Missing", "Complete") -> Complete | J6: Microdata: HCES | K6: Microdata: HCES | L6: Microdata: HCES | M6: Microdata: HCES
A7: Vehicle fortification at baseline -- amount among fortified | B7: Zero | C7: Zero | D7: Not modeled | E7: Not modeled | F7: Zero | G7: Zero | H7: =IF(COUNTIFS('Country-Vehicle-Fort Extraction'!$A$2:$A$973, F$1, 'Country-Vehicle-Fort Extraction'!$B$2:$B$973, F$2, 'Country-Vehicle-Fort Extraction'!$C$2:$C$973, H$3, 'Country-Vehicle-Fort Extraction'!$D$2:$D$973, "All", 'Country-Vehicle-Fort Extraction'!$E$2:$E$973, $A7, 'Country-Vehicle-Fort Extraction'!$J$2:$J$973, "<>") = 0, "Missing", "Complete") -> Complete | I7: =IF(COUNTIFS('Country-Vehicle-Fort Extraction'!$A$2:$A$973, F$1, 'Country-Vehicle-Fort Extraction'!$B$2:$B$973, F$2, 'Country-Vehicle-Fort Extraction'!$C$2:$C$973, H$3, 'Country-Vehicle-Fort Extraction'!$D$2:$D$973, "<>All", 'Country-Vehicle-Fort Extraction'!$E$2:$E$973, $A7, 'Country-Vehicle-Fort Extraction'!$J$2:$J$973, "<>") < 5, "Missing", "Complete") -> Complete | J7: =IF(COUNTIFS('Country-Vehicle-Fort Extraction'!$A$2:$A$973, J$1, 'Country-Vehicle-Fort Extraction'!$B$2:$B$973, J$2, 'Country-Vehicle-Fort Extraction'!$C$2:$C$973, J$3, 'Country-Vehicle-Fort Extraction'!$D$2:$D$973, "All", 'Country-Vehicle-Fort Extraction'!$E$2:$E$973, $A7, 'Country-Vehicle-Fort Extraction'!$J$2:$J$973, "<>") = 0, "Missing", "Complete") -> Complete | K7: N/A | L7: =IF(COUNTIFS('Country-Vehicle-Fort Extraction'!$A$2:$A$973, J$1, 'Country-Vehicle-Fort Extraction'!$B$2:$B$973, J$2, 'Country-Vehicle-Fort Extraction'!$C$2:$C$973, L$3, 'Country-Vehicle-Fort Extraction'!$D$2:$D$973, "All", 'Country-Vehicle-Fort Extraction'!$E$2:$E$973, $A7, 'Country-Vehicle-Fort Extraction'!$J$2:$J$973, "<>") = 0, "Missing", "Complete") -> Complete | M7: N/A

Sheet Country-Vehicle-Fort Extraction
A1: Country | B1: Vehicle | C1: Fortificant | D1: Quintile | E1: Data need | F1: Data point name | G1: Units | H1: Year | I1: Data source | J1: Value | K1: CI | L1: Notes
A2: Ethiopia | B2: Salt | C2: Folate | D2: All | E2: Vehicle fortification at baseline -- any | F2: percentage | G2: % | I2: Assumption | J2: 0
A3: Ethiopia | B3: Salt | C3: Folate | D3: Lowest | E3: Vehicle fortification at baseline -- any | F3: percentage | G3: % | I3: Assumption | J3: 0
A4: Ethiopia | B4: Salt | C4: Folate | D4: Second | E4: Vehicle fortification at baseline -- any | F4: percentage | G4: % | I4: Assumption | J4: 0
A5: Ethiopia | B5: Salt | C5: Folate | D5: Middle | E5: Vehicle fortification at baseline -- any | F5: percentage | G5: % | I5: Assumption | J5: 0
A6: Ethiopia | B6: Salt | C6: Folate | D6: Fourth | E6: Vehicle fortification at baseline -- any | F6: percentage | G6: % | I6: Assumption | J6: 0
A7: Ethiopia | B7: Salt | C7: Folate | D7: Highest | E7: Vehicle fortification at baseline -- any | F7: percentage | G7: % | I7: Assumption | J7: 0
A8: Ethiopia | B8: Salt | C8: Folate | D8: All | E8: Vehicle fortification at baseline -- amount among fortified | F8: concentration | G8: mcg/g | I8: Assumption | J8: 0
A9: Ethiopia | B9: Salt | C9: Folate | D9: Lowest | E9: Vehicle fortification at baseline -- amount among fortified | F9: concentration | G9: mcg/g | I9: Assumption | J9: 0
A10: Ethiopia | B10: Salt | C10: Folate | D10: Second | E10: Vehicle fortification at baseline -- amount among fortified | F10: concentration | G10: mcg/g | I10: Assumption | J10: 0
A11: Ethiopia | B11: Salt | C11: Folate | D11: Middle | E11: Vehicle fortification at baseline -- amount among fortified | F11: concentration | G11: mcg/g | I11: Assumption | J11: 0
A12: Ethiopia | B12: Salt | C12: Folate | D12: Fourth | E12: Vehicle fortification at baseline -- amount among fortified | F12: concentration | G12: mcg/g | I12: Assumption | J12: 0
A13: Ethiopia | B13: Salt | C13: Folate | D13: Highest | E13: Vehicle fortification at baseline -- amount among fortified | F13: concentration | G13: mcg/g | I13: Assumption | J13: 0
A14: Nigeria | B14: Bouillon | C14: Iron | D14: All | E14: Vehicle fortification at baseline -- any | F14: percentage | G14: % | I14: Assumption | J14: 0.61875637 | L14: Assumption: labeled as fortified = fortified (basically true for salt). Divided "consumed food labeled as fortified" by "consumed food".
A15: Nigeria | B15: Bouillon | C15: Iron | D15: Lowest | E15: Vehicle fortification at baseline -- any | F15: percentage | G15: % | I15: Assumption | J15: 0.5192108
A16: Nigeria | B16: Bouillon | C16: Iron | D16: Second | E16: Vehicle fortification at baseline -- any | F16: percentage | G16: % | I16: Assumption | J16: 0.58409786
A17: Nigeria | B17: Bouillon | C17: Iron | D17: Middle | E17: Vehicle fortification at baseline -- any | F17: percentage | G17: % | I17: Assumption | J17: 0.63810484
A18: Nigeria | B18: Bouillon | C18: Iron | D18: Fourth | E18: Vehicle fortification at baseline -- any | F18: percentage | G18: % | I18: Assumption | J18: 0.6693712
A19: Nigeria | B19: Bouillon | C19: Iron | D19: Highest | E19: Vehicle fortification at baseline -- any | F19: percentage | G19: % | I19: Assumption | J19: 0.69979716
A20: Nigeria | B20: Bouillon | C20: Iron | D20: All | E20: Vehicle fortification at baseline -- amount among fortified | F20: concentration | G20: mcg/g | I20: Assumption | J20: 525 | L20: Maggi cubes (most popular brand and format) have 15% NRV per serving (https://www.nestle-cwa.com/en/ask-nestle/products-brands/what-is-in-the-maggi-cube)
A21: Nigeria | B21: Bouillon | C21: Iron | D21: Lowest | E21: Vehicle fortification at baseline -- amount among fortified | F21: concentration | G21: mcg/g | I21: Assumption | J21: 525 | L21: Assumed no disparity
A22: Nigeria | B22: Bouillon | C22: Iron | D22: Second | E22: Vehicle fortification at baseline -- amount among fortified | F22: concentration | G22: mcg/g | I22: Assumption | J22: 525
A23: Nigeria | B23: Bouillon | C23: Iron | D23: Middle | E23: Vehicle fortification at baseline -- amount among fortified | F23: concentration | G23: mcg/g | I23: Assumption | J23: 525
A24: Nigeria | B24: Bouillon | C24: Iron | D24: Fourth | E24: Vehicle fortification at baseline -- amount among fortified | F24: concentration | G24: mcg/g | I24: Assumption | J24: 525
A25: Nigeria | B25: Bouillon | C25: Iron | D25: Highest | E25: Vehicle fortification at baseline -- amount among fortified | F25: concentration | G25: mcg/g | I25: Assumption | J25: 525
A26: Nigeria | B26: Bouillon | C26: Folate | D26: All | E26: Vehicle fortification at baseline -- any | F26: percentage | G26: % | I26: Assumption | J26: 0 | L26: There is some information on fraction labeled as fortified in NFCMS Table 169, but it Figure 71 shows that 95% of WRA have RBC folate insufficiency. Also: '61 percent of the non-pregnant women from households consumed bouillons that are labelled as fortified with iodine and/or iron.' There is some evidence that the rich have more bouillon labeled as fortified (Table 169).
A27: Nigeria | B27: Bouillon | C27: Folate | D27: Lowest | E27: Vehicle fortification at baseline -- any | F27: percentage | G27: % | I27: Assumption | J27: 0
A28: Nigeria | B28: Bouillon | C28: Folate | D28: Second | E28: Vehicle fortification at baseline -- any | F28: percentage | G28: % | I28: Assumption | J28: 0
A29: Nigeria | B29: Bouillon | C29: Folate | D29: Middle | E29: Vehicle fortification at baseline -- any | F29: percentage | G29: % | I29: Assumption | J29: 0
A30: Nigeria | B30: Bouillon | C30: Folate | D30: Fourth | E30: Vehicle fortification at baseline -- any | F30: percentage | G30: % | I30: Assumption | J30: 0
A31: Nigeria | B31: Bouillon | C31: Folate | D31: Highest | E31: Vehicle fortification at baseline -- any | F31: percentage | G31: % | I31: Assumption | J31: 0
A32: Nigeria | B32: Bouillon | C32: Folate | D32: All | E32: Vehicle fortification at baseline -- amount among fortified | F32: concentration | G32: mcg/g | I32: Assumption | J32: 0
A33: Nigeria | B33: Bouillon | C33: Folate | D33: Lowest | E33: Vehicle fortification at baseline -- amount among fortified | F33: concentration | G33: mcg/g | I33: Assumption | J33: 0
A34: Nigeria | B34: Bouillon | C34: Folate | D34: Second | E34: Vehicle fortification at baseline -- amount among fortified | F34: concentration | G34: mcg/g | I34: Assumption | J34: 0
A35: Nigeria | B35: Bouillon | C35: Folate | D35: Middle | E35: Vehicle fortification at baseline -- amount among fortified | F35: concentration | G35: mcg/g | I35: Assumption | J35: 0
A36: Nigeria | B36: Bouillon | C36: Folate | D36: Fourth | E36: Vehicle fortification at baseline -- amount among fortified | F36: concentration | G36: mcg/g | I36: Assumption | J36: 0
A37: Nigeria | B37: Bouillon | C37: Folate | D37: Highest | E37: Vehicle fortification at baseline -- amount among fortified | F37: concentration | G37: mcg/g | I37: Assumption | J37: 0
A38: India | B38: Rice | C38: Iron | D38: All | E38: Vehicle fortification at baseline -- amount among fortified | F38: concentration | G38: mcg/g | I38: slide deck JG shared to ADF, credited to Helena.Pachon@emory.edu | J38: 42.5 | L38: Originally in mg/100g; https://www.wolframalpha.com/input?i=4.25+mg+per+100+grams+in+micrograms+per+gram
A39: India | B39: Rice | C39: Iron | D39: Lowest | E39: Vehicle fortification at baseline -- amount among fortified | F39: concentration | G39: mcg/g | I39: Assumption | J39: 42.5 | L39: assumed same by quintile?
A40: India | B40: Rice | C40: Iron | D40: Second | E40: Vehicle fortification at baseline -- amount among fortified | F40: concentration | G40: mcg/g | I40: Assumption | J40: 42.5
...

Sheet Country Progress
A1: Country | B1: Ethiopia | D1: Nigeria | F1: India | H1: Notes
A2: Wealth | B2: Overall | C2: Quintile | D2: Overall | E2: Quintile | F2: Overall | G2: Quintile
A3: Data need
A4: Pregnant people hemoglobin levels at baseline | B4: Not modeled | C4: Not modeled | D4: GBD | E4: DHS 2018 | F4: GBD | G4: DHS 2016
A5: Serum/plasma folate levels at baseline | B5: =IF(COUNTIFS('Country Extraction'!$A$2:$A$980, B$1, 'Country Extraction'!$B$2:$B$980, "All", 'Country Extraction'!$C$2:$C$980, $A5) = 0, "Missing", "Complete") -> Missing | C5: =IF(COUNTIFS('Country Extraction'!$A$1:$A$995, D$1, 'Country Extraction'!$B$1:$B$995, "<>All", 'Country Extraction'!$C$1:$C$995, $A5, 'Country Extraction'!$H$1:$H$995, "<>") < 5, "Missing", "Complete") -> Missing | D5: =IF(COUNTIFS('Country Extraction'!$A$2:$A$980, D$1, 'Country Extraction'!$B$2:$B$980, "All", 'Country Extraction'!$C$2:$C$980, $A5) = 0, "Missing", "Complete") -> Missing | E5: =IF(COUNTIFS('Country Extraction'!$A$1:$A$995, F$1, 'Country Extraction'!$B$1:$B$995, "<>All", 'Country Extraction'!$C$1:$C$995, $A5, 'Country Extraction'!$H$1:$H$995, "<>") < 5, "Missing", "Complete") -> Missing | F5: =IF(COUNTIFS('Country Extraction'!$A$2:$A$980, F$1, 'Country Extraction'!$B$2:$B$980, "All", 'Country Extraction'!$C$2:$C$980, $A5) = 0, "Missing", "Complete") -> Missing | G5: =IF(COUNTIFS('Country Extraction'!$A$1:$A$995, H$1, 'Country Extraction'!$B$1:$B$995, "<>All", 'Country Extraction'!$C$1:$C$995, $A5, 'Country Extraction'!$H$1:$H$995, "<>") < 5, "Missing", "Complete") -> Missing
A6: RBC folate levels at baseline | B6: =IF(COUNTIFS('Country Extraction'!$A$2:$A$980, B$1, 'Country Extraction'!$B$2:$B$980, "All", 'Country Extraction'!$C$2:$C$980, $A6) = 0, "Missing", "Complete") -> Missing | C6: =IF(COUNTIFS('Country Extraction'!$A$1:$A$995, D$1, 'Country Extraction'!$B$1:$B$995, "<>All", 'Country Extraction'!$C$1:$C$995, $A6, 'Country Extraction'!$H$1:$H$995, "<>") < 5, "Missing", "Complete") -> Missing | D6: =IF(COUNTIFS('Country Extraction'!$A$2:$A$980, D$1, 'Country Extraction'!$B$2:$B$980, "All", 'Country Extraction'!$C$2:$C$980, $A6) = 0, "Missing", "Complete") -> Missing | E6: =IF(COUNTIFS('Country Extraction'!$A$1:$A$995, F$1, 'Country Extraction'!$B$1:$B$995, "<>All", 'Country Extraction'!$C$1:$C$995, $A6, 'Country Extraction'!$H$1:$H$995, "<>") < 5, "Missing", "Complete") -> Missing | F6: =IF(COUNTIFS('Country Extraction'!$A$2:$A$980, F$1, 'Country Extraction'!$B$2:$B$980, "All", 'Country Extraction'!$C$2:$C$980, $A6) = 0, "Missing", "Complete") -> Missing | G6: =IF(COUNTIFS('Country Extraction'!$A$1:$A$995, H$1, 'Country Extraction'!$B$1:$B$995, "<>All", 'Country Extraction'!$C$1:$C$995, $A6, 'Country Extraction'!$H$1:$H$995, "<>") < 5, "Missing", "Complete") -> Missing
A7: LBWSG prevalence | B7: Not modeled | C7: Not modeled | D7: GBD | E7: DHS 2018 | F7: GBD | G7: DHS 2016
A8: CGF prevalence | B8: Not modeled | C8: Not modeled | D8: GBD | E8: DHS 2018 | F8: GBD | G8: DHS 2016
A9: Measles prevalence | B9: Not modeled | C9: Not modeled | D9: GBD | E9: DHS 2018 | F9: GBD | G9: DHS 2016 | H9: We have microdata on whether child has received Measles 1 vaccination.
A10: LRI prevalence | B10: Not modeled | C10: Not modeled | D10: GBD | E10: =IF(COUNTIFS('Country Extraction'!$A$1:$A$995, F$1, 'Country Extraction'!$B$1:$B$995, "<>All", 'Country Extraction'!$C$1:$C$995, $A10, 'Country Extraction'!$H$1:$H$995, "<>") < 5, "Missing", "Complete") -> Missing | F10: GBD | G10: =IF(COUNTIFS('Country Extraction'!$A$1:$A$995, H$1, 'Country Extraction'!$B$1:$B$995, "<>All", 'Country Extraction'!$C$1:$C$995, $A10, 'Country Extraction'!$H$1:$H$995, "<>") < 5, "Missing", "Complete") -> Missing | H10: We have microdata on whether child has had cough in the last two weeks, or ARI prevalence in DHS final reports.
A11: Malaria prevalence | B11: Not modeled | C11: Not modeled | D11: GBD | E11: =IF(COUNTIFS('Country Extraction'!$A$1:$A$995, F$1, 'Country Extraction'!$B$1:$B$995, "<>All", 'Country Extraction'!$C$1:$C$995, $A11, 'Country Extraction'!$H$1:$H$995, "<>") < 5, "Missing", "Complete") -> Missing | F11: GBD | G11: DHS 2016 | H11: For India, we might have to use the DHS microdata for whether child has had fever in the last two weeks as a proxy for malaria.
A12: U5 hemoglobin levels at baseline | B12: Not modeled | C12: Not modeled | D12: GBD | E12: DHS 2018 | F12: GBD | G12: DHS 2016
A13: Maternal disorders incidence | B13: Not modeled | C13: Not modeled | D13: GBD | E13: DHS 2018 | F13: GBD | G13: DHS 2016 | H13: Using DHS' maternal mortality ratio as a proxy for maternal disorders
A14: Maternal hemorrhage incidence | B14: Not modeled | C14: Not modeled | D14: GBD | E14: DHS 2018 | F14: GBD | G14: DHS 2016 | H14: Using DHS' maternal mortality ratio as a proxy for maternal hemorrhage
A15: Neural tube defect deaths | B15: GBD | C15: =IF(COUNTIFS('Country Extraction'!$A$1:$A$995, D$1, 'Country Extraction'!$B$1:$B$995, "<>All", 'Country Extraction'!$C$1:$C$995, $A15, 'Country Extraction'!$H$1:$H$995, "<>") < 5, "Missing", "Complete") -> Missing | D15: GBD | E15: =IF(COUNTIFS('Country Extraction'!$A$1:$A$995, F$1, 'Country Extraction'!$B$1:$B$995, "<>All", 'Country Extraction'!$C$1:$C$995, $A15, 'Country Extraction'!$H$1:$H$995, "<>") < 5, "Missing", "Complete") -> Missing | F15: GBD | G15: =IF(COUNTIFS('Country Extraction'!$A$1:$A$995, H$1, 'Country Extraction'!$B$1:$B$995, "<>All", 'Country Extraction'!$C$1:$C$995, $A15, 'Country Extraction'!$H$1:$H$995, "<>") < 5, "Missing", "Complete") -> Missing

Sheet Country Extraction
A1: Country | B1: Quintile | C1: Data need | D1: Data point name | E1: Units | F1: Year | G1: Data source | H1: Value | I1: CI | J1: Notes
A2: Ethiopia | B2: All | C2: Serum folate levels at baseline | E2: ? | G2: ? | J2: potential data gap!
A3: Ethiopia | B3: Lowest | C3: Serum folate levels at baseline | E3: ? | G3: ? | J3: Back-calculate from GBD NTDs? (and DHS NTDs for wealth quintiles?)
A4: Ethiopia | B4: Second | C4: Serum folate levels at baseline | E4: ? | G4: ?
A5: Ethiopia | B5: Middle | C5: Serum folate levels at baseline | E5: ? | G5: ?
A6: Ethiopia | B6: Fourth | C6: Serum folate levels at baseline | E6: ? | G6: ?
A7: Ethiopia | B7: Highest | C7: Serum folate levels at baseline | E7: ? | G7: ?
A8: Nigeria | B8: All | C8: Serum folate levels at baseline | E8: ? | G8: ?
A9: Nigeria | B9: Lowest | C9: Serum folate levels at baseline | E9: ? | G9: ?
A10: Nigeria | B10: Second | C10: Serum folate levels at baseline | E10: ? | G10: ?
A11: Nigeria | B11: Middle | C11: Serum folate levels at baseline | E11: ? | G11: ?
A12: Nigeria | B12: Fourth | C12: Serum folate levels at baseline | E12: ? | G12: ?
A13: Nigeria | B13: Highest | C13: Serum folate levels at baseline | E13: ? | G13: ?
A14: India | B14: All | C14: Serum folate levels at baseline | E14: ? | G14: ?
A15: India | B15: Lowest | C15: Serum folate levels at baseline | E15: ? | G15: ?
... A19: India | B19: Highest | C19: Serum folate levels at baseline | E19: ? | G19: ?
A20: Ethiopia | B20: All | C20: Red blood cell folate levels at baseline -- Also called “whole blood lysate”? | E20: nmol/L? | G20: ? | J20: potential data gap!
A21: Ethiopia | B21: Lowest | C21: Red blood cell folate levels at baseline -- Also called “whole blood lysate”? | E21: nmol/L? | G21: ? | J21: Back-calculate from GBD NTDs? (and DHS NTDs for wealth quintiles?)
A22: Ethiopia | B22: Second | C22: Red blood cell folate levels at baseline -- Also called “whole blood lysate”? | E22: nmol/L? | G22: ?
A23: Ethiopia | B23: Middle | C23: Red blood cell folate levels at baseline -- Also called “whole blood lysate”? | E23: nmol/L? | G23: ?
A24: Ethiopia | B24: Fourth | C24: Red blood cell folate levels at baseline -- Also called “whole blood lysate”? | E24: nmol/L? | G24: ?
A25: Ethiopia | B25: Highest | C25: Red blood cell folate levels at baseline -- Also called “whole blood lysate”? | E25: nmol/L? | G25: ?
A26: Nigeria | B26: All | C26: Red blood cell folate levels at baseline -- Also called “whole blood lysate”? | E26: nmol/L? | G26: ?
A27: Nigeria | B27: Lowest | C27: Red blood cell folate levels at baseline -- Also called “whole blood lysate”? | E27: nmol/L? | G27: ?
A28: Nigeria | B28: Second | C28: Red blood cell folate levels at baseline -- Also called “whole blood lysate”? | E28: nmol/L? | G28: ?
A29: Nigeria | B29: Middle | C29: Red blood cell folate levels at baseline -- Also called “whole blood lysate”? | E29: nmol/L? | G29: ?
A30: Nigeria | B30: Fourth | C30: Red blood cell folate levels at baseline -- Also called “whole blood lysate”? | E30: nmol/L? | G30: ?
A31: Nigeria | B31: Highest | C31: Red blood cell folate levels at baseline -- Also called “whole blood lysate”? | E31: nmol/L? | G31: ?
A32: India | B32: All | C32: Red blood cell folate levels at baseline -- Also called “whole blood lysate”? | E32: nmol/L? | G32: ?
A33: India | B33: Lowest | C33: Red blood cell folate levels at baseline -- Also called “whole blood lysate”? | E33: nmol/L? | G33: ?
... A37: India | B37: Highest | C37: Red blood cell folate levels at baseline -- Also called “whole blood lysate”? | E37: nmol/L? | G37: ?
A38: Ethiopia | B38: All | C38: Pregnancies longer than 7 months | G38: Most recent DHS for Ethiopia
A39: Ethiopia | B39: Lowest | C39: Pregnancies longer than 7 months | G39: Ethiopia DHS survey report Table 8.4
A40: Ethiopia | B40: Second | C40: Pregnancies longer than 7 months | G40: Ethiopia DHS survey report Table 8.4
A41: Ethiopia | B41: Middle | C41: Pregnancies longer than 7 months | G41: Ethiopia DHS survey report Table 8.4
A42: Ethiopia | B42: Fourth | C42: Pregnancies longer than 7 months | G42: Ethiopia DHS survey report Table 8.4
A43: Ethiopia | B43: Highest | C43: Pregnancies longer than 7 months | G43: Ethiopia DHS survey report Table 8.4
A44: Nigeria | B44: All | C44: Pregnancies longer than 7 months | G44: Most recent DHS for Nigeria
A45: Nigeria | B45: Lowest | C45: Pregnancies longer than 7 months | G45: Nigeria DHS survey report - Table 8.4
A46: Nigeria | B46: Second | C46: Pregnancies longer than 7 months | G46: Nigeria DHS survey report - Table 8.4
...

Sheet Vehicle Progress
A1: Vehicle | B1: Salt | C1: Bouillon | D1: Rice | E1: Notes
A2: Data need
A3: Iron fortification/consumption effect on hemoglobin | B3: Not modeled | C3: =IF(COUNTIFS('Vehicle Extraction'!$A$2:$A$904, C$1, 'Vehicle Extraction'!$B$2:$B$904, $A3) = 0, "Missing", "Complete") -> Complete | D3: =IF(COUNTIFS('Vehicle Extraction'!$A$2:$A$904, D$1, 'Vehicle Extraction'!$B$2:$B$904, $A3) = 0, "Missing", "Complete") -> Complete
A4: Iron fortification/consumption effect on birthweight | B4: Not modeled | C4: =IF(COUNTIFS('Vehicle Extraction'!$A$2:$A$904, C$1, 'Vehicle Extraction'!$B$2:$B$904, $A4) = 0, "Missing", "Complete") -> Complete | D4: =IF(COUNTIFS('Vehicle Extraction'!$A$2:$A$904, D$1, 'Vehicle Extraction'!$B$2:$B$904, $A4) = 0, "Missing", "Complete") -> Complete

Sheet Vehicle Extraction
A1: Vehicle | B1: Data need | C1: Data point name | D1: Units | E1: Year | F1: Data source | G1: Value | H1: CI | I1: Notes
A2: Rice | B2: Iron fortification/consumption effect on hemoglobin | C2: Mean difference | D2: g/L | E2: Unpublished | F2: Dorbu et al. Nutritional anemia reductions due to food fortification among women of childbearing age: a systematic review and Bayesian meta-analysis. Unpublished data. | G2: 3.25 | H2: 0.9-5.71 | I2: "This comes from a slide deck that Jonathan send to Abie. It is credited to Helena.Pachon@emory.edu". There are also https://doi.org/10.1080/09637486.2020.1855126 and https://iris.who.int/bitstream/handle/10665/272535/9789241550291-eng.pdf?ua=1 which report similar-ish numbers but this is the one we got from Gates.
A3: Salt | B3: Iron fortification/consumption effect on hemoglobin | C3: Mean difference | D3: g/L | E3: 2021 | F3: Can Double Fortification of Salt with Iron and Iodine Reduce Anemia, Iron Deficiency Anemia, Iron Deficiency, Iodine Deficiency, and Functional Outcomes? Evidence of Efficacy, Effectiveness, and Safety | G3: 4.4 | H3: 2.3-6.4 | I3: https://www.ncbi.nlm.nih.gov/pmc/articles/PMC7882357/; meta-analysis of 22 studies
A4: Bouillon | B4: Iron fortification/consumption effect on hemoglobin | C4: Mean difference | D4: g/L | E4: 2012 | F4: Effect of iron-fortified foods on hematologic and biological outcomes: systematic review of randomized controlled trials | G4: 4.2 | H4: 2.8-5.6 | I4: https://www.sciencedirect.com/science/article/pii/S0002916523028915; could not find anything bouillon-specific
A5: Rice | B5: Iron fortification/consumption effect on birthweight | C5: Mean difference | D5: g/(mg/person-day) | E5: 2013 | F5: Anaemia, prenatal iron use, and risk of adverse pregnancy outcomes: systematic review and meta-analysis | G5: 16.7 | H5: 7.29 to 26.11 | I5: https://www.bmj.com/content/346/bmj.f3443; study of supplementation at higher doses than fortification; selected the effect among trials <66mg/day as all fortification would fall in this range
A6: Bouillon | B6: Iron fortification/consumption effect on birthweight | C6: Mean difference | D6: g/(mg/person-day) | E6: 2013 | F6: Anaemia, prenatal iron use, and risk of adverse pregnancy outcomes: systematic review and meta-analysis | G6: 16.7 | H6: 7.29 to 26.11 | I6: https://www.bmj.com/content/346/bmj.f3443; study of supplementation at higher doses than fortification; selected the effect among trials <66mg/day as all fortification would fall in this range

Sheet Universal
A1: Data need | B1: Data point name | C1: Units | D1: Year | E1: Data source | F1: Value | G1: CI | H1: Notes
A2: Folate fortification/consumption effect on serum/plasma folate
A3: Rice | B3: Risk Difference | C3: nmol/L | D3: 2018 | E3: WHO 2018 systematic review | F3: 4.3 | G3: 2.00-6.60 | H3: https://iris.who.int/bitstream/handle/10665/272535/9789241550291-eng.pdf?ua=1 found a single study
A4: Folate fortification/consumption effect on RBC folate | B4: Relative Risk (linear dose-response) | C4: percent RBC increase per 10% increase in folate intake | D4: 2015 | E4: Marchetta et al, 2015 | F4: 6 | G4: 4-9
A5: Serum/plasma folate effect on RBC folate
A6: RBC folate effect on NTD incidence | B6: non-linear relationship | E6: (Daly et al, 1995) | F6: ln (odds of NTD risk) = 1.6563 − 1.2193 × ln (RBC)
A7: RBC folate effect on NTD incidence | B7: non-linear relationship | E7: (Crider et al, 2014) | F7: ln (odds of NTD risk) = 4.57 − 1.70 × ln (RBC)
A8: NTD stillbirth-to-death ratio | B8: Ratio | E8: NTD Stillbirths paper in Lancet Global Health based on CHAMPS MITS data | F8: 51/18 | H8: There might be more data available since this paper was published

Sheet Scenario Definition Progress
A1: Country | B1: Ethiopia | D1: Nigeria | F1: India
A2: Vehicle | B2: Salt | D2: Bouillon | F2: Rice
A3: Fortificant | B3: Folate | D3: Folate | E3: Iron | F3: Folate | G3: Iron
A4: Scenario | B4: Intervention - 25% NRV | C4: Intervention - 100% NRV | D4: Intervention | E4: Intervention | F4: Intervention | G4: Intervention
A5: Data need
A6: Vehicle fortification in intervention -- amount among fortified | B6: =IF(COUNTIFS('Scenario Definition Extraction'!$A$2:$A$991, B$1, 'Scenario Definition Extraction'!$B$2:$B$991, B$2, 'Scenario Definition Extraction'!$C$2:$C$991, B$3, 'Scenario Definition Extraction'!$D$2:$D$991, B$4, 'Scenario Definition Extraction'!$E$2:$E$991, $A6) = 0, "Missing", "Complete") -> Complete | C6: =IF(COUNTIFS('Scenario Definition Extraction'!$A$2:$A$991, B$1, 'Scenario Definition Extraction'!$B$2:$B$991, B$2, 'Scenario Definition Extraction'!$C$2:$C$991, B$3, 'Scenario Definition Extraction'!$D$2:$D$991, C$4, 'Scenario Definition Extraction'!$E$2:$E$991, $A6) = 0, "Missing", "Complete") -> Complete | D6: =IF(COUNTIFS('Scenario Definition Extraction'!$A$2:$A$991, D$1, 'Scenario Definition Extraction'!$B$2:$B$991, D$2, 'Scenario Definition Extraction'!$C$2:$C$991, D$3, 'Scenario Definition Extraction'!$D$2:$D$991, D$4, 'Scenario Definition Extraction'!$E$2:$E$991, $A6) = 0, "Missing", "Complete") -> Complete | E6: =IF(COUNTIFS('Scenario Definition Extraction'!$A$2:$A$991, D$1, 'Scenario Definition Extraction'!$B$2:$B$991, D$2, 'Scenario Definition Extraction'!$C$2:$C$991, E$3, 'Scenario Definition Extraction'!$D$2:$D$991, E$4, 'Scenario Definition Extraction'!$E$2:$E$991, $A6) = 0, "Missing", "Complete") -> Complete | F6: =IF(COUNTIFS('Scenario Definition Extraction'!$A$2:$A$991, F$1, 'Scenario Definition Extraction'!$B$2:$B$991, F$2, 'Scenario Definition Extraction'!$C$2:$C$991, F$3, 'Scenario Definition Extraction'!$D$2:$D$991, F$4, 'Scenario Definition Extraction'!$E$2:$E$991, $A6) = 0, "Missing", "Complete") -> Complete | G6: =IF(COUNTIFS('Scenario Definition Extraction'!$A$2:$A$991, F$1, 'Scenario Definition Extraction'!$B$2:$B$991, F$2, 'Scenario Definition Extraction'!$C$2:$C$991, G$3, 'Scenario Definition Extraction'!$D$2:$D$991, G$4, 'Scenario Definition Extraction'!$E$2:$E$991, $A6) = 0, "Missing", "Complete") -> Complete
A7: Intervention coverage % of fortifiable and unfortified | B7: =IF(COUNTIFS('Scenario Definition Extraction'!$A$2:$A$991, B$1, 'Scenario Definition Extraction'!$B$2:$B$991, B$2, 'Scenario Definition Extraction'!$C$2:$C$991, B$3, 'Scenario Definition Extraction'!$D$2:$D$991, B$4, 'Scenario Definition Extraction'!$E$2:$E$991, $A7) = 0, "Missing", "Complete") -> Complete | C7: =IF(COUNTIFS('Scenario Definition Extraction'!$A$2:$A$991, B$1, 'Scenario Definition Extraction'!$B$2:$B$991, B$2, 'Scenario Definition Extraction'!$C$2:$C$991, B$3, 'Scenario Definition Extraction'!$D$2:$D$991, C$4, 'Scenario Definition Extraction'!$E$2:$E$991, $A7) = 0, "Missing", "Complete") -> Complete | D7: =IF(COUNTIFS('Scenario Definition Extraction'!$A$2:$A$991, D$1, 'Scenario Definition Extraction'!$B$2:$B$991, D$2, 'Scenario Definition Extraction'!$C$2:$C$991, D$3, 'Scenario Definition Extraction'!$D$2:$D$991, D$4, 'Scenario Definition Extraction'!$E$2:$E$991, $A7) = 0, "Missing", "Complete") -> Complete | E7: =IF(COUNTIFS('Scenario Definition Extraction'!$A$2:$A$991, D$1, 'Scenario Definition Extraction'!$B$2:$B$991, D$2, 'Scenario Definition Extraction'!$C$2:$C$991, E$3, 'Scenario Definition Extraction'!$D$2:$D$991, E$4, 'Scenario Definition Extraction'!$E$2:$E$991, $A7) = 0, "Missing", "Complete") -> Complete | F7: =IF(COUNTIFS('Scenario Definition Extraction'!$A$2:$A$991, F$1, 'Scenario Definition Extraction'!$B$2:$B$991, F$2, 'Scenario Definition Extraction'!$C$2:$C$991, F$3, 'Scenario Definition Extraction'!$D$2:$D$991, F$4, 'Scenario Definition Extraction'!$E$2:$E$991, $A7) = 0, "Missing", "Complete") -> Complete | G7: =IF(COUNTIFS('Scenario Definition Extraction'!$A$2:$A$991, F$1, 'Scenario Definition Extraction'!$B$2:$B$991, F$2, 'Scenario Definition Extraction'!$C$2:$C$991, G$3, 'Scenario Definition Extraction'!$D$2:$D$991, G$4, 'Scenario Definition Extraction'!$E$2:$E$991, $A7) = 0, "Missing", "Complete") -> Complete
A8: Intervention effective % of newly fortified | B8: =IF(COUNTIFS('Scenario Definition Extraction'!$A$2:$A$991, B$1, 'Scenario Definition Extraction'!$B$2:$B$991, B$2, 'Scenario Definition Extraction'!$C$2:$C$991, B$3, 'Scenario Definition Extraction'!$D$2:$D$991, B$4, 'Scenario Definition Extraction'!$E$2:$E$991, $A8) = 0, "Missing", "Complete") -> Complete | C8: =IF(COUNTIFS('Scenario Definition Extraction'!$A$2:$A$991, B$1, 'Scenario Definition Extraction'!$B$2:$B$991, B$2, 'Scenario Definition Extraction'!$C$2:$C$991, B$3, 'Scenario Definition Extraction'!$D$2:$D$991, C$4, 'Scenario Definition Extraction'!$E$2:$E$991, $A8) = 0, "Missing", "Complete") -> Complete | D8: =IF(COUNTIFS('Scenario Definition Extraction'!$A$2:$A$991, D$1, 'Scenario Definition Extraction'!$B$2:$B$991, D$2, 'Scenario Definition Extraction'!$C$2:$C$991, D$3, 'Scenario Definition Extraction'!$D$2:$D$991, D$4, 'Scenario Definition Extraction'!$E$2:$E$991, $A8) = 0, "Missing", "Complete") -> Complete | E8: =IF(COUNTIFS('Scenario Definition Extraction'!$A$2:$A$991, D$1, 'Scenario Definition Extraction'!$B$2:$B$991, D$2, 'Scenario Definition Extraction'!$C$2:$C$991, E$3, 'Scenario Definition Extraction'!$D$2:$D$991, E$4, 'Scenario Definition Extraction'!$E$2:$E$991, $A8) = 0, "Missing", "Complete") -> Complete | F8: =IF(COUNTIFS('Scenario Definition Extraction'!$A$2:$A$991, F$1, 'Scenario Definition Extraction'!$B$2:$B$991, F$2, 'Scenario Definition Extraction'!$C$2:$C$991, F$3, 'Scenario Definition Extraction'!$D$2:$D$991, F$4, 'Scenario Definition Extraction'!$E$2:$E$991, $A8) = 0, "Missing", "Complete") -> Complete | G8: =IF(COUNTIFS('Scenario Definition Extraction'!$A$2:$A$991, F$1, 'Scenario Definition Extraction'!$B$2:$B$991, F$2, 'Scenario Definition Extraction'!$C$2:$C$991, G$3, 'Scenario Definition Extraction'!$D$2:$D$991, G$4, 'Scenario Definition Extraction'!$E$2:$E$991, $A8) = 0, "Missing", "Complete") -> Complete

Sheet Scenario Definition Extraction
A1: Country | B1: Vehicle | C1: Fortificant | D1: Scenario | E1: Data need | F1: Data point name | G1: Units | H1: Data source | I1: Value | J1: Notes
A2: Nigeria | B2: Bouillon | C2: Iron | D2: Intervention | E2: Intervention coverage % of fortifiable and unfortified | F2: percentage | G2: % | H2: Andy Garcia email 7/26 | I2: 0.8 | J2: Same across all vehicles/countries/fortificants
A3: Nigeria | B3: Bouillon | C3: Folate | D3: Intervention | E3: Intervention coverage % of fortifiable and unfortified | F3: percentage | G3: % | H3: Andy Garcia email 7/26 | I3: 0.8 | J3: Same across all vehicles/countries/fortificants
A4: Ethiopia | B4: Salt | C4: Folate | D4: Intervention - 25% NRV | E4: Intervention coverage % of fortifiable and unfortified | F4: percentage | G4: % | H4: Andy Garcia email 7/26 | I4: 0.8 | J4: Same across all vehicles/countries/fortificants
A5: Ethiopia | B5: Salt | C5: Folate | D5: Intervention - 100% NRV | E5: Intervention coverage % of fortifiable and unfortified | F5: percentage | G5: % | H5: Andy Garcia email 7/26 | I5: 0.8 | J5: Same across all vehicles/countries/fortificants
A6: India | B6: Rice | C6: Iron | D6: Intervention | E6: Intervention coverage % of fortifiable and unfortified | F6: percentage | G6: % | H6: Andy Garcia email 7/26 | I6: 0.8 | J6: Same across all vehicles/countries/fortificants
A7: India | B7: Rice | C7: Folate | D7: Intervention | E7: Intervention coverage % of fortifiable and unfortified | F7: percentage | G7: % | H7: Andy Garcia email 7/26 | I7: 0.8 | J7: Same across all vehicles/countries/fortificants
A8: Nigeria | B8: Bouillon | C8: Iron | D8: Intervention | E8: Intervention effective % of newly fortified | F8: percentage | G8: % | H8: Andy Garcia email 7/26 | I8: 0.8 | J8: Same across all vehicles/countries/fortificants
A9: Nigeria | B9: Bouillon | C9: Folate | D9: Intervention | E9: Intervention effective % of newly fortified | F9: percentage | G9: % | H9: Andy Garcia email 7/26 | I9: 0.8 | J9: Same across all vehicles/countries/fortificants
A10: Ethiopia | B10: Salt | C10: Folate | D10: Intervention - 25% NRV | E10: Intervention effective % of newly fortified | F10: percentage | G10: % | H10: Andy Garcia email 7/26 | I10: 0.8 | J10: Same across all vehicles/countries/fortificants
A11: Ethiopia | B11: Salt | C11: Folate | D11: Intervention - 100% NRV | E11: Intervention effective % of newly fortified | F11: percentage | G11: % | H11: Andy Garcia email 7/26 | I11: 0.8 | J11: Same across all vehicles/countries/fortificants
A12: India | B12: Rice | C12: Iron | D12: Intervention | E12: Intervention effective % of newly fortified | F12: percentage | G12: % | H12: Andy Garcia email 7/26 | I12: 0.8 | J12: Same across all vehicles/countries/fortificants
A13: India | B13: Rice | C13: Folate | D13: Intervention | E13: Intervention effective % of newly fortified | F13: percentage | G13: % | H13: Andy Garcia email 7/26 | I13: 0.8 | J13: Same across all vehicles/countries/fortificants
... A19: India | B19: Rice | C19: Folate | D19: Intervention | E19: Vehicle fortification in intervention -- amount among fortified | F19: concentration | G19: mcg/g | H19: FSSAI | I19: 0.125 | J19: Same as baseline, PDS rice; see county-vehicle-fort extraction

Sheet Data Sources
A1: Name | B1: Full Title | C1: Link | D1: Authors | E1: Year | F1: In Sharepoint?
A2: NFCMS | B2: National Food Consumption and Micronutrient Survey 2021 | C2: https://www.unicef.org/nigeria/media/9271/file/%20National%20Food%20Consumption%20and%20Micronutrient%20Survey%20(2021).pdf | D2: UNICEF | E2: 2021
A3: HCES | B3: Household Consumption Expenditure Survey
A4: DHS | B4: Demographic and Health Surveys | C4: https://www.dhsprogram.com/pubs/pdf/DHSG4/Recode7_DHS_10Sep2018_DHSG4.pdf | D4: USAID | E4: 2016; 2018 | F4: J Drive
