Workbook

Sheet Country-Vehicle Progress
A1: Country | B1: Ethiopia | D1: Nigeria | H1: India
A2: Vehicle | B2: Salt | D2: Bouillon | F2: Rice | H2: Rice
A3: Wealth | B3: Overall | C3: Quintile | D3: Overall | E3: Quintile | F3: Overall | G3: Quintile | H3: Overall | I3: Quintile
A4: Data need
A5: Vehicle consumption by WRA -- any | B5: =IF(COUNTIFS('Country-Vehicle Extraction'!$A$2:$A$979, B$1, 'Country-Vehicle Extraction'!$B$2:$B$979, B$2, 'Country-Vehicle Extraction'!$C$2:$C$979, "Total", 'Country-Vehicle Extraction'!$E$2:$E$979, $A5, 'Country-Vehicle Extraction'!$J$2:$J$979, "<>") = 0, "Missing", "Complete") -> Missing | C5: =IF(COUNTIFS('Country-Vehicle Extraction'!$A$2:$A$979, B$1, 'Country-Vehicle Extraction'!$B$2:$B$979, B$2, 'Country-Vehicle Extraction'!$C$2:$C$979, "<>All", 'Country-Vehicle Extraction'!E$2:E$979, $A5, 'Country-Vehicle Extraction'!$J$2:$J$979, "<>") = 0, "Missing", "Complete") -> Complete | D5: =IF(COUNTIFS('Country-Vehicle Extraction'!$A$2:$A$979, D$1, 'Country-Vehicle Extraction'!$B$2:$B$979, D$2, 'Country-Vehicle Extraction'!$C$2:$C$979, "Total", 'Country-Vehicle Extraction'!$E$2:$E$979, $A5, 'Country-Vehicle Extraction'!$J$2:$J$979, "<>") = 0, "Missing", "Complete") -> Complete | E5: =IF(COUNTIFS('Country-Vehicle Extraction'!$A$2:$A$979, D$1, 'Country-Vehicle Extraction'!$B$2:$B$979, D$2, 'Country-Vehicle Extraction'!$C$2:$C$979, "<>All", 'Country-Vehicle Extraction'!$E$2:$E$979, $A5, 'Country-Vehicle Extraction'!$J$2:$J$979, "<>") = 0, "Missing", "Complete") -> Complete | F5: =IF(COUNTIFS('Country-Vehicle Extraction'!$A$2:$A$979, D$1, 'Country-Vehicle Extraction'!$B$2:$B$979, F$2, 'Country-Vehicle Extraction'!$C$2:$C$979, "Total", 'Country-Vehicle Extraction'!$E$2:$E$979, $A5, 'Country-Vehicle Extraction'!$J$2:$J$979, "<>") = 0, "Missing", "Complete") -> Complete | G5: =IF(COUNTIFS('Country-Vehicle Extraction'!$A$2:$A$979, D$1, 'Country-Vehicle Extraction'!$B$2:$B$979, F$2, 'Country-Vehicle Extraction'!$C$2:$C$979, "<>All", 'Country-Vehicle Extraction'!$E$2:$E$979, $A5, 'Country-Vehicle Extraction'!$J$2:$J$979, "<>") = 0, "Missing", "Complete") -> Complete | H5: Microdata: HCES | I5: Microdata: HCES
A6: Vehicle consumption by WRA -- amount | B6: =IF(COUNTIFS('Country-Vehicle Extraction'!$A$2:$A$979, B$1, 'Country-Vehicle Extraction'!$B$2:$B$979, B$2, 'Country-Vehicle Extraction'!$C$2:$C$979, "Total", 'Country-Vehicle Extraction'!$E$2:$E$979, $A6, 'Country-Vehicle Extraction'!$J$2:$J$979, "<>") = 0, "Missing", "Complete") -> Complete | C6: =IF(COUNTIFS('Country-Vehicle Extraction'!$A$2:$A$979, B$1, 'Country-Vehicle Extraction'!$B$2:$B$979, B$2, 'Country-Vehicle Extraction'!$C$2:$C$979, "<>All", 'Country-Vehicle Extraction'!E$2:E$979, $A6, 'Country-Vehicle Extraction'!$J$2:$J$979, "<>") = 0, "Missing", "Complete") -> Complete | D6: =IF(COUNTIFS('Country-Vehicle Extraction'!$A$2:$A$979, D$1, 'Country-Vehicle Extraction'!$B$2:$B$979, D$2, 'Country-Vehicle Extraction'!$C$2:$C$979, "Total", 'Country-Vehicle Extraction'!$E$2:$E$979, $A6, 'Country-Vehicle Extraction'!$J$2:$J$979, "<>") = 0, "Missing", "Complete") -> Complete | E6: =IF(COUNTIFS('Country-Vehicle Extraction'!$A$2:$A$979, D$1, 'Country-Vehicle Extraction'!$B$2:$B$979, D$2, 'Country-Vehicle Extraction'!$C$2:$C$979, "<>All", 'Country-Vehicle Extraction'!$E$2:$E$979, $A6, 'Country-Vehicle Extraction'!$J$2:$J$979, "<>") = 0, "Missing", "Complete") -> Complete | F6: =IF(COUNTIFS('Country-Vehicle Extraction'!$A$2:$A$979, D$1, 'Country-Vehicle Extraction'!$B$2:$B$979, F$2, 'Country-Vehicle Extraction'!$C$2:$C$979, "Total", 'Country-Vehicle Extraction'!$E$2:$E$979, $A6, 'Country-Vehicle Extraction'!$J$2:$J$979, "<>") = 0, "Missing", "Complete") -> Complete | G6: =IF(COUNTIFS('Country-Vehicle Extraction'!$A$2:$A$979, D$1, 'Country-Vehicle Extraction'!$B$2:$B$979, F$2, 'Country-Vehicle Extraction'!$C$2:$C$979, "<>All", 'Country-Vehicle Extraction'!$E$2:$E$979, $A6, 'Country-Vehicle Extraction'!$J$2:$J$979, "<>") = 0, "Missing", "Complete") -> Complete | H6: Microdata: HCES | I6: Microdata: HCES
A7: Vehicle consumption by U5 children -- any | B7: =IF(COUNTIFS('Country-Vehicle Extraction'!$A$2:$A$979, B$1, 'Country-Vehicle Extraction'!$B$2:$B$979, B$2, 'Country-Vehicle Extraction'!$C$2:$C$979, "Total", 'Country-Vehicle Extraction'!$E$2:$E$979, $A7, 'Country-Vehicle Extraction'!$J$2:$J$979, "<>") = 0, "Missing", "Complete") -> Missing | C7: =IF(COUNTIFS('Country-Vehicle Extraction'!$A$2:$A$979, B$1, 'Country-Vehicle Extraction'!$B$2:$B$979, B$2, 'Country-Vehicle Extraction'!$C$2:$C$979, "<>All", 'Country-Vehicle Extraction'!E$2:E$979, $A7, 'Country-Vehicle Extraction'!$J$2:$J$979, "<>") = 0, "Missing", "Complete") -> Complete | D7: =IF(COUNTIFS('Country-Vehicle Extraction'!$A$2:$A$979, D$1, 'Country-Vehicle Extraction'!$B$2:$B$979, D$2, 'Country-Vehicle Extraction'!$C$2:$C$979, "Total", 'Country-Vehicle Extraction'!$E$2:$E$979, $A7, 'Country-Vehicle Extraction'!$J$2:$J$979, "<>") = 0, "Missing", "Complete") -> Complete | E7: =IF(COUNTIFS('Country-Vehicle Extraction'!$A$2:$A$979, D$1, 'Country-Vehicle Extraction'!$B$2:$B$979, D$2, 'Country-Vehicle Extraction'!$C$2:$C$979, "<>All", 'Country-Vehicle Extraction'!$E$2:$E$979, $A7, 'Country-Vehicle Extraction'!$J$2:$J$979, "<>") = 0, "Missing", "Complete") -> Complete | F7: =IF(COUNTIFS('Country-Vehicle Extraction'!$A$2:$A$979, D$1, 'Country-Vehicle Extraction'!$B$2:$B$979, F$2, 'Country-Vehicle Extraction'!$C$2:$C$979, "Total", 'Country-Vehicle Extraction'!$E$2:$E$979, $A7, 'Country-Vehicle Extraction'!$J$2:$J$979, "<>") = 0, "Missing", "Complete") -> Complete | G7: =IF(COUNTIFS('Country-Vehicle Extraction'!$A$2:$A$979, D$1, 'Country-Vehicle Extraction'!$B$2:$B$979, F$2, 'Country-Vehicle Extraction'!$C$2:$C$979, "<>All", 'Country-Vehicle Extraction'!$E$2:$E$979, $A7, 'Country-Vehicle Extraction'!$J$2:$J$979, "<>") = 0, "Missing", "Complete") -> Complete | H7: Microdata: HCES | I7: Microdata: HCES
A8: Vehicle consumption by U5 children -- amount | B8: =IF(COUNTIFS('Country-Vehicle Extraction'!$A$2:$A$979, B$1, 'Country-Vehicle Extraction'!$B$2:$B$979, B$2, 'Country-Vehicle Extraction'!$C$2:$C$979, "Total", 'Country-Vehicle Extraction'!$E$2:$E$979, $A8, 'Country-Vehicle Extraction'!$J$2:$J$979, "<>") = 0, "Missing", "Complete") -> Complete | C8: =IF(COUNTIFS('Country-Vehicle Extraction'!$A$2:$A$979, B$1, 'Country-Vehicle Extraction'!$B$2:$B$979, B$2, 'Country-Vehicle Extraction'!$C$2:$C$979, "<>All", 'Country-Vehicle Extraction'!E$2:E$979, $A8, 'Country-Vehicle Extraction'!$J$2:$J$979, "<>") = 0, "Missing", "Complete") -> Complete | D8: =IF(COUNTIFS('Country-Vehicle Extraction'!$A$2:$A$979, D$1, 'Country-Vehicle Extraction'!$B$2:$B$979, D$2, 'Country-Vehicle Extraction'!$C$2:$C$979, "Total", 'Country-Vehicle Extraction'!$E$2:$E$979, $A8, 'Country-Vehicle Extraction'!$J$2:$J$979, "<>") = 0, "Missing", "Complete") -> Complete | E8: =IF(COUNTIFS('Country-Vehicle Extraction'!$A$2:$A$979, D$1, 'Country-Vehicle Extraction'!$B$2:$B$979, D$2, 'Country-Vehicle Extraction'!$C$2:$C$979, "<>All", 'Country-Vehicle Extraction'!$E$2:$E$979, $A8, 'Country-Vehicle Extraction'!$J$2:$J$979, "<>") = 0, "Missing", "Complete") -> Complete | F8: =IF(COUNTIFS('Country-Vehicle Extraction'!$A$2:$A$979, D$1, 'Country-Vehicle Extraction'!$B$2:$B$979, F$2, 'Country-Vehicle Extraction'!$C$2:$C$979, "Total", 'Country-Vehicle Extraction'!$E$2:$E$979, $A8, 'Country-Vehicle Extraction'!$J$2:$J$979, "<>") = 0, "Missing", "Complete") -> Complete | G8: =IF(COUNTIFS('Country-Vehicle Extraction'!$A$2:$A$979, D$1, 'Country-Vehicle Extraction'!$B$2:$B$979, F$2, 'Country-Vehicle Extraction'!$C$2:$C$979, "<>All", 'Country-Vehicle Extraction'!$E$2:$E$979, $A8, 'Country-Vehicle Extraction'!$J$2:$J$979, "<>") = 0, "Missing", "Complete") -> Complete | H8: Microdata: HCES | I8: Microdata: HCES
A9: Vehicle "fortifiability" (essentially amount industrially produced) | B9: =IF(COUNTIFS('Country-Vehicle Extraction'!$A$2:$A$979, B$1, 'Country-Vehicle Extraction'!$B$2:$B$979, B$2, 'Country-Vehicle Extraction'!$C$2:$C$979, "Total", 'Country-Vehicle Extraction'!$E$2:$E$979, $A9, 'Country-Vehicle Extraction'!$J$2:$J$979, "<>") = 0, "Missing", "Complete") -> Missing | C9: =IF(COUNTIFS('Country-Vehicle Extraction'!$A$2:$A$979, B$1, 'Country-Vehicle Extraction'!$B$2:$B$979, B$2, 'Country-Vehicle Extraction'!$C$2:$C$979, "<>All", 'Country-Vehicle Extraction'!E$2:E$979, $A9, 'Country-Vehicle Extraction'!$J$2:$J$979, "<>") = 0, "Missing", "Complete") -> Complete | D9: =IF(COUNTIFS('Country-Vehicle Extraction'!$A$2:$A$979, D$1, 'Country-Vehicle Extraction'!$B$2:$B$979, D$2, 'Country-Vehicle Extraction'!$C$2:$C$979, "Total", 'Country-Vehicle Extraction'!$E$2:$E$979, $A9, 'Country-Vehicle Extraction'!$J$2:$J$979, "<>") = 0, "Missing", "Complete") -> Complete | E9: =IF(COUNTIFS('Country-Vehicle Extraction'!$A$2:$A$979, D$1, 'Country-Vehicle Extraction'!$B$2:$B$979, D$2, 'Country-Vehicle Extraction'!$C$2:$C$979, "<>All", 'Country-Vehicle Extraction'!$E$2:$E$979, $A9, 'Country-Vehicle Extraction'!$J$2:$J$979, "<>") = 0, "Missing", "Complete") -> Complete | F9: =IF(COUNTIFS('Country-Vehicle Extraction'!$A$2:$A$979, D$1, 'Country-Vehicle Extraction'!$B$2:$B$979, F$2, 'Country-Vehicle Extraction'!$C$2:$C$979, "Total", 'Country-Vehicle Extraction'!$E$2:$E$979, $A9, 'Country-Vehicle Extraction'!$J$2:$J$979, "<>") = 0, "Missing", "Complete") -> Missing | G9: =IF(COUNTIFS('Country-Vehicle Extraction'!$A$2:$A$979, D$1, 'Country-Vehicle Extraction'!$B$2:$B$979, F$2, 'Country-Vehicle Extraction'!$C$2:$C$979, "<>All", 'Country-Vehicle Extraction'!$E$2:$E$979, $A9, 'Country-Vehicle Extraction'!$J$2:$J$979, "<>") = 0, "Missing", "Complete") -> Complete | H9: =IF(COUNTIFS('Country-Vehicle Extraction'!$A$2:$A$979, H$1, 'Country-Vehicle Extraction'!$B$2:$B$979, H$2, 'Country-Vehicle Extraction'!$C$2:$C$979, "Total", 'Country-Vehicle Extraction'!$E$2:$E$979, $A9, 'Country-Vehicle Extraction'!$J$2:$J$979, "<>") = 0, "Missing", "Complete") -> Complete | I9: Microdata: HCES

Sheet Country-Vehicle Extraction
A1: Country | B1: Vehicle | C1: Quintile | D1: Sex | E1: Data need | F1: Data point name | G1: Units | H1: Year | I1: Data source | J1: Value | K1: CI | L1: SE | M1: Notes
A2: Ethiopia | B2: Salt | C2: All (assumed same) | D2: Female | E2: Vehicle consumption by WRA -- any | F2: percentage | G2: % | I2: EPHI data sent by Andy Garcia | J2: 0.97 | M2: Total population (?), not WRA specifically; Not stratified by wealth quintile
A3: Ethiopia | B3: Salt | C3: Total | D3: Female | E3: Vehicle consumption by WRA -- amount | F3: mean | G3: g/day | I3: EPHI data sent by Andy Garcia | J3: 7.1 | M3: 2022 National Nutrition Survey; Total population (?), not WRA specifically
A4: Ethiopia | B4: Salt | C4: Lowest | D4: Female | E4: Vehicle consumption by WRA -- amount | F4: mean | G4: g/day | I4: EPHI data sent by Andy Garcia | J4: 7.1
A5: Ethiopia | B5: Salt | C5: Second | D5: Female | E5: Vehicle consumption by WRA -- amount | F5: mean | G5: g/day | I5: EPHI data sent by Andy Garcia | J5: 7.2
A6: Ethiopia | B6: Salt | C6: Middle | D6: Female | E6: Vehicle consumption by WRA -- amount | F6: mean | G6: g/day | I6: EPHI data sent by Andy Garcia | J6: 7.7
A7: Ethiopia | B7: Salt | C7: Fourth | D7: Female | E7: Vehicle consumption by WRA -- amount | F7: mean | G7: g/day | I7: EPHI data sent by Andy Garcia | J7: 7.2
A8: Ethiopia | B8: Salt | C8: Highest | D8: Female | E8: Vehicle consumption by WRA -- amount | F8: mean | G8: g/day | I8: EPHI data sent by Andy Garcia | J8: 6.5
A9: Ethiopia | B9: Salt | C9: All (assumed same) | D9: Female | E9: Vehicle consumption by WRA -- amount | F9: standard deviation | G9: g/day | I9: Survey in Addis Ababa | J9: 2.2 | M9: https://www.ncbi.nlm.nih.gov/pmc/articles/PMC10195378/; among all adults
A10: Ethiopia | B10: Salt | C10: All (assumed same) | D10: All (assumed same) | E10: Vehicle consumption by U5 children -- any | F10: percentage | G10: % | J10: 0.97 | M10: Total population (?), not U5 specifically
A11: Ethiopia | B11: Salt | C11: Total | D11: All (assumed same) | E11: Vehicle consumption by U5 children -- amount | F11: mean | G11: g/day | I11: EPHI data sent by Andy Garcia | J11: 7.1 | M11: 2022 National Nutrition Survey; Total population (?), not U5 specifically
A12: Ethiopia | B12: Salt | C12: Lowest | D12: All (assumed same) | E12: Vehicle consumption by U5 children -- amount | F12: mean | G12: g/day | I12: EPHI data sent by Andy Garcia | J12: 7.1
A13: Ethiopia | B13: Salt | C13: Second | D13: All (assumed same) | E13: Vehicle consumption by U5 children -- amount | F13: mean | G13: g/day | I13: EPHI data sent by Andy Garcia | J13: 7.2
A14: Ethiopia | B14: Salt | C14: Middle | D14: All (assumed same) | E14: Vehicle consumption by U5 children -- amount | F14: mean | G14: g/day | I14: EPHI data sent by Andy Garcia | J14: 7.7
A15: Ethiopia | B15: Salt | C15: Fourth | D15: All (assumed same) | E15: Vehicle consumption by U5 children -- amount | F15: mean | G15: g/day | I15: EPHI data sent by Andy Garcia | J15: 7.2
A16: Ethiopia | B16: Salt | C16: Highest | D16: All (assumed same) | E16: Vehicle consumption by U5 children -- amount | F16: mean | G16: g/day | I16: EPHI data sent by Andy Garcia | J16: 6.5
A17: Ethiopia | B17: Salt | C17: All (assumed same) | D17: All (assumed same) | E17: Vehicle consumption by U5 children -- amount | F17: standard deviation | G17: g/day | I17: Survey in Addis Ababa | J17: 2.2 | M17: https://www.ncbi.nlm.nih.gov/pmc/articles/PMC10195378/; among all adults
A18: Ethiopia | B18: Salt | C18: All (assumed same) | D18: All (assumed same) | E18: Vehicle "fortifiability" (essentially amount industrially produced) | F18: percentage | G18: % | I18: Assumption | J18: 1 | M18: "Almost all households in Ethiopia have access to iodized salt." ~ National Food and Nutrition Strategy Baseline Survey
A19: Nigeria | B19: Bouillon | C19: Total | D19: Female | E19: Vehicle consumption by WRA -- any | F19: percentage | G19: % | H19: 2021 | I19: NFCMS | J19: 0.981 | K19: [97.5,98.8] | M19: https://www.unicef.org/nigeria/media/9271/file/%20National%20Food%20Consumption%20and%20Micronutrient%20Survey%20(2021).pdf
A20: Nigeria | B20: Bouillon | C20: Lowest | D20: Female | E20: Vehicle consumption by WRA -- any | F20: percentage | G20: % | H20: 2021 | I20: NFCMS | J20: 0.963 | K20: [94.2, 98.4] | M20: Table 169, page 220
A21: Nigeria | B21: Bouillon | C21: Second | D21: Female | E21: Vehicle consumption by WRA -- any | F21: percentage | G21: % | H21: 2021 | I21: NFCMS | J21: 0.981 | K21: [96.8, 99.3] | M21: 95% CI
A22: Nigeria | B22: Bouillon | C22: Middle | D22: Female | E22: Vehicle consumption by WRA -- any | F22: percentage | G22: % | H22: 2021 | I22: NFCMS | J22: 0.992 | K22: [98.5, 99.8] | M22: These numbers are for non-pregnant WRA, not all WRA
A23: Nigeria | B23: Bouillon | C23: Fourth | D23: Female | E23: Vehicle consumption by WRA -- any | F23: percentage | G23: % | H23: 2021 | I23: NFCMS | J23: 0.986 | K23: [97.8, 99.4]
A24: Nigeria | B24: Bouillon | C24: Highest | D24: Female | E24: Vehicle consumption by WRA -- any | F24: percentage | G24: % | H24: 2021 | I24: NFCMS | J24: 0.986 | K24: [97.5, 99.7]
A25: Nigeria | B25: Bouillon | C25: Total | D25: Female | E25: Vehicle consumption by WRA -- amount | F25: mean | G25: g/day | H25: 2021 | I25: NFCMS | J25: 6.3 | K25: [6.0, 6.6] | L25: 0.1 | M25: Table 170, page 222
A26: Nigeria | B26: Bouillon | C26: Lowest | D26: Female | E26: Vehicle consumption by WRA -- amount | F26: mean | G26: g/day | H26: 2021 | I26: NFCMS | J26: 8.4 | K26: [7.7, 9.0] | L26: 0.3 | M26: 95% CI
A27: Nigeria | B27: Bouillon | C27: Second | D27: Female | E27: Vehicle consumption by WRA -- amount | F27: mean | G27: g/day | H27: 2021 | I27: NFCMS | J27: 8 | K27: [7.3, 8.7] | L27: 0.3 | M27: Pregnant and non-pregnant WRA have been stratified in the NFCMS final report, these are the non-pregnant numbers
A28: Nigeria | B28: Bouillon | C28: Middle | D28: Female | E28: Vehicle consumption by WRA -- amount | F28: mean | G28: g/day | H28: 2021 | I28: NFCMS | J28: 5.9 | K28: [5.3, 6.5] | L28: 0.3 | M28: Also, these numbers are across all women, not just those who consume bouillon
A29: Nigeria | B29: Bouillon | C29: Fourth | D29: Female | E29: Vehicle consumption by WRA -- amount | F29: mean | G29: g/day | H29: 2021 | I29: NFCMS | J29: 4.9 | K29: [4.3, 5.4] | L29: 0.3
A30: Nigeria | B30: Bouillon | C30: Highest | D30: Female | E30: Vehicle consumption by WRA -- amount | F30: mean | G30: g/day | H30: 2021 | I30: NFCMS | J30: 4.6 | K30: [4.1, 5.2] | L30: 0.3
A31: Nigeria | B31: Bouillon | C31: Total | D31: Female | E31: Vehicle consumption by WRA -- amount | F31: standard deviation | G31: g/day | H31: 2021 | I31: NFCMS | J31: 3.037037 | M31: Very rough estimate using SD = IQR / 1.35 (normality assumption), IQR reported in table 170
A32: Nigeria | B32: Bouillon | C32: Lowest | D32: Female | E32: Vehicle consumption by WRA -- amount | F32: standard deviation | G32: g/day | H32: 2021 | I32: NFCMS | J32: 3.6296296
A33: Nigeria | B33: Bouillon | C33: Second | D33: Female | E33: Vehicle consumption by WRA -- amount | F33: standard deviation | G33: g/day | H33: 2021 | I33: NFCMS | J33: 3.1111111
A34: Nigeria | B34: Bouillon | C34: Middle | D34: Female | E34: Vehicle consumption by WRA -- amount | F34: standard deviation | G34: g/day | H34: 2021 | I34: NFCMS | J34: 2.962963
A35: Nigeria | B35: Bouillon | C35: Fourth | D35: Female | E35: Vehicle consumption by WRA -- amount | F35: standard deviation | G35: g/day | H35: 2021 | I35: NFCMS | J35: 2.4444444
A36: Nigeria | B36: Bouillon | C36: Highest | D36: Female | E36: Vehicle consumption by WRA -- amount | F36: standard deviation | G36: g/day | H36: 2021 | I36: NFCMS | J36: 1.7037037
A37: Nigeria | B37: Bouillon | C37: Total | D37: All (assumed same) | E37: Vehicle consumption by U5 children -- any | F37: percentage | G37: % | H37: 2021 | I37: NFCMS | J37: 0.988 | K37: [98.3,99.2] | M37: Annex 43, page 549
A38: Nigeria | B38: Bouillon | C38: Lowest | D38: All (assumed same) | E38: Vehicle consumption by U5 children -- any | F38: percentage | G38: % | H38: 2021 | I38: NFCMS | J38: 0.963 | K38: [94.2, 98.4] | M38: Children 6-59 months old (doesn't include U6months)
A39: Nigeria | B39: Bouillon | C39: Second | D39: All (assumed same) | E39: Vehicle consumption by U5 children -- any | F39: percentage | G39: % | H39: 2021 | I39: NFCMS | J39: 0.981 | K39: [96.8, 99.3] | M39: Not stratified by wealth quintile for children; wealth stratification numbers are for WRA
A40: Nigeria | B40: Bouillon | C40: Middle | D40: All (assumed same) | E40: Vehicle consumption by U5 children -- any | F40: percentage | G40: % | H40: 2021 | I40: NFCMS | J40: 0.992 | K40: [98.5, 99.8] | M40: 95% CI
...

Sheet Country-Vehicle-Fortif Progress
A1: Country | B1: Ethiopia | F1: Nigeria | N1: India
A2: Vehicle | B2: Salt | F2: Bouillon | J2: Rice | N2: Rice
A3: Fortificant | B3: Folate | D3: Iron | F3: Folate | H3: Iron | J3: Folate | L3: Iron | N3: Folate | P3: Iron
A4: Wealth | B4: Overall | C4: Quintile | D4: Overall | E4: Quintile | F4: Overall | G4: Quintile | H4: Overall | I4: Quintile | J4: Overall | K4: Quintile | L4: Overall | M4: Quintile | N4: Overall | O4: Quintile | P4: Overall | Q4: Quintile
A5: Data need
A6: Vehicle fortification at baseline -- any | B6: Zero | C6: Zero | D6: Not modeled | E6: Not modeled | F6: Zero | G6: Zero | H6: =IF(COUNTIFS('Country-Vehicle-Fort Extraction'!$A$2:$A$944, F$1, 'Country-Vehicle-Fort Extraction'!$B$2:$B$944, F$2, 'Country-Vehicle-Fort Extraction'!$C$2:$C$944, H$3, 'Country-Vehicle-Fort Extraction'!$D$2:$D$944, "Total", 'Country-Vehicle-Fort Extraction'!$E$2:$E$944, $A6, 'Country-Vehicle-Fort Extraction'!$J$2:$J$944, "<>") = 0, "Missing", "Complete") -> Complete | I6: =IF(COUNTIFS('Country-Vehicle-Fort Extraction'!$A$2:$A$944, F$1, 'Country-Vehicle-Fort Extraction'!$B$2:$B$944, F$2, 'Country-Vehicle-Fort Extraction'!$C$2:$C$944, H$3, 'Country-Vehicle-Fort Extraction'!$D$2:$D$944, "<>All", 'Country-Vehicle-Fort Extraction'!$E$2:$E$944, $A6, 'Country-Vehicle-Fort Extraction'!$J$2:$J$944, "<>") < 5, "Missing", "Complete") -> Complete | J6: Zero | K6: Zero | L6: Zero | M6: Zero | N6: Microdata: HCES | O6: Microdata: HCES | P6: Microdata: HCES | Q6: Microdata: HCES
A7: Vehicle fortification at baseline -- amount among fortified | B7: Zero | C7: Zero | D7: Not modeled | E7: Not modeled | F7: Zero | G7: Zero | H7: =IF(COUNTIFS('Country-Vehicle-Fort Extraction'!$A$2:$A$944, F$1, 'Country-Vehicle-Fort Extraction'!$B$2:$B$944, F$2, 'Country-Vehicle-Fort Extraction'!$C$2:$C$944, H$3, 'Country-Vehicle-Fort Extraction'!$D$2:$D$944, "Total", 'Country-Vehicle-Fort Extraction'!$E$2:$E$944, $A7, 'Country-Vehicle-Fort Extraction'!$J$2:$J$944, "<>") = 0, "Missing", "Complete") -> Missing | I7: =IF(COUNTIFS('Country-Vehicle-Fort Extraction'!$A$2:$A$944, F$1, 'Country-Vehicle-Fort Extraction'!$B$2:$B$944, F$2, 'Country-Vehicle-Fort Extraction'!$C$2:$C$944, H$3, 'Country-Vehicle-Fort Extraction'!$D$2:$D$944, "<>Total", 'Country-Vehicle-Fort Extraction'!$E$2:$E$944, $A7, 'Country-Vehicle-Fort Extraction'!$J$2:$J$944, "<>") < 5, "Missing", "Complete") -> Missing | J7: Zero | K7: Zero | L7: Zero | M7: Zero | N7: =IF(COUNTIFS('Country-Vehicle-Fort Extraction'!$A$2:$A$944, N$1, 'Country-Vehicle-Fort Extraction'!$B$2:$B$944, N$2, 'Country-Vehicle-Fort Extraction'!$C$2:$C$944, N$3, 'Country-Vehicle-Fort Extraction'!$D$2:$D$944, "All", 'Country-Vehicle-Fort Extraction'!$E$2:$E$944, $A7, 'Country-Vehicle-Fort Extraction'!$J$2:$J$944, "<>") = 0, "Missing", "Complete") -> Missing | O7: N/A | P7: =IF(COUNTIFS('Country-Vehicle-Fort Extraction'!$A$2:$A$944, N$1, 'Country-Vehicle-Fort Extraction'!$B$2:$B$944, N$2, 'Country-Vehicle-Fort Extraction'!$C$2:$C$944, P$3, 'Country-Vehicle-Fort Extraction'!$D$2:$D$944, "All", 'Country-Vehicle-Fort Extraction'!$E$2:$E$944, $A7, 'Country-Vehicle-Fort Extraction'!$J$2:$J$944, "<>") = 0, "Missing", "Complete") -> Missing | Q7: N/A
A8: Baseline effective % of fortified | B8: Zero | C8: Zero | D8: Not modeled | E8: Not modeled | F8: Zero | G8: Zero | H8: =IF(COUNTIFS('Country-Vehicle-Fort Extraction'!$A$2:$A$944, F$1, 'Country-Vehicle-Fort Extraction'!$B$2:$B$944, F$2, 'Country-Vehicle-Fort Extraction'!$C$2:$C$944, H$3, 'Country-Vehicle-Fort Extraction'!$D$2:$D$944, "Total", 'Country-Vehicle-Fort Extraction'!$E$2:$E$944, $A8, 'Country-Vehicle-Fort Extraction'!$J$2:$J$944, "<>") = 0, "Missing", "Complete") -> Missing | I8: =IF(COUNTIFS('Country-Vehicle-Fort Extraction'!$A$2:$A$944, F$1, 'Country-Vehicle-Fort Extraction'!$B$2:$B$944, F$2, 'Country-Vehicle-Fort Extraction'!$C$2:$C$944, H$3, 'Country-Vehicle-Fort Extraction'!$D$2:$D$944, "<>Total", 'Country-Vehicle-Fort Extraction'!$E$2:$E$944, $A8, 'Country-Vehicle-Fort Extraction'!$J$2:$J$944, "<>") < 5, "Missing", "Complete") -> Missing | J8: Zero | K8: Zero | L8: Zero | M8: Zero | N8: =IF(COUNTIFS('Country-Vehicle-Fort Extraction'!$A$2:$A$944, N$1, 'Country-Vehicle-Fort Extraction'!$B$2:$B$944, N$2, 'Country-Vehicle-Fort Extraction'!$C$2:$C$944, N$3, 'Country-Vehicle-Fort Extraction'!$D$2:$D$944, "All", 'Country-Vehicle-Fort Extraction'!$E$2:$E$944, $A8, 'Country-Vehicle-Fort Extraction'!$J$2:$J$944, "<>") = 0, "Missing", "Complete") -> Missing | O8: N/A | P8: =IF(COUNTIFS('Country-Vehicle-Fort Extraction'!$A$2:$A$944, N$1, 'Country-Vehicle-Fort Extraction'!$B$2:$B$944, N$2, 'Country-Vehicle-Fort Extraction'!$C$2:$C$944, P$3, 'Country-Vehicle-Fort Extraction'!$D$2:$D$944, "All", 'Country-Vehicle-Fort Extraction'!$E$2:$E$944, $A8, 'Country-Vehicle-Fort Extraction'!$J$2:$J$944, "<>") = 0, "Missing", "Complete") -> Missing | Q8: N/A

Sheet Country-Vehicle-Fort Extraction
A1: Country | B1: Vehicle | C1: Fortificant | D1: Quintile | E1: Data need | F1: Data point name | G1: Units | H1: Year | I1: Data source | J1: Value | K1: CI | L1: Notes
A2: Ethiopia | B2: Salt | C2: Folate | D2: All (assumed same) | E2: Vehicle fortification at baseline -- any | F2: percentage | G2: % | I2: Assumption | J2: 0
A3: Ethiopia | B3: Salt | C3: Folate | D3: All (assumed same) | E3: Vehicle fortification at baseline -- amount among fortified | F3: concentration | G3: mcg/g | I3: Assumption | J3: 0
A4: Nigeria | B4: Rice | C4: Folate | D4: All (assumed same) | E4: Vehicle fortification at baseline -- any | F4: percentage | G4: % | I4: Assumption | J4: 0 | L4: Jonathan Gorstein, 8/30
A5: Nigeria | B5: Rice | C5: Folate | D5: All (assumed same) | E5: Vehicle fortification at baseline -- amount among fortified | F5: concentration | G5: mcg/g | I5: Assumption | J5: 0 | L5: Jonathan Gorstein, 8/30
A6: Nigeria | B6: Rice | C6: Iron | D6: All (assumed same) | E6: Vehicle fortification at baseline -- any | F6: percentage | G6: % | I6: Assumption | J6: 0 | L6: Jonathan Gorstein, 8/30
A7: Nigeria | B7: Rice | C7: Iron | D7: All (assumed same) | E7: Vehicle fortification at baseline -- amount among fortified | F7: concentration | G7: mcg/g | I7: Assumption | J7: 0 | L7: Jonathan Gorstein, 8/30
A8: Nigeria | B8: Bouillon | C8: Iron | D8: Total | E8: Vehicle fortification at baseline -- any | F8: percentage | G8: % | I8: Assumption | J8: 0.61875637 | L8: Assumption: labeled as fortified = fortified (basically true for salt). Divided "consumed food labeled as fortified" by "consumed food".
A9: Nigeria | B9: Bouillon | C9: Iron | D9: Lowest | E9: Vehicle fortification at baseline -- any | F9: percentage | G9: % | I9: Assumption | J9: 0.5192108
A10: Nigeria | B10: Bouillon | C10: Iron | D10: Second | E10: Vehicle fortification at baseline -- any | F10: percentage | G10: % | I10: Assumption | J10: 0.58409786
A11: Nigeria | B11: Bouillon | C11: Iron | D11: Middle | E11: Vehicle fortification at baseline -- any | F11: percentage | G11: % | I11: Assumption | J11: 0.63810484
A12: Nigeria | B12: Bouillon | C12: Iron | D12: Fourth | E12: Vehicle fortification at baseline -- any | F12: percentage | G12: % | I12: Assumption | J12: 0.6693712
A13: Nigeria | B13: Bouillon | C13: Iron | D13: Highest | E13: Vehicle fortification at baseline -- any | F13: percentage | G13: % | I13: Assumption | J13: 0.69979716
A14: Nigeria | B14: Bouillon | C14: Iron | D14: All (assumed same) | E14: Vehicle fortification at baseline -- amount among fortified | F14: concentration | G14: mcg/g | I14: Assumption | J14: 420 | L14: Maggi cubes (most popular brand and format) claim to have 15% NRV per serving (https://www.nestle-cwa.com/en/ask-nestle/products-brands/what-is-in-the-maggi-cube), but according to Jonathan Gorstein email on July 27th it is actually 12%; https://www.wolframalpha.com/input?i=12%25+of+14mg+per+4+grams+in+mcg%2Fg
A15: Nigeria | B15: Bouillon | C15: Folate | D15: All (assumed same) | E15: Vehicle fortification at baseline -- any | F15: percentage | G15: % | I15: Assumption | J15: 0 | L15: There is some information on fraction labeled as fortified in NFCMS Table 169, but it Figure 71 shows that 95% of WRA have RBC folate insufficiency. Also: '61 percent of the non-pregnant women from households consumed bouillons that are labelled as fortified with iodine and/or iron.' There is some evidence that the rich have more bouillon labeled as fortified (Table 169).
A16: Nigeria | B16: Bouillon | C16: Folate | D16: All (assumed same) | E16: Vehicle fortification at baseline -- amount among fortified | F16: concentration | G16: mcg/g | I16: Assumption | J16: 0
A17: India | B17: Rice | C17: Iron | D17: All (assumed same) | E17: Vehicle fortification at baseline -- amount among fortified | F17: concentration | G17: mcg/g | I17: slide deck JG shared to ADF, credited to Helena.Pachon@emory.edu | J17: 42.5 | L17: Originally in mg/100g; https://www.wolframalpha.com/input?i=4.25+mg+per+100+grams+in+micrograms+per+gram
A18: India | B18: Rice | C18: Folate | D18: All (assumed same) | E18: Vehicle fortification at baseline -- amount among fortified | F18: concentration | G18: mcg/g | I18: slide deck JG shared to ADF, credited to Helena.Pachon@emory.edu | J18: 0.125 | L18: Originally in mcg/100g; https://www.wolframalpha.com/input?i=12.5+mcg+per+100+grams+in+micrograms+per+gram
A19: Nigeria | B19: Bouillon | C19: Iron | D19: All (assumed same) | E19: Baseline effective % of fortified | F19: percentage | G19: % | I19: Assumption | J19: 0 | L19: Jonathan Gorstein, 8/15
A20: Nigeria | B20: Bouillon | C20: Folate | D20: All (assumed same) | E20: Baseline effective % of fortified | F20: percentage | G20: % | I20: Assumption | J20: 0 | L20: Jonathan Gorstein, 8/15
A21: India | B21: Rice | C21: Iron | D21: All (assumed same) | E21: Baseline effective % of fortified | F21: percentage | G21: % | J21: 0.8 | L21: Same as intervention, for now
A22: India | B22: Rice | C22: Folate | D22: All (assumed same) | E22: Baseline effective % of fortified | F22: percentage | G22: % | J22: 0.8 | L22: Same as intervention, for now
A23: Ethiopia | B23: Salt | C23: Folate | D23: All (assumed same) | E23: Baseline effective % of fortified | F23: percentage | G23: % | J23: 0.8 | L23: Does not matter, no baseline fortification
A24: Nigeria | B24: Rice | C24: Folate | D24: All (assumed same) | E24: Baseline effective % of fortified | F24: percentage | G24: % | J24: 0.8 | L24: Does not matter, no baseline fortification
A25: Nigeria | B25: Rice | C25: Iron | D25: All (assumed same) | E25: Baseline effective % of fortified | F25: percentage | G25: % | J25: 0.8 | L25: Does not matter, no baseline fortification
A26: Nigeria | B26: Salt | C26: Folate | D26: All (assumed same) | E26: Vehicle fortification at baseline -- any | F26: percentage | G26: % | I26: Assumption | J26: 0 | L26: Nigeria mandates salt iodization, not folic acid; zero baseline FA recorded as data per the checklist.
A27: Nigeria | B27: Salt | C27: Folate | D27: All (assumed same) | E27: Vehicle fortification at baseline -- amount among fortified | F27: concentration | G27: mcg/g | I27: Assumption | J27: 0
A28: Nigeria | B28: Salt | C28: Folate | D28: All (assumed same) | E28: Baseline effective % of fortified | F28: percentage | G28: % | J28: 0.8 | L28: Does not matter, no baseline fortification
A29: Nigeria | B29: Wheat | C29: Iron | D29: All (assumed same) | E29: Vehicle fortification at baseline -- any | F29: percentage | G29: % | I29: DUMMY (MIC-7549) | J29: 0 | L29: DUMMY PLACEHOLDER (MIC-7549): value copied from the corresponding Rice row. Replace with real wheat data.
A30: Nigeria | B30: Wheat | C30: Iron | D30: All (assumed same) | E30: Vehicle fortification at baseline -- amount among fortified | F30: concentration | G30: mcg/g | I30: DUMMY (MIC-7549) | J30: 0 | L30: DUMMY PLACEHOLDER (MIC-7549): value copied from the corresponding Rice row. Replace with real wheat data.
A31: Nigeria | B31: Wheat | C31: Iron | D31: All (assumed same) | E31: Baseline effective % of fortified | F31: percentage | G31: % | I31: DUMMY (MIC-7549) | J31: 0.8 | L31: DUMMY PLACEHOLDER (MIC-7549): value copied from the corresponding Rice row. Replace with real wheat data.
A32: Nigeria | B32: Wheat | C32: Folate | D32: All (assumed same) | E32: Vehicle fortification at baseline -- any | F32: percentage | G32: % | I32: DUMMY (SSCI-2784) | J32: 0 | L32: DUMMY PLACEHOLDER (SSCI-2784): folate value copied from the corresponding Nigeria Rice Folate row. Replace with real wheat data.
A33: Nigeria | B33: Wheat | C33: Folate | D33: All (assumed same) | E33: Vehicle fortification at baseline -- amount among fortified | F33: concentration | G33: mcg/g | I33: DUMMY (SSCI-2784) | J33: 0 | L33: DUMMY PLACEHOLDER (SSCI-2784): folate value copied from the corresponding Nigeria Rice Folate row. Replace with real wheat data.
A34: Nigeria | B34: Wheat | C34: Folate | D34: All (assumed same) | E34: Baseline effective % of fortified | F34: percentage | G34: % | I34: DUMMY (SSCI-2784) | J34: 0.8 | L34: DUMMY PLACEHOLDER (SSCI-2784): folate value copied from the corresponding Nigeria Rice Folate row. Replace with real wheat data.
A35: India | B35: Wheat | C35: Iron | D35: All (assumed same) | E35: Vehicle fortification at baseline -- any | F35: percentage | G35: % | I35: DUMMY (MIC-7580) | J35: 0 | L35: DUMMY PLACEHOLDER (MIC-7580): value copied from the Nigeria wheat placeholder row (itself copied from Nigeria rice). Replace with real India wheat data.
A36: India | B36: Wheat | C36: Iron | D36: All (assumed same) | E36: Vehicle fortification at baseline -- amount among fortified | F36: concentration | G36: mcg/g | I36: DUMMY (MIC-7580) | J36: 0 | L36: DUMMY PLACEHOLDER (MIC-7580): value copied from the Nigeria wheat placeholder row (itself copied from Nigeria rice). Replace with real India wheat data.
A37: India | B37: Wheat | C37: Iron | D37: All (assumed same) | E37: Baseline effective % of fortified | F37: percentage | G37: % | I37: DUMMY (MIC-7580) | J37: 0.8 | L37: DUMMY PLACEHOLDER (MIC-7580): value copied from the Nigeria wheat placeholder row (itself copied from Nigeria rice). Replace with real India wheat data.
A38: India | B38: Salt | C38: Iron | D38: All (assumed same) | E38: Vehicle fortification at baseline -- any | F38: percentage | G38: % | I38: DUMMY (MIC-7580) | J38: 0 | L38: DUMMY PLACEHOLDER (MIC-7580): value copied from the India wheat placeholder row. Replace with real India salt data.
A39: India | B39: Salt | C39: Iron | D39: All (assumed same) | E39: Vehicle fortification at baseline -- amount among fortified | F39: concentration | G39: mcg/g | I39: DUMMY (MIC-7580) | J39: 0 | L39: DUMMY PLACEHOLDER (MIC-7580): value copied from the India wheat placeholder row. Replace with real India salt data.
A40: India | B40: Salt | C40: Iron | D40: All (assumed same) | E40: Baseline effective % of fortified | F40: percentage | G40: % | I40: DUMMY (MIC-7580) | J40: 0.8 | L40: DUMMY PLACEHOLDER (MIC-7580): value copied from the India wheat placeholder row. Replace with real India salt data.
...

Sheet Country Progress
A1: Country | B1: Ethiopia | D1: Nigeria | F1: India | H1: Notes
A2: Wealth | B2: Overall | C2: Quintile | D2: Overall | E2: Quintile | F2: Overall | G2: Quintile
A3: Data need
A4: Pregnant people hemoglobin levels at baseline | B4: Not modeled | C4: Not modeled | D4: GBD | E4: DHS 2018 | F4: GBD | G4: DHS 2016
A5: Serum/plasma folate levels at baseline | B5: =IF(COUNTIFS('Country Extraction'!$A$2:$A$980, B$1, 'Country Extraction'!$B$2:$B$980, "All", 'Country Extraction'!$C$2:$C$980, $A5) = 0, "Missing", "Complete") -> Missing | C5: =IF(COUNTIFS('Country Extraction'!$A$1:$A$995, D$1, 'Country Extraction'!$B$1:$B$995, "<>All", 'Country Extraction'!$C$1:$C$995, $A5, 'Country Extraction'!$H$1:$H$995, "<>") < 5, "Missing", "Complete") -> Missing | D5: =IF(COUNTIFS('Country Extraction'!$A$2:$A$980, D$1, 'Country Extraction'!$B$2:$B$980, "All", 'Country Extraction'!$C$2:$C$980, $A5) = 0, "Missing", "Complete") -> Missing | E5: =IF(COUNTIFS('Country Extraction'!$A$1:$A$995, F$1, 'Country Extraction'!$B$1:$B$995, "<>All", 'Country Extraction'!$C$1:$C$995, $A5, 'Country Extraction'!$H$1:$H$995, "<>") < 5, "Missing", "Complete") -> Missing | F5: =IF(COUNTIFS('Country Extraction'!$A$2:$A$980, F$1, 'Country Extraction'!$B$2:$B$980, "All", 'Country Extraction'!$C$2:$C$980, $A5) = 0, "Missing", "Complete") -> Missing | G5: =IF(COUNTIFS('Country Extraction'!$A$1:$A$995, H$1, 'Country Extraction'!$B$1:$B$995, "<>All", 'Country Extraction'!$C$1:$C$995, $A5, 'Country Extraction'!$H$1:$H$995, "<>") < 5, "Missing", "Complete") -> Missing
A6: RBC folate levels at baseline | B6: =IF(COUNTIFS('Country Extraction'!$A$2:$A$980, B$1, 'Country Extraction'!$B$2:$B$980, "All", 'Country Extraction'!$C$2:$C$980, $A6) = 0, "Missing", "Complete") -> Missing | C6: =IF(COUNTIFS('Country Extraction'!$A$1:$A$995, D$1, 'Country Extraction'!$B$1:$B$995, "<>All", 'Country Extraction'!$C$1:$C$995, $A6, 'Country Extraction'!$H$1:$H$995, "<>") < 5, "Missing", "Complete") -> Missing | D6: =IF(COUNTIFS('Country Extraction'!$A$2:$A$980, D$1, 'Country Extraction'!$B$2:$B$980, "All", 'Country Extraction'!$C$2:$C$980, $A6) = 0, "Missing", "Complete") -> Missing | E6: =IF(COUNTIFS('Country Extraction'!$A$1:$A$995, F$1, 'Country Extraction'!$B$1:$B$995, "<>All", 'Country Extraction'!$C$1:$C$995, $A6, 'Country Extraction'!$H$1:$H$995, "<>") < 5, "Missing", "Complete") -> Missing | F6: =IF(COUNTIFS('Country Extraction'!$A$2:$A$980, F$1, 'Country Extraction'!$B$2:$B$980, "All", 'Country Extraction'!$C$2:$C$980, $A6) = 0, "Missing", "Complete") -> Missing | G6: =IF(COUNTIFS('Country Extraction'!$A$1:$A$995, H$1, 'Country Extraction'!$B$1:$B$995, "<>All", 'Country Extraction'!$C$1:$C$995, $A6, 'Country Extraction'!$H$1:$H$995, "<>") < 5, "Missing", "Complete") -> Missing
A7: LBWSG prevalence | B7: Not modeled | C7: Not modeled | D7: GBD | E7: DHS 2018 | F7: GBD | G7: DHS 2016
A8: CGF prevalence | B8: Not modeled | C8: Not modeled | D8: GBD | E8: DHS 2018 | F8: GBD | G8: DHS 2016
A9: Measles prevalence | B9: Not modeled | C9: Not modeled | D9: GBD | E9: DHS 2018 | F9: GBD | G9: DHS 2016 | H9: We have microdata on whether child has received Measles 1 vaccination.
A10: LRI prevalence | B10: Not modeled | C10: Not modeled | D10: GBD | E10: =IF(COUNTIFS('Country Extraction'!$A$1:$A$995, F$1, 'Country Extraction'!$B$1:$B$995, "<>All", 'Country Extraction'!$C$1:$C$995, $A10, 'Country Extraction'!$H$1:$H$995, "<>") < 5, "Missing", "Complete") -> Missing | F10: GBD | G10: =IF(COUNTIFS('Country Extraction'!$A$1:$A$995, H$1, 'Country Extraction'!$B$1:$B$995, "<>All", 'Country Extraction'!$C$1:$C$995, $A10, 'Country Extraction'!$H$1:$H$995, "<>") < 5, "Missing", "Complete") -> Missing | H10: We have microdata on whether child has had cough in the last two weeks, or ARI prevalence in DHS final reports.
A11: Malaria prevalence | B11: Not modeled | C11: Not modeled | D11: GBD | E11: =IF(COUNTIFS('Country Extraction'!$A$1:$A$995, F$1, 'Country Extraction'!$B$1:$B$995, "<>All", 'Country Extraction'!$C$1:$C$995, $A11, 'Country Extraction'!$H$1:$H$995, "<>") < 5, "Missing", "Complete") -> Missing | F11: GBD | G11: DHS 2016 | H11: For India, we might have to use the DHS microdata for whether child has had fever in the last two weeks as a proxy for malaria.
A12: U5 hemoglobin levels at baseline | B12: Not modeled | C12: Not modeled | D12: GBD | E12: DHS 2018 | F12: GBD | G12: DHS 2016
A13: Maternal disorders incidence | B13: Not modeled | C13: Not modeled | D13: GBD | E13: DHS 2018 | F13: GBD | G13: DHS 2016 | H13: Using DHS' maternal mortality ratio as a proxy for maternal disorders
A14: Maternal hemorrhage incidence | B14: Not modeled | C14: Not modeled | D14: GBD | E14: DHS 2018 | F14: GBD | G14: DHS 2016 | H14: Using DHS' maternal mortality ratio as a proxy for maternal hemorrhage
A15: Neural tube defect deaths | B15: GBD | C15: =IF(COUNTIFS('Country Extraction'!$A$1:$A$995, D$1, 'Country Extraction'!$B$1:$B$995, "<>All", 'Country Extraction'!$C$1:$C$995, $A15, 'Country Extraction'!$H$1:$H$995, "<>") < 5, "Missing", "Complete") -> Missing | D15: GBD | E15: =IF(COUNTIFS('Country Extraction'!$A$1:$A$995, F$1, 'Country Extraction'!$B$1:$B$995, "<>All", 'Country Extraction'!$C$1:$C$995, $A15, 'Country Extraction'!$H$1:$H$995, "<>") < 5, "Missing", "Complete") -> Missing | F15: GBD | G15: =IF(COUNTIFS('Country Extraction'!$A$1:$A$995, H$1, 'Country Extraction'!$B$1:$B$995, "<>All", 'Country Extraction'!$C$1:$C$995, $A15, 'Country Extraction'!$H$1:$H$995, "<>") < 5, "Missing", "Complete") -> Missing

Sheet Country Extraction
A1: Country | B1: Quintile | C1: Data need | D1: Data point name | E1: Units | F1: Year | G1: Data source | H1: Value | I1: CI | J1: Notes
A2: Ethiopia | B2: All | C2: Serum folate levels at baseline | E2: ? | G2: ? | J2: potential data gap!
A3: Ethiopia | B3: Lowest | C3: Serum folate levels at baseline | E3: ? | G3: ? | J3: Back-calculate from GBD NTDs? (and DHS NTDs for wealth quintiles?)
A4: Ethiopia | B4: Second | C4: Serum folate levels at baseline | E4: ? | G4: ?
A5: Ethiopia | B5: Middle | C5: Serum folate levels at baseline | E5: ? | G5: ?
A6: Ethiopia | B6: Fourth | C6: Serum folate levels at baseline | E6: ? | G6: ?
A7: Ethiopia | B7: Highest | C7: Serum folate levels at baseline | E7: ? | G7: ?
A8: Nigeria | B8: All | C8: Serum folate levels at baseline | E8: ? | G8: ?
A9: Nigeria | B9: Lowest | C9: Serum folate levels at baseline | E9: ? | G9: ?
A10: Nigeria | B10: Second | C10: Serum folate levels at baseline | E10: ? | G10: ?
A11: Nigeria | B11: Middle | C11: Serum folate levels at baseline | E11: ? | G11: ?
A12: Nigeria | B12: Fourth | C12: Serum folate levels at baseline | E12: ? | G12: ?
A13: Nigeria | B13: Highest | C13: Serum folate levels at baseline | E13: ? | G13: ?
A14: India | B14: All | C14: Serum folate levels at baseline | E14: ? | G14: ?
A15: India | B15: Lowest | C15: Serum folate levels at baseline | E15: ? | G15: ?
... A19: India | B19: Highest | C19: Serum folate levels at baseline | E19: ? | G19: ?
A20: Ethiopia | B20: All | C20: Red blood cell folate levels at baseline -- Also called “whole blood lysate”? | E20: nmol/L? | G20: ? | J20: potential data gap!
A21: Ethiopia | B21: Lowest | C21: Red blood cell folate levels at baseline -- Also called “whole blood lysate”? | E21: nmol/L? | G21: ? | J21: Back-calculate from GBD NTDs? (and DHS NTDs for wealth quintiles?)
A22: Ethiopia | B22: Second | C22: Red blood cell folate levels at baseline -- Also called “whole blood lysate”? | E22: nmol/L? | G22: ?
A23: Ethiopia | B23: Middle | C23: Red blood cell folate levels at baseline -- Also called “whole blood lysate”? | E23: nmol/L? | G23: ?
A24: Ethiopia | B24: Fourth | C24: Red blood cell folate levels at baseline -- Also called “whole blood lysate”? | E24: nmol/L? | G24: ?
A25: Ethiopia | B25: Highest | C25: Red blood cell folate levels at baseline -- Also called “whole blood lysate”? | E25: nmol/L? | G25: ?
A26: Nigeria | B26: All | C26: Red blood cell folate levels at baseline -- Also called “whole blood lysate”? | E26: nmol/L? | G26: ?
A27: Nigeria | B27: Lowest | C27: Red blood cell folate levels at baseline -- Also called “whole blood lysate”? | E27: nmol/L? | G27: ?
A28: Nigeria | B28: Second | C28: Red blood cell folate levels at baseline -- Also called “whole blood lysate”? | E28: nmol/L? | G28: ?
A29: Nigeria | B29: Middle | C29: Red blood cell folate levels at baseline -- Also called “whole blood lysate”? | E29: nmol/L? | G29: ?
A30: Nigeria | B30: Fourth | C30: Red blood cell folate levels at baseline -- Also called “whole blood lysate”? | E30: nmol/L? | G30: ?
A31: Nigeria | B31: Highest | C31: Red blood cell folate levels at baseline -- Also called “whole blood lysate”? | E31: nmol/L? | G31: ?
A32: India | B32: All | C32: Red blood cell folate levels at baseline -- Also called “whole blood lysate”? | E32: nmol/L? | G32: ?
A33: India | B33: Lowest | C33: Red blood cell folate levels at baseline -- Also called “whole blood lysate”? | E33: nmol/L? | G33: ?
... A37: India | B37: Highest | C37: Red blood cell folate levels at baseline -- Also called “whole blood lysate”? | E37: nmol/L? | G37: ?
A38: Ethiopia | B38: All | C38: Pregnancies longer than 7 months | G38: Most recent DHS for Ethiopia
A39: Ethiopia | B39: Lowest | C39: Pregnancies longer than 7 months | G39: Ethiopia DHS survey report Table 8.4
A40: Ethiopia | B40: Second | C40: Pregnancies longer than 7 months | G40: Ethiopia DHS survey report Table 8.4
A41: Ethiopia | B41: Middle | C41: Pregnancies longer than 7 months | G41: Ethiopia DHS survey report Table 8.4
A42: Ethiopia | B42: Fourth | C42: Pregnancies longer than 7 months | G42: Ethiopia DHS survey report Table 8.4
A43: Ethiopia | B43: Highest | C43: Pregnancies longer than 7 months | G43: Ethiopia DHS survey report Table 8.4
A44: Nigeria | B44: All | C44: Pregnancies longer than 7 months | G44: Most recent DHS for Nigeria
A45: Nigeria | B45: Lowest | C45: Pregnancies longer than 7 months | G45: Nigeria DHS survey report - Table 8.4
A46: Nigeria | B46: Second | C46: Pregnancies longer than 7 months | G46: Nigeria DHS survey report - Table 8.4
...

Sheet Vehicle Progress
A1: Vehicle | B1: Salt | C1: Bouillon | D1: Rice | E1: Notes
A2: Data need
A3: Iron fortification/consumption effect on hemoglobin | B3: Not modeled | C3: =IF(COUNTIFS('Vehicle Extraction'!$A$2:$A$904, C$1, 'Vehicle Extraction'!$B$2:$B$904, $A3) = 0, "Missing", "Complete") -> Complete | D3: =IF(COUNTIFS('Vehicle Extraction'!$A$2:$A$904, D$1, 'Vehicle Extraction'!$B$2:$B$904, $A3) = 0, "Missing", "Complete") -> Complete
A4: Iron fortification/consumption effect on birthweight | B4: Not modeled | C4: =IF(COUNTIFS('Vehicle Extraction'!$A$2:$A$904, C$1, 'Vehicle Extraction'!$B$2:$B$904, $A4) = 0, "Missing", "Complete") -> Complete | D4: =IF(COUNTIFS('Vehicle Extraction'!$A$2:$A$904, D$1, 'Vehicle Extraction'!$B$2:$B$904, $A4) = 0, "Missing", "Complete") -> Complete

Sheet Vehicle Extraction
A1: Vehicle | B1: Data need | C1: Data point name | D1: Units | E1: Year | F1: Data source | G1: Value | H1: CI | I1: Notes
A2: Rice | B2: Iron fortification/consumption effect on hemoglobin | C2: Mean difference | D2: g/L | E2: Unpublished | F2: Dorbu et al. Nutritional anemia reductions due to food fortification among women of childbearing age: a systematic review and Bayesian meta-analysis. Unpublished data. | G2: 3.25 | H2: 0.9-5.71 | I2: "This comes from a slide deck that Jonathan send to Abie. It is credited to Helena.Pachon@emory.edu". There are also https://doi.org/10.1080/09637486.2020.1855126 and https://iris.who.int/bitstream/handle/10665/272535/9789241550291-eng.pdf?ua=1 which report similar-ish numbers but this is the one we got from Gates.
A3: Salt | B3: Iron fortification/consumption effect on hemoglobin | C3: Mean difference | D3: g/L | E3: 2021 | F3: Can Double Fortification of Salt with Iron and Iodine Reduce Anemia, Iron Deficiency Anemia, Iron Deficiency, Iodine Deficiency, and Functional Outcomes? Evidence of Efficacy, Effectiveness, and Safety | G3: 4.4 | H3: 2.3-6.4 | I3: https://www.ncbi.nlm.nih.gov/pmc/articles/PMC7882357/; meta-analysis of 22 studies
A4: Bouillon | B4: Iron fortification/consumption effect on hemoglobin | C4: Mean difference | D4: g/L | E4: 2012 | F4: Effect of iron-fortified foods on hematologic and biological outcomes: systematic review of randomized controlled trials | G4: 4.2 | H4: 2.8-5.6 | I4: https://www.sciencedirect.com/science/article/pii/S0002916523028915; could not find anything bouillon-specific
A5: Rice | B5: Iron fortification/consumption effect on birthweight | C5: Mean difference | D5: g/(mg/person-day) | E5: 2013 | F5: Anaemia, prenatal iron use, and risk of adverse pregnancy outcomes: systematic review and meta-analysis | G5: 1.67 | H5: 0.729 to 2.611 | I5: https://www.bmj.com/content/346/bmj.f3443; study of supplementation at higher doses than fortification; selected the effect among trials <66mg/day as all fortification would fall in this range
A6: Bouillon | B6: Iron fortification/consumption effect on birthweight | C6: Mean difference | D6: g/(mg/person-day) | E6: 2013 | F6: Anaemia, prenatal iron use, and risk of adverse pregnancy outcomes: systematic review and meta-analysis | G6: 1.67 | H6: 0.729 to 2.611 | I6: https://www.bmj.com/content/346/bmj.f3443; study of supplementation at higher doses than fortification; selected the effect among trials <66mg/day as all fortification would fall in this range
A7: Wheat | B7: Iron fortification/consumption effect on hemoglobin | C7: Mean difference | D7: g/L | F7: DUMMY (MIC-7549) | G7: 3.25 | I7: DUMMY PLACEHOLDER (MIC-7549): value copied from the corresponding Rice row. Replace with real wheat data.
A8: Wheat | B8: Iron fortification/consumption effect on birthweight | C8: Mean difference | D8: g/(mg/person-day) | F8: DUMMY (MIC-7549) | G8: 1.67 | I8: DUMMY PLACEHOLDER (MIC-7549): value copied from the corresponding Rice row. Replace with real wheat data.
A9: Salt | B9: Iron fortification/consumption effect on birthweight | C9: Mean difference | D9: g/(mg/person-day) | F9: DUMMY (MIC-7580) | G9: 1.67 | I9: DUMMY PLACEHOLDER (MIC-7580): copied from the wheat row; every vehicle uses 1.67. Confirm for salt.

Sheet Universal
A1: Data need | B1: Data point name | C1: Units | D1: Year | E1: Data source | F1: Value | G1: CI | H1: Notes
A2: Folate fortification/consumption effect on serum/plasma folate
A3: Rice | B3: Risk Difference | C3: nmol/L | D3: 2018 | E3: WHO 2018 systematic review | F3: 4.3 | G3: 2.00-6.60 | H3: https://iris.who.int/bitstream/handle/10665/272535/9789241550291-eng.pdf?ua=1 found a single study
A4: Folate fortification/consumption effect on RBC folate | B4: Relative Risk (linear dose-response) | C4: percent RBC increase per 10% increase in folate intake | D4: 2015 | E4: Marchetta et al, 2015 | F4: 6 | G4: 4-9
A5: Serum/plasma folate effect on RBC folate
A6: RBC folate effect on NTD incidence | B6: non-linear relationship | E6: (Daly et al, 1995) | F6: ln (odds of NTD risk) = 1.6563 − 1.2193 × ln (RBC)
A7: RBC folate effect on NTD incidence | B7: non-linear relationship | E7: (Crider et al, 2014) | F7: ln (odds of NTD risk) = 4.57 − 1.70 × ln (RBC)
A8: NTD stillbirth-to-death ratio | B8: Ratio | E8: NTD Stillbirths paper in Lancet Global Health based on CHAMPS MITS data | F8: 51/18 | H8: There might be more data available since this paper was published

Sheet Scenario Definition Progress
A1: Country | B1: Ethiopia | E1: Nigeria | I1: India
A2: Vehicle | B2: Salt | E2: Bouillon | G2: Rice | I2: Rice
A3: Fortificant | B3: Folate | E3: Folate | F3: Iron | G3: Folate | H3: Iron | I3: Folate | J3: Iron
A4: Scenario | B4: Intervention - 25% NRV | C4: Intervention - 100% NRV | D4: Intervention - 45 ppm | E4: Intervention | F4: Intervention | G4: Intervention | H4: Intervention | I4: Intervention | J4: Intervention
A5: Data need
A6: Vehicle fortification in intervention -- amount among fortified | B6: =IF(COUNTIFS('Scenario Definition Extraction'!$A$2:$A$1000, B$1, 'Scenario Definition Extraction'!$B$2:$B$1000, B$2, 'Scenario Definition Extraction'!$C$2:$C$1000, B$3, 'Scenario Definition Extraction'!$D$2:$D$1000, B$4, 'Scenario Definition Extraction'!$E$2:$E$1000, $A6) = 0, "Missing", "Complete") -> Complete | C6: =IF(COUNTIFS('Scenario Definition Extraction'!$A$2:$A$1000, B$1, 'Scenario Definition Extraction'!$B$2:$B$1000, B$2, 'Scenario Definition Extraction'!$C$2:$C$1000, B$3, 'Scenario Definition Extraction'!$D$2:$D$1000, C$4, 'Scenario Definition Extraction'!$E$2:$E$1000, $A6) = 0, "Missing", "Complete") -> Complete | D6: Complete | E6: =IF(COUNTIFS('Scenario Definition Extraction'!$A$2:$A$1000, E$1, 'Scenario Definition Extraction'!$B$2:$B$1000, E$2, 'Scenario Definition Extraction'!$C$2:$C$1000, E$3, 'Scenario Definition Extraction'!$D$2:$D$1000, E$4, 'Scenario Definition Extraction'!$E$2:$E$1000, $A6) = 0, "Missing", "Complete") -> Complete | F6: =IF(COUNTIFS('Scenario Definition Extraction'!$A$2:$A$1000, E$1, 'Scenario Definition Extraction'!$B$2:$B$1000, E$2, 'Scenario Definition Extraction'!$C$2:$C$1000, F$3, 'Scenario Definition Extraction'!$D$2:$D$1000, F$4, 'Scenario Definition Extraction'!$E$2:$E$1000, $A6) = 0, "Missing", "Complete") -> Complete | G6: =IF(COUNTIFS('Scenario Definition Extraction'!$A$2:$A$1000, E$1, 'Scenario Definition Extraction'!$B$2:$B$1000, G$2, 'Scenario Definition Extraction'!$C$2:$C$1000, G$3, 'Scenario Definition Extraction'!$D$2:$D$1000, G$4, 'Scenario Definition Extraction'!$E$2:$E$1000, $A6) = 0, "Missing", "Complete") -> Complete | H6: =IF(COUNTIFS('Scenario Definition Extraction'!$A$2:$A$1000, E$1, 'Scenario Definition Extraction'!$B$2:$B$1000, G$2, 'Scenario Definition Extraction'!$C$2:$C$1000, H$3, 'Scenario Definition Extraction'!$D$2:$D$1000, H$4, 'Scenario Definition Extraction'!$E$2:$E$1000, $A6) = 0, "Missing", "Complete") -> Complete | I6: =IF(COUNTIFS('Scenario Definition Extraction'!$A$2:$A$1000, I$1, 'Scenario Definition Extraction'!$B$2:$B$1000, I$2, 'Scenario Definition Extraction'!$C$2:$C$1000, I$3, 'Scenario Definition Extraction'!$D$2:$D$1000, I$4, 'Scenario Definition Extraction'!$E$2:$E$1000, $A6) = 0, "Missing", "Complete") -> Complete | J6: =IF(COUNTIFS('Scenario Definition Extraction'!$A$2:$A$1000, I$1, 'Scenario Definition Extraction'!$B$2:$B$1000, I$2, 'Scenario Definition Extraction'!$C$2:$C$1000, J$3, 'Scenario Definition Extraction'!$D$2:$D$1000, J$4, 'Scenario Definition Extraction'!$E$2:$E$1000, $A6) = 0, "Missing", "Complete") -> Complete
A7: Intervention coverage % of fortifiable | B7: =IF(COUNTIFS('Scenario Definition Extraction'!$A$2:$A$1000, B$1, 'Scenario Definition Extraction'!$B$2:$B$1000, B$2, 'Scenario Definition Extraction'!$C$2:$C$1000, B$3, 'Scenario Definition Extraction'!$D$2:$D$1000, B$4, 'Scenario Definition Extraction'!$E$2:$E$1000, $A7) = 0, "Missing", "Complete") -> Complete | C7: =IF(COUNTIFS('Scenario Definition Extraction'!$A$2:$A$1000, B$1, 'Scenario Definition Extraction'!$B$2:$B$1000, B$2, 'Scenario Definition Extraction'!$C$2:$C$1000, B$3, 'Scenario Definition Extraction'!$D$2:$D$1000, C$4, 'Scenario Definition Extraction'!$E$2:$E$1000, $A7) = 0, "Missing", "Complete") -> Complete | D7: Complete | E7: =IF(COUNTIFS('Scenario Definition Extraction'!$A$2:$A$1000, E$1, 'Scenario Definition Extraction'!$B$2:$B$1000, E$2, 'Scenario Definition Extraction'!$C$2:$C$1000, E$3, 'Scenario Definition Extraction'!$D$2:$D$1000, E$4, 'Scenario Definition Extraction'!$E$2:$E$1000, $A7) = 0, "Missing", "Complete") -> Complete | F7: =IF(COUNTIFS('Scenario Definition Extraction'!$A$2:$A$1000, E$1, 'Scenario Definition Extraction'!$B$2:$B$1000, E$2, 'Scenario Definition Extraction'!$C$2:$C$1000, F$3, 'Scenario Definition Extraction'!$D$2:$D$1000, F$4, 'Scenario Definition Extraction'!$E$2:$E$1000, $A7) = 0, "Missing", "Complete") -> Complete | G7: =IF(COUNTIFS('Scenario Definition Extraction'!$A$2:$A$1000, E$1, 'Scenario Definition Extraction'!$B$2:$B$1000, G$2, 'Scenario Definition Extraction'!$C$2:$C$1000, G$3, 'Scenario Definition Extraction'!$D$2:$D$1000, G$4, 'Scenario Definition Extraction'!$E$2:$E$1000, $A7) = 0, "Missing", "Complete") -> Complete | H7: =IF(COUNTIFS('Scenario Definition Extraction'!$A$2:$A$1000, E$1, 'Scenario Definition Extraction'!$B$2:$B$1000, G$2, 'Scenario Definition Extraction'!$C$2:$C$1000, H$3, 'Scenario Definition Extraction'!$D$2:$D$1000, H$4, 'Scenario Definition Extraction'!$E$2:$E$1000, $A7) = 0, "Missing", "Complete") -> Complete | I7: =IF(COUNTIFS('Scenario Definition Extraction'!$A$2:$A$1000, I$1, 'Scenario Definition Extraction'!$B$2:$B$1000, I$2, 'Scenario Definition Extraction'!$C$2:$C$1000, I$3, 'Scenario Definition Extraction'!$D$2:$D$1000, I$4, 'Scenario Definition Extraction'!$E$2:$E$1000, $A7) = 0, "Missing", "Complete") -> Complete | J7: =IF(COUNTIFS('Scenario Definition Extraction'!$A$2:$A$1000, I$1, 'Scenario Definition Extraction'!$B$2:$B$1000, I$2, 'Scenario Definition Extraction'!$C$2:$C$1000, J$3, 'Scenario Definition Extraction'!$D$2:$D$1000, J$4, 'Scenario Definition Extraction'!$E$2:$E$1000, $A7) = 0, "Missing", "Complete") -> Complete
A8: Intervention effective % of fortified | B8: =IF(COUNTIFS('Scenario Definition Extraction'!$A$2:$A$1000, B$1, 'Scenario Definition Extraction'!$B$2:$B$1000, B$2, 'Scenario Definition Extraction'!$C$2:$C$1000, B$3, 'Scenario Definition Extraction'!$D$2:$D$1000, B$4, 'Scenario Definition Extraction'!$E$2:$E$1000, $A8) = 0, "Missing", "Complete") -> Complete | C8: =IF(COUNTIFS('Scenario Definition Extraction'!$A$2:$A$1000, B$1, 'Scenario Definition Extraction'!$B$2:$B$1000, B$2, 'Scenario Definition Extraction'!$C$2:$C$1000, B$3, 'Scenario Definition Extraction'!$D$2:$D$1000, C$4, 'Scenario Definition Extraction'!$E$2:$E$1000, $A8) = 0, "Missing", "Complete") -> Complete | D8: Complete | E8: =IF(COUNTIFS('Scenario Definition Extraction'!$A$2:$A$1000, E$1, 'Scenario Definition Extraction'!$B$2:$B$1000, E$2, 'Scenario Definition Extraction'!$C$2:$C$1000, E$3, 'Scenario Definition Extraction'!$D$2:$D$1000, E$4, 'Scenario Definition Extraction'!$E$2:$E$1000, $A8) = 0, "Missing", "Complete") -> Complete | F8: =IF(COUNTIFS('Scenario Definition Extraction'!$A$2:$A$1000, E$1, 'Scenario Definition Extraction'!$B$2:$B$1000, E$2, 'Scenario Definition Extraction'!$C$2:$C$1000, F$3, 'Scenario Definition Extraction'!$D$2:$D$1000, F$4, 'Scenario Definition Extraction'!$E$2:$E$1000, $A8) = 0, "Missing", "Complete") -> Complete | G8: =IF(COUNTIFS('Scenario Definition Extraction'!$A$2:$A$1000, E$1, 'Scenario Definition Extraction'!$B$2:$B$1000, G$2, 'Scenario Definition Extraction'!$C$2:$C$1000, G$3, 'Scenario Definition Extraction'!$D$2:$D$1000, G$4, 'Scenario Definition Extraction'!$E$2:$E$1000, $A8) = 0, "Missing", "Complete") -> Complete | H8: =IF(COUNTIFS('Scenario Definition Extraction'!$A$2:$A$1000, E$1, 'Scenario Definition Extraction'!$B$2:$B$1000, G$2, 'Scenario Definition Extraction'!$C$2:$C$1000, H$3, 'Scenario Definition Extraction'!$D$2:$D$1000, H$4, 'Scenario Definition Extraction'!$E$2:$E$1000, $A8) = 0, "Missing", "Complete") -> Complete | I8: =IF(COUNTIFS('Scenario Definition Extraction'!$A$2:$A$1000, I$1, 'Scenario Definition Extraction'!$B$2:$B$1000, I$2, 'Scenario Definition Extraction'!$C$2:$C$1000, I$3, 'Scenario Definition Extraction'!$D$2:$D$1000, I$4, 'Scenario Definition Extraction'!$E$2:$E$1000, $A8) = 0, "Missing", "Complete") -> Complete | J8: =IF(COUNTIFS('Scenario Definition Extraction'!$A$2:$A$1000, I$1, 'Scenario Definition Extraction'!$B$2:$B$1000, I$2, 'Scenario Definition Extraction'!$C$2:$C$1000, J$3, 'Scenario Definition Extraction'!$D$2:$D$1000, J$4, 'Scenario Definition Extraction'!$E$2:$E$1000, $A8) = 0, "Missing", "Complete") -> Complete

Sheet Scenario Definition Extraction
A1: Country | B1: Vehicle | C1: Fortificant | D1: Scenario | E1: Data need | F1: Data point name | G1: Units | H1: Data source | I1: Value | J1: Notes
A2: Nigeria | B2: Bouillon | C2: Iron | D2: Intervention | E2: Intervention coverage % of fortifiable | F2: percentage | G2: % | H2: GF Apr-2026 workbook 'Vehicles - WRA' BI10/BL10 (2035 compliance 50%); Kathy Banke email 9/9/2026: use 2035 targets | I2: 0.715 | J2: coverage = effectiveness = 0.715 equal split: sqrt(0.50) ~ 0.7071 rounded up because coverage x fortifiability must exceed baseline iron-labeled bouillon coverage (0.6998 in Q5 -> coverage >= 0.7113, asserted in the coverage notebook); product 0.5112 vs 2035 compliance target 0.50; pending GF country-team confirmation (KB email 9/9/2026)
A3: Nigeria | B3: Bouillon | C3: Folate | D3: Intervention | E3: Intervention coverage % of fortifiable | F3: percentage | G3: % | H3: GF Apr-2026 workbook 'Vehicles - WRA' BI10/BL10 (2035 compliance 50%); Kathy Banke email 9/9/2026: use 2035 targets | I3: 0.715 | J3: coverage = effectiveness = 0.715 equal split: sqrt(0.50) ~ 0.7071 rounded up because coverage x fortifiability must exceed baseline iron-labeled bouillon coverage (0.6998 in Q5 -> coverage >= 0.7113, asserted in the coverage notebook); product 0.5112 vs 2035 compliance target 0.50; pending GF country-team confirmation (KB email 9/9/2026)
A4: Nigeria | B4: Rice | C4: Iron | D4: Intervention | E4: Intervention coverage % of fortifiable | F4: percentage | G4: % | H4: GF Apr-2026 workbook 'Vehicles - WRA' V10/Y10 (2035 compliance 90%); Kathy Banke email 9/9/2026: use 2035 targets | I4: 0.95 | J4: coverage = effectiveness = sqrt(0.90) ~ 0.95, product 0.9025 realizes the 2035 compliance target
A5: Nigeria | B5: Rice | C5: Folate | D5: Intervention | E5: Intervention coverage % of fortifiable | F5: percentage | G5: % | H5: GF Apr-2026 workbook 'Vehicles - WRA' V10/Y10 (2035 compliance 90%); Kathy Banke email 9/9/2026: use 2035 targets | I5: 0.95 | J5: coverage = effectiveness = sqrt(0.90) ~ 0.95, product 0.9025 realizes the 2035 compliance target
