Workbook

Sheet Fortification
A1: Vehicle | B1: Nutrient | C1: Risk or Disease | D1: Data need | E1: Measure | F1: Units | G1: Value | H1: Uncertainty | I1: Year | J1: Data source author | K1: Data source Title | L1: URL | M1: Notes
A2: Rice | B2: iron + other | C2: anemia, birthweight, maternal disorders | D2: iron fortification/consumption effect on hemoglobin | E2: mean difference | F2: g/L | G2: 3.24 | H2: 0.9-5.7 | I2: 2025 | J2: Dorbu et al.* | K2: Nutritional Anemia Reductions Due to Food Fortification Among Women of Childbearing Age: A Literature Review and Bayesian Meta-Analysis | L2: https://onlinelibrary.wiley.com/doi/full/10.1111/mcn.13801 | M2: Included studies of foods fortified with any nutrient contributing to hemoglobin biology: iron, folic acid, B12, riboflavin, vitamin A, vitamin C, zinc, and or vitamin E
A3: Condiments | B3: iron + other | C3: anemia, birthweight, maternal disorders | D3: iron fortification/consumption effect on hemoglobin | E3: mean difference | F3: g/dL | G3: 6.22 | H3: 1.60-10.83 | I3: 2023 | J3: Jalal et al. | K3: Fortification of condiments and seasonings with iron for preventing anaemia and improving health | L3: https://www.cochranelibrary.com/cdsr/doi/10.1002/14651858.CD009604.pub2/full | M3: Fortification of condiments, not specific to bouillon. very low‐certainty evidence
A4: Any | B4: iron | C4: anemia, birthweight, maternal disorders | D4: iron fortification/consumption effect on hemoglobin | E4: mean difference | F4: g/L | G4: 4.2 | H4: 2.8-5.6 | I4: 2012 | J4: Gera et al.* | K4: Effect of iron-fortified foods on hematologic and biological outcomes: systematic review of randomized controlled trials | L4: https://www.sciencedirect.com/science/article/pii/S0002916523028915 | M4: Fortification of any food, not specific to bouillon
A5: Any | B5: iron | C5: anemia, birthweight, maternal disorders | D5: iron fortification/consumption effect on hemoglobin | E5: weighted mean difference | F5: g/L | G5: 4.45 | H5: 2.73-6.17 | I5: 2020 | J5: Athe et al. | K5: Meta-analysis approach on iron fortification and its effect on pregnancy and its outcome through randomized, controlled trials | L5: https://pmc.ncbi.nlm.nih.gov/articles/PMC7114015/ | M5: Specific to pregnant women, also reports effects on iron deficiency anemia and LBW
A6: Any | B6: iron | C6: birthweight | D6: Iron fortification/consumption effect on birthweight | E6: Mean difference | F6: g/(mg/person-day) | G6: 1.67 | H6: 0.729-2.611 | I6: 2013 | J6: Haider et al.* | K6: Anaemia, prenatal iron use, and risk of adverse pregnancy outcomes: systematic review and meta-analysis | L6: https://doi.org/10.1136/bmj.f3443 | M6: From Table 4. This source also contains other iron effect sizes that could be useful for comparison, e.g., dose-response of Hb on birthweight, and effect on LBW
A7: Salt | B7: folic acid + iodine | C7: NTDs | D7: 99 ppm folic acid fortification/consumption effect on RBC folate | E7: geometric mean ratio | F7: ratio | G7: 2.79 | H7: 2.58-3.01 | I7: 2026 | J7: Tessema et al. | K7: Folic acid fortification of iodized salt improves the folate status of nonpregnant adult Ethiopian females and does not impair their iodine status: a community-based, household-randomized, dose-response trial | L7: https://pubmed.ncbi.nlm.nih.gov/41611087/ | M7: Sounds extremely relevant to our Ethiopia/Salt/FA scenario
A8: Salt | B8: folic acid + iodine | C8: NTDs | D8: 36 ppm folic acid fortification/consumption effect on RBC folate | E8: geometric mean ratio | F8: ratio | G8: 1.99 | H8: 1.85-2.15 | I8: 2026 | J8: Tessema et al. | K8: Folic acid fortification of iodized salt improves the folate status of nonpregnant adult Ethiopian females and does not impair their iodine status: a community-based, household-randomized, dose-response trial | L8: https://pubmed.ncbi.nlm.nih.gov/41611087/ | M8: Sounds extremely relevant to our Ethiopia/Salt/FA scenario
A9: Any | B9: folic acid | C9: NTDs | D9: folic acid fortification/consumption effect on RBC folate | I9: 2019 | J9: Crider et al. | K9: Systematic Review and Bayesian Meta-analysis of the Dose-response Relationship between Folic Acid Intake and Changes in Blood Folate Concentrations | L9: https://pmc.ncbi.nlm.nih.gov/articles/PMC6356991/
A10: Natural foods | B10: folate | C10: NTDs | D10: folic acid fortification/consumption effect on RBC folate | I10: 2015 | J10: Marchetta et al.* | K10: Assessing the association between natural food folate intake and blood folate concentrations: a systematic review and Bayesian meta-analysis of trials and observational studies | L10: https://pubmed.ncbi.nlm.nih.gov/25867949/
A11: Rice | B11: iron, FA, other | D11: external validation comparison | I11: 2026 | J11: Tiwari et al | K11: Impact assessment of fortified rice under the public distribution system: evidence from the tribal regions of Gujarat | L11: https://pubmed.ncbi.nlm.nih.gov/41994527/ | M11: Evaluation of PDS in Gujarat
A12: Rice | B12: iron, FA, other | D12: external validation comparison | I12: 2025 | J12: Thankachan et al | K12: Assessing the effect of Government of India’s pilot scheme on rice fortification and other etiological factors on the prevalence of anaemia among non-pregnant women in Odisha and Uttar Pradesh | L12: https://www.medrxiv.org/content/10.1101/2025.04.30.25326719v1.full
A13: Rice | D13: another modeling study | I13: 2026 | J13: Luo et al | K13: Quantifying the Potential Impact of Food Fortification on Iron Intake, Hemoglobin Concentration and Anemia Prevalence Among Women of Reproductive Age in India | L13: https://pmc.ncbi.nlm.nih.gov/articles/PMC13501248/
A14: Multiple | B14: FA | D14: external validation comparison | I14: 2026 | J14: Moges et al | K14: The effectiveness of mandatory folic acid fortification compared with pre-fortification periods on reducing neural tube defects (NTDs): a systematic review and meta-analysis | L14: https://pmc.ncbi.nlm.nih.gov/articles/PMC12888319/ | M14: See also https://pubmed.ncbi.nlm.nih.gov/42280401/ which criticizes this sort of approach
A15: Bouillon | B15: iron + other | D15: another modeling study | I15: 2025 | J15: Vosti et al | K15: Cost‐Efficiency and Cost‐Effectiveness of Alternative Bouillon Fortification Programs: Evidence for Burkina Faso, Nigeria, and Senegal | L15: https://pmc.ncbi.nlm.nih.gov/articles/PMC12917931/
L16: https://nyaspubs.onlinelibrary.wiley.com/doi/epdf/10.1111/nyas.13511?getft_integrator=sciencedirect_contenthosting&src=getftr&utm_source=sciencedirect_contenthosting | M16: RBC folate & NTD
A17: Salt | B17: folate, Zn | C17: NTDs | D17: folate consumption by quintile | I17: 2024 | J17: Saje et al.* | K17: Modeling the Contribution of Multiple Micronutrient Fortification of Salt to Daily Nutrient Intake Among the Ethiopian Population | L17: https://cdn.nutrition.org/article/S2475-2991%2824%2901728-1/fulltext
A18: Multiple | B18: folate, other | C18: NTDs | D18: folate consumption in India | I18: 2023 | J18: Mediratta et al.* | K18: Intake of ultra-processed food, dietary diversity and the risk of nutritional inadequacy among adults in India | L18: https://pmc.ncbi.nlm.nih.gov/articles/PMC10755415/pdf/S1368980023002112a.pdf

Sheet OLD vehicle consumption
A1: Country | B1: Vehicle | C1: Quintile | D1: Population | E1: Data need | F1: Data point name | G1: Units | H1: Year | I1: Data source | J1: Value | K1: CI | L1: CI Type | M1: SE | N1: Notes
A2: Nigeria | B2: Wheat | C2: Total | D2: Non-pregnant WRA | E2: Vehicle consumption by WRA -- any | F2: percentage | G2: % | H2: 2021 | I2: Nigeria National Food Consumption and Micronutrient Status Survey (NFCMS), Table 146, p 191 | J2: 28.2 | K2: [24.3, 32.2] | L2: 95% CI | N2: the NFCMS Annex 38 (p 544) should have included vehicle consumption percentage and 95% CI for pregnant women and children U5 groups, but looks like the pdf has a printing error in the table (title states wheat flour, but header rows indicate vegetable oil comsumption values). maybe we can use non-pregnant WRA values for pregnant women and children U5?
A3: Nigeria | B3: Wheat | C3: Lowest | D3: Non-pregnant WRA | E3: Vehicle consumption by WRA -- any | F3: percentage | G3: % | H3: 2021 | I3: NFCMS, Table 146, p 191 | J3: 19.1 | K3: [14.3, 24.0] | L3: 95% CI
A4: Nigeria | B4: Wheat | C4: Second | D4: Non-pregnant WRA | E4: Vehicle consumption by WRA -- any | F4: percentage | G4: % | H4: 2021 | I4: NFCMS, Table 146, p 191 | J4: 25.3 | K4: [19.5, 31.2] | L4: 95% CI
A5: Nigeria | B5: Wheat | C5: Middle | D5: Non-pregnant WRA | E5: Vehicle consumption by WRA -- any | F5: percentage | G5: % | H5: 2021 | I5: NFCMS, Table 146, p 191 | J5: 30.5 | K5: [24.6, 36.5] | L5: 95% CI
A6: Nigeria | B6: Wheat | C6: Fourth | D6: Non-pregnant WRA | E6: Vehicle consumption by WRA -- any | F6: percentage | G6: % | H6: 2021 | I6: NFCMS, Table 146, p 191 | J6: 33.3 | K6: [28.2, 38.5] | L6: 95% CI
A7: Nigeria | B7: Wheat | C7: Highest | D7: Non-pregnant WRA | E7: Vehicle consumption by WRA -- any | F7: percentage | G7: % | H7: 2021 | I7: NFCMS, Table 146, p 191 | J7: 35.3 | K7: [28.0, 42.6] | L7: 95% CI
A8: Nigeria | B8: Wheat | C8: Total | D8: Non-pregnant WRA | E8: Vehicle consumption by WRA -- amount | F8: mean | G8: g/day | H8: 2021 | I8: NFCMS, Table 147, p 193 | J8: 39 | K8: [35.1, 42.9] | L8: 95% CI | M8: 2
A9: Nigeria | B9: Wheat | C9: Lowest | D9: Non-pregnant WRA | E9: Vehicle consumption by WRA -- amount | F9: mean | G9: g/day | H9: 2021 | I9: NFCMS, Table 147, p 193 | J9: 16.1 | K9: [12.6, 19.6] | L9: 95% CI | M9: 1.8
A10: Nigeria | B10: Wheat | C10: Second | D10: Non-pregnant WRA | E10: Vehicle consumption by WRA -- amount | F10: mean | G10: g/day | H10: 2021 | I10: NFCMS, Table 147, p 193 | J10: 23.4 | K10: [18.7, 28.2] | L10: 95% CI | M10: 2.4
A11: Nigeria | B11: Wheat | C11: Middle | D11: Non-pregnant WRA | E11: Vehicle consumption by WRA -- amount | F11: mean | G11: g/day | H11: 2021 | I11: NFCMS, Table 147, p 193 | J11: 38.2 | K11: [31.5, 44.8] | L11: 95% CI | M11: 3.4
A12: Nigeria | B12: Wheat | C12: Fourth | D12: Non-pregnant WRA | E12: Vehicle consumption by WRA -- amount | F12: mean | G12: g/day | H12: 2021 | I12: NFCMS, Table 147, p 193 | J12: 49.3 | K12: [43.0, 55.6] | L12: 95% CI | M12: 3.2
A13: Nigeria | B13: Wheat | C13: Highest | D13: Non-pregnant WRA | E13: Vehicle consumption by WRA -- amount | F13: mean | G13: g/day | H13: 2021 | I13: NFCMS, Table 147, p 193 | J13: 62.4 | K13: [57.0, 67.7] | L13: 95% CI | M13: 2.7
A14: Nigeria | B14: Wheat | C14: Total | D14: Pregnant women | E14: Vehicle consumption by WRA -- amount | F14: mean | G14: g/day | H14: 2021 | I14: NFCMS, Table 147, p 193 | J14: 35 | K14: [29.5, 40.6] | L14: 95% CI | M14: 2.8 | N14: not included in GF input "Vehicles - WRA" C10; they used non pregnant women for all WRA (not sure if we are supposed to assume it is the same for all WRA? I could not find a value in NFCMS that is for all WRA)
A15: Nigeria | B15: Wheat | C15: Total | D15: Children U5 | E15: Vehicle consumption by U5 children -- amount | F15: mean | G15: g/day | H15: 2021 | I15: NFCMS, Table 148, p 194 | J15: 26 | K15: [22.9, 29.2] | L15: 95% CI | M15: 1.6
A16: Nigeria | B16: Wheat | C16: Total | D16: Children U5 - male | E16: Vehicle consumption by U5 children -- amount | F16: mean | G16: g/day | H16: 2021 | I16: NFCMS, Table 148, p 194 | J16: 26.9 | K16: [23.3, 30.4] | L16: 95% CI | M16: 1.8 | N16: GF input file states sex-specific values for U5 children "not to be projected / filled out". But not sure why? Maybe can safely assume no significant difference between sexes for children U5?
A17: Nigeria | B17: Wheat | C17: Total | D17: Children U5 - female | E17: Vehicle consumption by U5 children -- amount | F17: mean | G17: g/day | H17: 2021 | I17: NFCMS, Table 148, p 194 | J17: 25.1 | K17: [21.0, 29.1] | L17: 95% CI | M17: 2.1 | N17: GF input file states sex-specific values for U5 children "not to be projected / filled out". But not sure why? Maybe can safely assume no significant difference between sexes for children U5?
A18: Nigeria | B18: Salt | C18: Total | D18: Non-pregnant WRA | E18: Vehicle consumption by WRA -- any | F18: percentage | G18: % | H18: 2021 | I18: NFCMS, Table 166, p 215 | J18: 99.3 | K18: [99.0, 99.6] | L18: 95% CI
A19: Nigeria | B19: Salt | C19: Lowest | D19: Non-pregnant WRA | E19: Vehicle consumption by WRA -- any | F19: percentage | G19: % | H19: 2021 | I19: NFCMS, Table 166, p 215 | J19: 99.5 | K19: [98.9, 100.0] | L19: 95% CI
A20: Nigeria | B20: Salt | C20: Second | D20: Non-pregnant WRA | E20: Vehicle consumption by WRA -- any | F20: percentage | G20: % | H20: 2021 | I20: NFCMS, Table 166, p 215 | J20: 99.7 | K20: [99.4, 100.0] | L20: 95% CI
A21: Nigeria | B21: Salt | C21: Middle | D21: Non-pregnant WRA | E21: Vehicle consumption by WRA -- any | F21: percentage | G21: % | H21: 2021 | I21: NFCMS, Table 166, p 215 | J21: 99.5 | K21: [99.0, 99.9] | L21: 95% CI
A22: Nigeria | B22: Salt | C22: Fourth | D22: Non-pregnant WRA | E22: Vehicle consumption by WRA -- any | F22: percentage | G22: % | H22: 2021 | I22: NFCMS, Table 166, p 215 | J22: 99.4 | K22: [98.7, 100.0] | L22: 95% CI
A23: Nigeria | B23: Salt | C23: Highest | D23: Non-pregnant WRA | E23: Vehicle consumption by WRA -- any | F23: percentage | G23: % | H23: 2021 | I23: NFCMS, Table 166, p 215 | J23: 98.5 | K23: [97.1, 99.9] | L23: 95% CI
A24: Nigeria | B24: Salt | C24: Total | D24: Pregnant women | E24: Vehicle consumption by WRA -- any | F24: percentage | G24: % | H24: 2021 | I24: NFCMS, Annex 42, p 548 | J24: 99.1 | K24: [98.5, 99.8] | L24: 95% CI
A25: Nigeria | B25: Salt | C25: Total | D25: Children U5 | E25: Vehicle consumption by U5 children -- any | F25: percentage | G25: % | H25: 2021 | I25: NFCMS, Annex 42, p 548 | J25: 99.2 | K25: [98.8, 99.6] | L25: 95% CI
A26: Nigeria | B26: Salt | C26: Total | D26: Non-pregnant WRA | E26: Vehicle consumption by WRA -- amount | F26: mean | G26: g/day | H26: 2021 | I26: NFCMS, Table 167, p 217 | J26: 3.9 | K26: [3.7, 4.1] | L26: 95% CI | M26: 0.1
A27: Nigeria | B27: Salt | C27: Lowest | D27: Non-pregnant WRA | E27: Vehicle consumption by WRA -- amount | F27: mean | G27: g/day | H27: 2021 | I27: NFCMS, Table 167, p 217 | J27: 4.2 | K27: [3.8, 4.6] | L27: 95% CI | M27: 0.2
A28: Nigeria | B28: Salt | C28: Second | D28: Non-pregnant WRA | E28: Vehicle consumption by WRA -- amount | F28: mean | G28: g/day | H28: 2021 | I28: NFCMS, Table 167, p 217 | J28: 4 | K28: [3.5, 4.4] | L28: 95% CI | M28: 0.2
A29: Nigeria | B29: Salt | C29: Middle | D29: Non-pregnant WRA | E29: Vehicle consumption by WRA -- amount | F29: mean | G29: g/day | H29: 2021 | I29: NFCMS, Table 167, p 217 | J29: 3.8 | K29: [3.5, 4.2] | L29: 95% CI | M29: 0.2
A30: Nigeria | B30: Salt | C30: Fourth | D30: Non-pregnant WRA | E30: Vehicle consumption by WRA -- amount | F30: mean | G30: g/day | H30: 2021 | I30: NFCMS, Table 167, p 217 | J30: 3.7 | K30: [3.4, 4.0] | L30: 95% CI | M30: 0.1
A31: Nigeria | B31: Salt | C31: Highest | D31: Non-pregnant WRA | E31: Vehicle consumption by WRA -- amount | F31: mean | G31: g/day | H31: 2021 | I31: NFCMS, Table 167, p 217 | J31: 3.8 | K31: [3.5, 4.0] | L31: 95% CI | M31: 0.1
A32: Nigeria | B32: Salt | C32: Total | D32: Pregnant women | E32: Vehicle consumption by WRA -- amount | F32: mean | G32: g/day | H32: 2021 | I32: NFCMS, Table 167, p 217 | J32: 4.2 | K32: [3.8, 4.5] | L32: 95% CI | M32: 0.2
A33: Nigeria | B33: Salt | C33: Total | D33: Children U5 | E33: Vehicle consumption by U5 children -- amount | F33: mean | G33: g/day | H33: 2021 | I33: NFCMS, Table 168, p 218 | J33: 2.6 | K33: [2.4, 2.9] | L33: 95% CI | M33: 0.1
A34: Nigeria | B34: Salt | C34: Total | D34: Children U5 - male | E34: Vehicle consumption by U5 children -- amount | F34: mean | G34: g/day | H34: 2021 | I34: NFCMS, Table 168, p 218 | J34: 2.7 | K34: [2.4, 3.0] | L34: 95% CI | M34: 0.1
A35: Nigeria | B35: Salt | C35: Total | D35: Children U5 - female | E35: Vehicle consumption by U5 children -- amount | F35: mean | G35: g/day | H35: 2021 | I35: NFCMS, Table 168, p 218 | J35: 2.5 | K35: [2.2, 2.8] | L35: 95% CI | M35: 0.1
A36: Ethiopia | B36: Wheat | C36: Total | D36: WRA | E36: Vehicle consumption by WRA -- any | F36: percentage | G36: % | H36: 2022 | I36: Ethiopia National Food Nutrition Survey (FNS), Table 8.9 | J36: 30.7 | N36: consumption of fortified wheat (not all wheat); no values in GF Input "Vehicles - preschool" for Ethiopia, so maybe we can use WRA values for children U5 as well? from GF input "Vehicles - WRA" N27 which doesn't include CI/SE data
A37: Ethiopia | B37: Wheat | C37: Lowest | D37: WRA | E37: Vehicle consumption by WRA -- any | F37: percentage | G37: % | H37: 2022 | I37: FNS, Table 8.9 | J37: 25.1 | N37: consumption of fortified wheat (not all wheat); from GF input "Vehicles - WRA" N48 which doesn't include CI/SE data
A38: Ethiopia | B38: Wheat | C38: Second | D38: WRA | E38: Vehicle consumption by WRA -- any | F38: percentage | G38: % | H38: 2022 | I38: FNS, Table 8.9 | J38: 21.4 | N38: consumption of fortified wheat (not all wheat); from GF input "Vehicles - WRA" N49 which doesn't include CI/SE data
A39: Ethiopia | B39: Wheat | C39: Middle | D39: WRA | E39: Vehicle consumption by WRA -- any | F39: percentage | G39: % | H39: 2022 | I39: FNS, Table 8.9 | J39: 22.7 | N39: consumption of fortified wheat (not all wheat); from GF input "Vehicles - WRA" N50 which doesn't include CI/SE data
A40: Ethiopia | B40: Wheat | C40: Fourth | D40: WRA | E40: Vehicle consumption by WRA -- any | F40: percentage | G40: % | H40: 2022 | I40: FNS, Table 8.9 | J40: 32.3 | N40: consumption of fortified wheat (not all wheat); from GF input "Vehicles - WRA" N51 which doesn't include CI/SE data
...

Sheet Vehicle Consumption
A1: Country | B1: Vehicle | C1: Model | D1: Quintile | E1: Population | F1: Term | G1: Term Definition | H1: Data need | I1: Data point name | J1: Units | K1: Year | L1: Data source | M1: Value | N1: CI | O1: CI Type | P1: SE | Q1: GF Input? | R1: Limitations | S1: Notes
A2: Nigeria | B2: Wheat | C2: 2 | D2: Total | E2: Non-pregnant WRA | F2: coverage | G2: use of vehicle, regardless of fortification | H2: Vehicle consumption by WRA -- any | I2: percentage | J2: % | K2: 2021 | L2: Nigeria National Food Consumption and Micronutrient Status Survey (NFCMS), Table 146, p 191 | M2: 28.2 | N2: [24.3, 32.2] | O2: 95% CI | Q2: Yes, but maybe a typo on their sheet? They put 28.0? | R2: 1. "The remaining 72% that did not use it at home dose not mean that the households did not consume wheat flour rather they consumed wheat flour products (i.e., bread, confectionaries) that are vendor processed." 2. This is the number GF used for all WRA (even though it specifically states for non-pregnant WRA) and for children U5. Percentage of vehicle consumption for pregnant WRA and children U5 is most likely located in Annex 38 (which is missing). | S2: the NFCMS Annex 38 (p 544) should have included vehicle consumption percentage and 95% CI for pregnant women and children U5 groups, but looks like the pdf has a printing error in the table (title states wheat flour, but header rows indicate vegetable oil comsumption values). maybe we can use non-pregnant WRA values for pregnant women and children U5?
A3: Nigeria | B3: Wheat | C3: 2 | D3: Lowest | E3: Non-pregnant WRA | F3: coverage | G3: use of vehicle, regardless of fortification | H3: Vehicle consumption by WRA -- any | I3: percentage | J3: % | K3: 2021 | L3: NFCMS, Table 146, p 191 | M3: 19.1 | N3: [14.3, 24.0] | O3: 95% CI | Q3: Yes
A4: Nigeria | B4: Wheat | C4: 2 | D4: Second | E4: Non-pregnant WRA | F4: coverage | G4: use of vehicle, regardless of fortification | H4: Vehicle consumption by WRA -- any | I4: percentage | J4: % | K4: 2021 | L4: NFCMS, Table 146, p 191 | M4: 25.3 | N4: [19.5, 31.2] | O4: 95% CI | Q4: Yes
A5: Nigeria | B5: Wheat | C5: 2 | D5: Middle | E5: Non-pregnant WRA | F5: coverage | G5: use of vehicle, regardless of fortification | H5: Vehicle consumption by WRA -- any | I5: percentage | J5: % | K5: 2021 | L5: NFCMS, Table 146, p 191 | M5: 30.5 | N5: [24.6, 36.5] | O5: 95% CI | Q5: Yes
A6: Nigeria | B6: Wheat | C6: 2 | D6: Fourth | E6: Non-pregnant WRA | F6: coverage | G6: use of vehicle, regardless of fortification | H6: Vehicle consumption by WRA -- any | I6: percentage | J6: % | K6: 2021 | L6: NFCMS, Table 146, p 191 | M6: 33.3 | N6: [28.2, 38.5] | O6: 95% CI | Q6: Yes
A7: Nigeria | B7: Wheat | C7: 2 | D7: Highest | E7: Non-pregnant WRA | F7: coverage | G7: use of vehicle, regardless of fortification | H7: Vehicle consumption by WRA -- any | I7: percentage | J7: % | K7: 2021 | L7: NFCMS, Table 146, p 191 | M7: 35.3 | N7: [28.0, 42.6] | O7: 95% CI | Q7: Yes
A8: Nigeria | B8: Wheat | C8: 2 | D8: Total | E8: Non-pregnant WRA | F8: consumption | G8: amount of vehicle consumed daily | H8: Vehicle consumption by WRA -- amount | I8: mean | J8: g/day | K8: 2021 | L8: NFCMS, Table 147, p 193 | M8: 39 | N8: [35.1, 42.9] | O8: 95% CI | P8: 2 | Q8: Yes | R8: This is the number GF used for all WRA (even though it specifically states for non-pregnant WRA) and for children U5. More specific amount numbers for pregnant WRA and children U5 (separated by sex as well) are located below
A9: Nigeria | B9: Wheat | C9: 2 | D9: Lowest | E9: Non-pregnant WRA | F9: consumption | G9: amount of vehicle consumed daily | H9: Vehicle consumption by WRA -- amount | I9: mean | J9: g/day | K9: 2021 | L9: NFCMS, Table 147, p 193 | M9: 16.1 | N9: [12.6, 19.6] | O9: 95% CI | P9: 1.8 | Q9: Yes
A10: Nigeria | B10: Wheat | C10: 2 | D10: Second | E10: Non-pregnant WRA | F10: consumption | G10: amount of vehicle consumed daily | H10: Vehicle consumption by WRA -- amount | I10: mean | J10: g/day | K10: 2021 | L10: NFCMS, Table 147, p 193 | M10: 23.4 | N10: [18.7, 28.2] | O10: 95% CI | P10: 2.4 | Q10: Yes
A11: Nigeria | B11: Wheat | C11: 2 | D11: Middle | E11: Non-pregnant WRA | F11: consumption | G11: amount of vehicle consumed daily | H11: Vehicle consumption by WRA -- amount | I11: mean | J11: g/day | K11: 2021 | L11: NFCMS, Table 147, p 193 | M11: 38.2 | N11: [31.5, 44.8] | O11: 95% CI | P11: 3.4 | Q11: Yes
A12: Nigeria | B12: Wheat | C12: 2 | D12: Fourth | E12: Non-pregnant WRA | F12: consumption | G12: amount of vehicle consumed daily | H12: Vehicle consumption by WRA -- amount | I12: mean | J12: g/day | K12: 2021 | L12: NFCMS, Table 147, p 193 | M12: 49.3 | N12: [43.0, 55.6] | O12: 95% CI | P12: 3.2 | Q12: Yes
A13: Nigeria | B13: Wheat | C13: 2 | D13: Highest | E13: Non-pregnant WRA | F13: consumption | G13: amount of vehicle consumed daily | H13: Vehicle consumption by WRA -- amount | I13: mean | J13: g/day | K13: 2021 | L13: NFCMS, Table 147, p 193 | M13: 62.4 | N13: [57.0, 67.7] | O13: 95% CI | P13: 2.7 | Q13: Yes
A14: Nigeria | B14: Wheat | C14: 2 | D14: Total | E14: Non-pregnant WRA | F14: consumption | G14: amount of vehicle consumed daily | H14: Vehicle consumption by WRA -- amount | I14: standard deviation | J14: g/day | K14: 2021 | L14: NFCMS, Table 147, p 193 | M14: =(57.1 - 13.3)/1.35 -> 32.444444 | Q14: No, GF did not provide SD | R14: Assuming normal distribution | S14: Very rough estimate using SD = IQR / 1.35 (normality assumption)
A15: Nigeria | B15: Wheat | C15: 2 | D15: Lowest | E15: Non-pregnant WRA | F15: consumption | G15: amount of vehicle consumed daily | H15: Vehicle consumption by WRA -- amount | I15: standard deviation | J15: g/day | K15: 2021 | L15: NFCMS, Table 147, p 193 | M15: =(22.2 - 4.3)/1.35 -> 13.259259 | Q15: No, GF did not provide SD | R15: Assuming normal distribution | S15: Very rough estimate using SD = IQR / 1.35 (normality assumption)
A16: Nigeria | B16: Wheat | C16: 2 | D16: Second | E16: Non-pregnant WRA | F16: consumption | G16: amount of vehicle consumed daily | H16: Vehicle consumption by WRA -- amount | I16: standard deviation | J16: g/day | K16: 2021 | L16: NFCMS, Table 147, p 193 | M16: =(33.2 - 7.6)/1.35 -> 18.962963 | Q16: No, GF did not provide SD | R16: Assuming normal distribution | S16: Very rough estimate using SD = IQR / 1.35 (normality assumption)
A17: Nigeria | B17: Wheat | C17: 2 | D17: Middle | E17: Non-pregnant WRA | F17: consumption | G17: amount of vehicle consumed daily | H17: Vehicle consumption by WRA -- amount | I17: standard deviation | J17: g/day | K17: 2021 | L17: NFCMS, Table 147, p 193 | M17: =(53.6 - 16.5)/1.35 -> 27.481481 | Q17: No, GF did not provide SD | R17: Assuming normal distribution | S17: Very rough estimate using SD = IQR / 1.35 (normality assumption)
A18: Nigeria | B18: Wheat | C18: 2 | D18: Fourth | E18: Non-pregnant WRA | F18: consumption | G18: amount of vehicle consumed daily | H18: Vehicle consumption by WRA -- amount | I18: standard deviation | J18: g/day | K18: 2021 | L18: NFCMS, Table 147, p 193 | M18: =(67.6 - 25.3)/1.35 -> 31.333333 | Q18: No, GF did not provide SD | R18: Assuming normal distribution | S18: Very rough estimate using SD = IQR / 1.35 (normality assumption)
A19: Nigeria | B19: Wheat | C19: 2 | D19: Highest | E19: Non-pregnant WRA | F19: consumption | G19: amount of vehicle consumed daily | H19: Vehicle consumption by WRA -- amount | I19: standard deviation | J19: g/day | K19: 2021 | L19: NFCMS, Table 147, p 193 | M19: =(82.2 - 37.7)/1.35 -> 32.962963 | Q19: No, GF did not provide SD | R19: Assuming normal distribution | S19: Very rough estimate using SD = IQR / 1.35 (normality assumption)
A20: Nigeria | B20: Wheat | C20: 2 | D20: Total | E20: Pregnant women | F20: consumption | G20: amount of vehicle consumed daily | H20: Vehicle consumption by WRA -- amount | I20: mean | J20: g/day | K20: 2021 | L20: NFCMS, Table 147, p 193 | M20: 35 | N20: [29.5, 40.6] | O20: 95% CI | P20: 2.8 | Q20: No, GF used non-pregnant WRA values for all WRA values | S20: not included in GF input "Vehicles - WRA" C10; they used non pregnant women for all WRA (not sure if we are supposed to assume it is the same for all WRA? I could not find a value in NFCMS that is for all WRA)
A21: Nigeria | B21: Wheat | C21: 2 | D21: Total | E21: Pregnant women | F21: consumption | G21: amount of vehicle consumed daily | H21: Vehicle consumption by WRA -- amount | I21: standard deviation | J21: g/day | K21: 2021 | L21: NFCMS, Table 147, p 193 | M21: =(51.4 - 11.5)/1.35 -> 29.555556 | Q21: No, GF did not provide SD | R21: Assuming normal distribution | S21: Very rough estimate using SD = IQR / 1.35 (normality assumption)
A22: Nigeria | B22: Wheat | C22: 2 | D22: Total | E22: Children U5 | F22: consumption | G22: amount of vehicle consumed daily | H22: Vehicle consumption by U5 children -- amount | I22: mean | J22: g/day | K22: 2021 | L22: NFCMS, Table 148, p 194 | M22: 26 | N22: [22.9, 29.2] | O22: 95% CI | P22: 1.6 | Q22: No, GF did not provide children specific numbers in new spreadsheet | R22: probably use sex-specific numbers over this?
A23: Nigeria | B23: Wheat | C23: 2 | D23: Total | E23: Children U5 - male | F23: consumption | G23: amount of vehicle consumed daily | H23: Vehicle consumption by U5 children -- amount | I23: mean | J23: g/day | K23: 2021 | L23: NFCMS, Table 148, p 194 | M23: 26.9 | N23: [23.3, 30.4] | O23: 95% CI | P23: 1.8 | Q23: No, GF did not provide children specific numbers in new spreadsheet | S23: GF input file states sex-specific values for U5 children "not to be projected / filled out". But not sure why? Maybe can safely assume no significant difference between sexes for children U5?
A24: Nigeria | B24: Wheat | C24: 2 | D24: Total | E24: Children U5 - female | F24: consumption | G24: amount of vehicle consumed daily | H24: Vehicle consumption by U5 children -- amount | I24: mean | J24: g/day | K24: 2021 | L24: NFCMS, Table 148, p 194 | M24: 25.1 | N24: [21.0, 29.1] | O24: 95% CI | P24: 2.1 | Q24: No, GF did not provide children specific numbers in new spreadsheet | S24: GF input file states sex-specific values for U5 children "not to be projected / filled out". But not sure why? Maybe can safely assume no significant difference between sexes for children U5?
A25: Nigeria | B25: Wheat | C25: 2 | D25: Total | E25: Children U5 | F25: consumption | G25: amount of vehicle consumed daily | H25: Vehicle consumption by U5 children -- amount | I25: standard deviation | J25: g/day | K25: 2021 | L25: NFCMS, Table 148, p 194 | M25: =(37.4 - 8.5)/1.35 -> 21.407407 | Q25: No, GF did not provide SD | S25: Very rough estimate using SD = IQR / 1.35 (normality assumption)
A26: Nigeria | B26: Wheat | C26: 2 | D26: Total | E26: Children U5 - male | F26: consumption | G26: amount of vehicle consumed daily | H26: Vehicle consumption by U5 children -- amount | I26: standard deviation | J26: g/day | K26: 2021 | L26: NFCMS, Table 148, p 194 | M26: =(39.5 - 7.5)/1.35 -> 23.703704 | Q26: No, GF did not provide SD | S26: Very rough estimate using SD = IQR / 1.35 (normality assumption)
A27: Nigeria | B27: Wheat | C27: 2 | D27: Total | E27: Children U5 - female | F27: consumption | G27: amount of vehicle consumed daily | H27: Vehicle consumption by U5 children -- amount | I27: standard deviation | J27: g/day | K27: 2021 | L27: NFCMS, Table 148, p 194 | M27: =(35.2 - 9.5)/1.35 -> 19.037037 | Q27: No, GF did not provide SD | S27: Very rough estimate using SD = IQR / 1.35 (normality assumption)
A28: Nigeria | B28: Wheat | C28: 2 | D28: Total | E28: All | F28: consolidation | G28: proportion of vehicle produced by industrial-scale facilities and therefore deemed fortifiable | H28: Vehicle "fortifiability" (essentially amount industrially produced) | I28: percentage | J28: % | K28: 2026 | L28: Millers for Nutrition (M4N) Database | M28: 100 | Q28: Yes
A29: Nigeria | B29: Salt | C29: 2 | D29: Total | E29: Non-pregnant WRA | F29: coverage | G29: use of vehicle, regardless of fortification | H29: Vehicle consumption by WRA -- any | I29: percentage | J29: % | K29: 2021 | L29: NFCMS, Table 166, p 215 | M29: 99.3 | N29: [99.0, 99.6] | O29: 95% CI | Q29: Yes, but maybe a typo on their sheet? They put 99.2?
A30: Nigeria | B30: Salt | C30: 2 | D30: Lowest | E30: Non-pregnant WRA | F30: coverage | G30: use of vehicle, regardless of fortification | H30: Vehicle consumption by WRA -- any | I30: percentage | J30: % | K30: 2021 | L30: NFCMS, Table 166, p 215 | M30: 99.5 | N30: [98.9, 100.0] | O30: 95% CI | Q30: Yes
A31: Nigeria | B31: Salt | C31: 2 | D31: Second | E31: Non-pregnant WRA | F31: coverage | G31: use of vehicle, regardless of fortification | H31: Vehicle consumption by WRA -- any | I31: percentage | J31: % | K31: 2021 | L31: NFCMS, Table 166, p 215 | M31: 99.7 | N31: [99.4, 100.0] | O31: 95% CI | Q31: Yes
A32: Nigeria | B32: Salt | C32: 2 | D32: Middle | E32: Non-pregnant WRA | F32: coverage | G32: use of vehicle, regardless of fortification | H32: Vehicle consumption by WRA -- any | I32: percentage | J32: % | K32: 2021 | L32: NFCMS, Table 166, p 215 | M32: 99.5 | N32: [99.0, 99.9] | O32: 95% CI | Q32: Yes
A33: Nigeria | B33: Salt | C33: 2 | D33: Fourth | E33: Non-pregnant WRA | F33: coverage | G33: use of vehicle, regardless of fortification | H33: Vehicle consumption by WRA -- any | I33: percentage | J33: % | K33: 2021 | L33: NFCMS, Table 166, p 215 | M33: 99.4 | N33: [98.7, 100.0] | O33: 95% CI | Q33: Yes
A34: Nigeria | B34: Salt | C34: 2 | D34: Highest | E34: Non-pregnant WRA | F34: coverage | G34: use of vehicle, regardless of fortification | H34: Vehicle consumption by WRA -- any | I34: percentage | J34: % | K34: 2021 | L34: NFCMS, Table 166, p 215 | M34: 98.5 | N34: [97.1, 99.9] | O34: 95% CI | Q34: Yes
A35: Nigeria | B35: Salt | C35: 2 | D35: Total | E35: Pregnant women | F35: coverage | G35: use of vehicle, regardless of fortification | H35: Vehicle consumption by WRA -- any | I35: percentage | J35: % | K35: 2021 | L35: NFCMS, Annex 42, p 548 | M35: 99.1 | N35: [98.5, 99.8] | O35: 95% CI | Q35: No, GF used non-pregnant WRA values for all WRA values
A36: Nigeria | B36: Salt | C36: 2 | D36: Total | E36: Children U5 | F36: coverage | G36: use of vehicle, regardless of fortification | H36: Vehicle consumption by U5 children -- any | I36: percentage | J36: % | K36: 2021 | L36: NFCMS, Annex 42, p 548 | M36: 99.2 | N36: [98.8, 99.6] | O36: 95% CI | Q36: No, GF did not provide children specific numbers in new spreadsheet
A37: Nigeria | B37: Salt | C37: 2 | D37: Total | E37: Non-pregnant WRA | F37: consumption | G37: amount of vehicle consumed daily | H37: Vehicle consumption by WRA -- amount | I37: mean | J37: g/day | K37: 2021 | L37: NFCMS, Table 167, p 217 | M37: 3.9 | N37: [3.7, 4.1] | O37: 95% CI | P37: 0.1 | Q37: Yes
A38: Nigeria | B38: Salt | C38: 2 | D38: Lowest | E38: Non-pregnant WRA | F38: consumption | G38: amount of vehicle consumed daily | H38: Vehicle consumption by WRA -- amount | I38: mean | J38: g/day | K38: 2021 | L38: NFCMS, Table 167, p 217 | M38: 4.2 | N38: [3.8, 4.6] | O38: 95% CI | P38: 0.2 | Q38: Yes
A39: Nigeria | B39: Salt | C39: 2 | D39: Second | E39: Non-pregnant WRA | F39: consumption | G39: amount of vehicle consumed daily | H39: Vehicle consumption by WRA -- amount | I39: mean | J39: g/day | K39: 2021 | L39: NFCMS, Table 167, p 217 | M39: 4 | N39: [3.5, 4.4] | O39: 95% CI | P39: 0.2 | Q39: Yes
A40: Nigeria | B40: Salt | C40: 2 | D40: Middle | E40: Non-pregnant WRA | F40: consumption | G40: amount of vehicle consumed daily | H40: Vehicle consumption by WRA -- amount | I40: mean | J40: g/day | K40: 2021 | L40: NFCMS, Table 167, p 217 | M40: 3.8 | N40: [3.5, 4.2] | O40: 95% CI | P40: 0.2 | Q40: Yes
...

Sheet MN baseline fortification
A1: Country | B1: Vehicle | C1: Fortificant | D1: Model | E1: Quintile | F1: Term | G1: Term definition | H1: Data need | I1: Data point name | J1: Units | K1: Year | L1: Data source | M1: Value | N1: 95% CI | O1: Current GF input? | P1: Limitations | Q1: Notes
A2: Nigeria | B2: Wheat | C2: Iron | D2: 2 | E2: Total | F2: baseline fortification | H2: Vehicle fortication at baseline -- any | I2: percentage | J2: % | K2: 2022 | L2: NFCMS, Table 146, p 191 | M2: 12.6 | O2: No, not an input for GF | Q2: any level of fortification
A3: Nigeria | B3: Wheat | C3: Iron | D3: 2 | E3: Total | F3: nutrient concentration | H3: Vehicle fortication at baseline -- amount among fortified | I3: concentration | J3: ppm | K3: 2021 | L3: NFCMS, Table 178, p 229 | M3: 53.9 | O3: SHOULD CONFIRM WITH GF No, they don't include nutrient concentrations in their input sheet | Q3: mean iron concentration in fortified samples
A4: Nigeria | B4: Wheat | C4: Iron | D4: 2 | E4: Total | F4: nutrient concentration | H4: Vehicle fortication at baseline -- amount among fortified | I4: concentration | J4: ppm | K4: 2021 | L4: NFCMS,Table | M4: 40 | O4: SHOULD CONFIRM WITH GF No, they don't include nutrient concentrations in their input sheet
A5: Nigeria | B5: Wheat | C5: Iron | D5: 2 | E5: Total | F5: compliance | G5: proportion of of fortifiable product that is actually fortified and meets standard | H5: Baseline effective % of fortified | I5: percentage | J5: % | K5: 2026 | L5: M4N Database | M5: 63 | O5: Yes | Q5: they don't have specific values for MN, so this number is for every MN
A6: Nigeria | B6: Wheat | C6: Iron | D6: 2 | E6: Total | F6: compliance | G6: proportion of of fortifiable product that is actually fortified and meets standard | H6: Baseline effective % of fortified | I6: percentage | J6: % | L6: NFCMS, Figure 28, p 229 | M6: 73 | O6: No | Q6: fortified "at or above standard"
A7: Nigeria | B7: Wheat | C7: Iron | D7: 2 | E7: Total | F7: effective coverage | G7: coverage x consolidation x compliance | H7: idk | I7: percentage | J7: % | L7: calculated from previous inputs | M7: 17.6 | O7: Yes | Q7: they don't have specific values for MN, so this number is for every MN
A8: Nigeria | B8: Wheat | C8: Folic Acid | D8: 2 | E8: Total | F8: baseline fortification | H8: Vehicle fortication at baseline -- any | I8: percentage | J8: % | L8: Assumption | M8: 0 | O8: No, not an input for GF
A9: Nigeria | B9: Wheat | C9: Folic Acid | D9: 2 | E9: Total | F9: nutrient concentration | H9: Vehicle fortication at baseline -- amount among fortified | I9: concentration | J9: ppm | L9: Assumption | M9: 0 | O9: SHOULD CONFIRM WITH GF No, they don't include nutrient concentrations in their input sheet | Q9: irrelevant bc fortification % is at 0?
A10: Nigeria | B10: Wheat | C10: Folic Acid | D10: 2 | E10: Total | F10: compliance | G10: proportion of of fortifiable product that is actually fortified and meets standard | H10: Baseline effective % of fortified | I10: percentage | J10: % | L10: Assumption | M10: 0 | O10: No | Q10: GF Input in their 20260416 input (I am assuming N/A means 0)
A11: Nigeria | B11: Wheat | C11: Folic Acid | D11: 2 | E11: Total | F11: compliance | G11: proportion of of fortifiable product that is actually fortified and meets standard | H11: Baseline effective % of fortified | I11: percentage | J11: % | L11: Assumption | M11: 63 | O11: Yes | Q11: they don't have specific values for MN, so this number is for every MN
A12: Nigeria | B12: Wheat | C12: Folic Acid | D12: 2 | E12: Total | F12: effective coverage | G12: coverage x consolidation x compliance | H12: idk | I12: percentage | J12: % | L12: assumption | M12: 0 | O12: No | Q12: Assumption using the GF Input of N/A
A13: Nigeria | B13: Wheat | C13: Folic Acid | D13: 2 | E13: Total | F13: effective coverage | G13: coverage x consolidation x compliance | H13: idk | I13: percentage | J13: % | L13: calculated from previous inputs | M13: 17.6 | O13: Yes | Q13: they don't have specific values for MN, so this number is for every MN
A14: Nigeria | B14: Salt | C14: Folic Acid | D14: 2 | E14: Total | F14: baseline fortification | H14: Vehicle fortication at baseline -- any | I14: percentage | J14: % | L14: Assumption | M14: 0 | O14: No, not an input for GF | Q14: no input, but Nigeria doesn't currently fortify salt for anything except iodine: https://www.technoserve.org/wp-content/uploads/2022/08/Premix-Study-Full-Report.pdf (table 2)
A15: Nigeria | B15: Salt | C15: Folic Acid | D15: 2 | E15: Total | F15: nutrient concentration | H15: Vehicle fortication at baseline -- amount among fortified | I15: concentration | J15: ppm | L15: Assumption | M15: 0 | O15: SHOULD CONFIRM WITH GF No, they don't include nutrient concentrations in their input sheet | Q15: irrelevant bc fortification % is at 0
A16: Nigeria | B16: Salt | C16: Folic Acid | D16: 2 | E16: Total | F16: compliance | G16: proportion of of fortifiable product that is actually fortified and meets standard | H16: Baseline effective % of fortified | I16: percentage | J16: % | L16: Assumption | M16: 0 | O16: Yes | Q16: no input, but Nigeria doesn't currently fortify salt for anything except iodine: https://www.technoserve.org/wp-content/uploads/2022/08/Premix-Study-Full-Report.pdf (table 2)
A17: Nigeria | B17: Salt | C17: Folic Acid | D17: 2 | E17: Total | F17: effective coverage | G17: coverage x consolidation x compliance | H17: idk | I17: percentage | J17: % | L17: calculated from previous inputs | M17: 0 | O17: Yes | Q17: I am assuming N/A means 0
A18: Nigeria | B18: Bouillon | C18: Iron | D18: 1 | E18: Total | F18: baseline fortification | H18: Vehicle fortication at baseline -- any | I18: percentage | J18: % | L18: NFCMS, Table 146, p 191 | M18: =60.7/'Vehicle Consumption'!M59*100 -> 61.875637 | O18: No | Q18: Assumption: labeled as fortified = fortified (basically true for salt). Divided "consumed food labeled as fortified" by "consumed food".
A19: Nigeria | B19: Bouillon | C19: Iron | D19: 1 | E19: Lowest | F19: baseline fortification | H19: Vehicle fortication at baseline -- any | I19: percentage | J19: % | L19: NFCMS, Table 146, p 191 | M19: =50/'Vehicle Consumption'!M60*100 -> 51.92108 | O19: No | Q19: Assumption: labeled as fortified = fortified (basically true for salt). Divided "consumed food labeled as fortified" by "consumed food".
A20: Nigeria | B20: Bouillon | C20: Iron | D20: 1 | E20: Second | F20: baseline fortification | H20: Vehicle fortication at baseline -- any | I20: percentage | J20: % | L20: NFCMS, Table 146, p 191 | M20: =57.3/'Vehicle Consumption'!M61*100 -> 58.409786 | O20: No | Q20: Assumption: labeled as fortified = fortified (basically true for salt). Divided "consumed food labeled as fortified" by "consumed food".
A21: Nigeria | B21: Bouillon | C21: Iron | D21: 1 | E21: Middle | F21: baseline fortification | H21: Vehicle fortication at baseline -- any | I21: percentage | J21: % | L21: NFCMS, Table 146, p 191 | M21: =63.3/'Vehicle Consumption'!M62*100 -> 63.810484 | O21: No | Q21: Assumption: labeled as fortified = fortified (basically true for salt). Divided "consumed food labeled as fortified" by "consumed food".
A22: Nigeria | B22: Bouillon | C22: Iron | D22: 1 | E22: Fourth | F22: baseline fortification | H22: Vehicle fortication at baseline -- any | I22: percentage | J22: % | L22: NFCMS, Table 146, p 191 | M22: =66/'Vehicle Consumption'!M63*100 -> 66.93712 | O22: No | Q22: Assumption: labeled as fortified = fortified (basically true for salt). Divided "consumed food labeled as fortified" by "consumed food".
A23: Nigeria | B23: Bouillon | C23: Iron | D23: 1 | E23: Highest | F23: baseline fortification | H23: Vehicle fortication at baseline -- any | I23: percentage | J23: % | L23: NFCMS, Table 146, p 191 | M23: =69/'Vehicle Consumption'!M64*100 -> 69.979716 | O23: No | Q23: Assumption: labeled as fortified = fortified (basically true for salt). Divided "consumed food labeled as fortified" by "consumed food".
A24: India | B24: Rice | F24: compliance | H24: Baseline effective % of fortified | I24: percentage | J24: % | M24: 50 | Q24: this is for government rice only

Sheet MN intervention fortification
A1: Country | B1: Vehicle | C1: Fortificant | D1: Scenario | E1: Data need | F1: Data point name | G1: Units | H1: Data source | I1: Value | J1: Notes
A2: Nigeria | B2: Wheat | C2: Iron | D2: Intervention | E2: Intervention coverage % of fortifiable | F2: percentage | G2: % | H2: GF Input 2035 Compliance | I2: =SQRT(1)*100 -> 100 | J2: coverage = effectiveness = 1 (100%)
A3: Nigeria | B3: Wheat | C3: Folic Acid | D3: Intervention | E3: Intervention coverage % of fortifiable | F3: percentage | G3: % | H3: GF Input 2035 Compliance | I3: =SQRT(1)*100 -> 100 | J3: coverage = effectiveness = 1 (100%)
A4: Nigeria | B4: Salt | C4: Folic Acid | D4: Intervention | E4: Intervention coverage % of fortifiable | F4: percentage | G4: %
A5: Nigera | B5: Wheat | C5: Iron | D5: Total | E5: Vehicle fortification in intervention -- amount among fortified | F5: concentration | G5: ppm | H5: TechnoServe, 2019; Table 2 | I5: 40 | J5: Nigeria Mandatory Fortification Standards; no value in GF input file; originally given as mg/kg, which is equivalent to ppm and mcg/g
A6: Nigera | B6: Wheat | C6: Folic Acid | D6: Total | E6: Vehicle fortification in intervention -- amount among fortified | F6: concentration | G6: ppm | H6: TechnoServe, 2019; Table 2 | I6: 2.6 | J6: Nigeria Mandatory Fortification Standards; no value in GF input file; originally given as mg/kg, which is equivalent to ppm and mcg/g
A7: Nigera | B7: Salt | C7: Folic Acid | D7: Total | E7: Vehicle fortification in intervention -- amount among fortified | F7: concentration | G7: ppm

Sheet Biology
A1: Data need | B1: Measure | C1: Units | D1: Value | E1: Uncertainty | F1: Year | G1: Data source author | H1: Data source Title | I1: URL | J1: Notes
A2: baseline RBC folate distribution | F2: 2026 | G2: Berihu et al. | H2: High prevalence and associated factors of red blood cell folate deficiency among first-trimester pregnant women in a neural tube defect high-risk Region of Tigray, Northern Ethiopia | I2: https://pubmed.ncbi.nlm.nih.gov/42623418/
A3: lack of good serum folate threshold for NTDs | F3: 2025 | G3: Tesfaye et al. | H3: Serum Folate Concentration Corresponding to the Red Blood Cell Folate Threshold for Increased Risk of Neural Tube Defects Among Ethiopian Women of Reproductive Age | I3: https://onlinelibrary.wiley.com/doi/full/10.1111/mcn.70121
A4: RBC folate effect on NTD incidence | F4: 2014 | G4: Crider et al.* | H4: Population red blood cell folate concentrations for prevention of neural tube defects: Bayesian model | I4: https://pubmed.ncbi.nlm.nih.gov/25073783/
A5: anemia etiology in Ethiopia | F5: 2022 | G5: Andersen et al.* | H5: Anemia Etiology in Ethiopia: Assessment of Nutritional, Infectious Disease, and Other Risk Factors in a Population-Based Cross-Sectional Survey of Women, Men, and Children | I5: https://pubmed.ncbi.nlm.nih.gov/34647598/

Sheet Sheet1
A1: Vehicle | B1: Data need | C1: Data point name | D1: Units | E1: Year | F1: Data source | G1: Value | H1: CI | I1: Notes
A2: Rice | B2: Iron fortification/consumption effect on hemoglobin | C2: Mean difference | D2: g/L | E2: Unpublished | F2: Dorbu et al. Nutritional anemia reductions due to food fortification among women of childbearing age: a systematic review and Bayesian meta-analysis. Unpublished data. | G2: 3.25 | H2: 0.9-5.71 | I2: "This comes from a slide deck that Jonathan send to Abie. It is credited to Helena.Pachon@emory.edu". There are also https://doi.org/10.1080/09637486.2020.1855126 and https://iris.who.int/bitstream/handle/10665/272535/9789241550291-eng.pdf?ua=1 which report similar-ish numbers but this is the one we got from Gates.
A3: Salt | B3: Iron fortification/consumption effect on hemoglobin | C3: Mean difference | D3: g/L | E3: 2021 | F3: Can Double Fortification of Salt with Iron and Iodine Reduce Anemia, Iron Deficiency Anemia, Iron Deficiency, Iodine Deficiency, and Functional Outcomes? Evidence of Efficacy, Effectiveness, and Safety | G3: 4.4 | H3: 2.3-6.4 | I3: https://www.ncbi.nlm.nih.gov/pmc/articles/PMC7882357/; meta-analysis of 22 studies
A4: Bouillon | B4: Iron fortification/consumption effect on hemoglobin | C4: Mean difference | D4: g/L | E4: 2012 | F4: Effect of iron-fortified foods on hematologic and biological outcomes: systematic review of randomized controlled trials | G4: 4.2 | H4: 2.8-5.6 | I4: https://www.sciencedirect.com/science/article/pii/S0002916523028915; could not find anything bouillon-specific
A6: Rice | B6: Iron fortification/consumption effect on birthweight | C6: Mean difference | D6: g/(mg/person-day) | E6: 2013 | F6: Anaemia, prenatal iron use, and risk of adverse pregnancy outcomes: systematic review and meta-analysis | G6: 1.67 | H6: 0.729 to 2.611 | I6: https://www.bmj.com/content/346/bmj.f3443; study of supplementation at higher doses than fortification; selected the effect among trials <66mg/day as all fortification would fall in this range
A7: Bouillon | B7: Iron fortification/consumption effect on birthweight | C7: Mean difference | D7: g/(mg/person-day) | E7: 2013 | F7: Anaemia, prenatal iron use, and risk of adverse pregnancy outcomes: systematic review and meta-analysis | G7: 1.67 | H7: 0.729 to 2.611 | I7: https://www.bmj.com/content/346/bmj.f3443; study of supplementation at higher doses than fortification; selected the effect among trials <66mg/day as all fortification would fall in this range
A9: Wheat | B9: Iron fortification/consumption effect on hemoglobin | C9: Mean difference
