Workbook

Sheet Burden x Vehicle Matrix
A1: Burden × Vehicle Matrix — 8 countries; VA, Iron, Folate (+ Zinc for status) | N1: LAST UPDATED: 16 September 2026
A2: Burden shown three ways (DALYs, % inadequate intake, biomarker deficiency). Vehicle columns (consolidation, coverage, per-capita g/day, compliance)
C4: Burden — DALYs (all ages) | G4: % inadequate intake | K4: MN Biomarker data | O4: Wheat flour | S4: Edible oil | W4: Rice | AA4: Maize flour | AE4: Salt (DFS) | AI4: Bouillon | AM4: Additional
A5: Country | B5: Tier | C5: VA | D5: Iron | E5: Folate | F5: Total | G5: VA | H5: Iron | I5: Folate | J5: Zinc | K5: VA deficiency | L5: Iron deficiency | M5: Folate deficiency/ insufficiency | N5: Zinc deficiency | O5: Cons | P5: Cov | Q5: g/cap | R5: Compl | S5: Cons | T5: Cov | U5: g/cap | V5: Compl | W5: Cons | X5: Cov | Y5: g/cap | Z5: Compl | AA5: Cons | AB5: Cov | AC5: g/cap | AD5: Compl | AE5: Cons | AF5: Cov | AG5: g/cap | AH5: Compl | AI5: Cons | AJ5: Cov | AK5: g/cap | AL5: Compl | AM5: CoHD (PPP$/day) | AN5: % unable to afford | AO5: MDD-W (%) | AP5: Anemia WRA (%)
A6: Ethiopia | B6: Core | C6: 64273 | D6: 909668 | E6: 191764 | F6: =C6+D6+E6 -> 1165705 | G6: 0.873 | H6: 0.144 | I6: 0.58 | J6: 0.313 | K6: 32.0 (2022) | L6: 8.0 (2022) | M6: 63.0% (2022, RBC) | N6: 50.0% (2022) | O6: 0.6 | P6: 0.4 | Q6: 34.5 | R6: 0.4 | S6: 1 | T6: 0.9 | U6: 6.8 | V6: 0.5 | W6: n/a | X6: n/a | Y6: n/a | Z6: n/a | AA6: n/a | AB6: n/a | AC6: n/a | AD6: n/a | AE6: 0.95 | AF6: 0.98 | AG6: 7.8 | AH6: 0 | AI6: n/a | AJ6: n/a | AK6: n/a | AL6: n/a | AM6: 4.75 | AN6: 0.679 | AO6: 0.07 | AP6: 0.2
A7: India | B7: Core | C7: 286411 | D7: 13693048 | E7: 727963 | F7: =C7+D7+E7 -> 14707422 | G7: 0.975 | H7: 0.57 | I7: 0.39 | J7: 0.722 | K7: 17.6% (2018) | L7: 54.0% (2019) | M7: 41.0% (2019, serum) | N7: 18.9% (2018) | O7: 0.15 | P7: 0.927 | Q7: 122.7 | R7: 0.05 | S7: 0.74 | T7: 0.999 | U7: 30.3 | V7: 0.5 | W7: 0.5 | X7: 0.988 | Y7: 155 | Z7: 0.5 | AA7: n/a | AB7: n/a | AC7: n/a | AD7: n/a | AE7: 0.035 | AF7: 1 | AG7: 7 | AH7: 0.33 | AI7: n/a | AJ7: n/a | AK7: n/a | AL7: n/a | AM7: 4.11 | AN7: 0.355 | AO7: 0.41 | AP7: 57.2% non-preg; 52.2% preg
A8: Kenya | B8: Core | C8: 9680 | D8: 289102 | E8: 17997 | F8: =C8+D8+E8 -> 316779 | G8: 0.5265 | H8: 0.7805 | I8: 0.4553 | J8: 0.5007 | K8: 84.4% (1999) | L8: 28.6% (1999) | M8: 30.9% (2011) | N8: 52.2% (1999) | O8: 0.95 | P8: 0.47 | Q8: 55 | R8: 0.6 | S8: 0.95 | T8: 0.69 | U8: 30 | V8: 0.55 | W8: 0.74 | X8: n/a | Y8: 164 | Z8: n/a | AA8: 0.5 | AB8: 0.74 | AC8: 141 | AD8: 0.64 | AE8: n/a | AF8: n/a | AG8: n/a | AH8: n/a | AI8: n/a | AJ8: n/a | AK8: n/a | AL8: n/a | AM8: 4.26 | AN8: 0.77 | AO8: n/a | AP8: 0.322
A9: Nigeria | B9: Core | C9: 493063 | D9: 2306803 | E9: 336170 | F9: =C9+D9+E9 -> 3136036 | G9: 0.093 | H9: 0.569 | I9: 0.568 | J9: 0.744 | K9: 32.0% (2021) | L9: 10.4% (2021) | M9: 42.8% (2021, RBC) | N9: 20.4% (2021) | O9: 1 | P9: 0.28 | Q9: 39 | R9: 0.63 | S9: 0.329 | T9: 0.903 | U9: 18.7 | V9: 0.6 | W9: n/a | X9: 0.54 | Y9: 38 | Z9: n/a | AA9: 0.05 | AB9: 0.574 | AC9: n/a | AD9: n/a | AE9: n/a | AF9: 0.992 | AG9: 3.9 | AH9: n/a | AI9: n/a | AJ9: 0.981 | AK9: 6.3 | AL9: n/a | AM9: 4.17 | AN9: 0.805 | AO9: 27.7 non-preg; 28.8 preg | AP9: 25.4% non-preg; 32.8% preg
A10: Core subtotal | C10: =SUM(C6:C9) -> 853427 | D10: =SUM(D6:D9) -> 17198621 | E10: =SUM(E6:E9) -> 1273894 | F10: =C10+D10+E10 -> 19325942
A11: Bangladesh | B11: Moderate | C11: 11290 | D11: 1025044 | E11: 168025 | F11: =C11+D11+E11 -> 1204359 | G11: 0.749 | H11: 0.615 | I11: 0.42 | J11: 0.61 | K11: 20.5% (2011) | L11: 14.1% (2020) | M11: 9.1% (2011, serum) | N11: 44.6% (2011) | O11: 0.49 | P11: 0.61 | Q11: 36 | R11: 0.01 | S11: 0.34 | T11: 1 | U11: 19 | V11: 0.98 | W11: n/a | X11: 1 | Y11: 480 | Z11: 0.03 | AB11: n/a | AC11: n/a | AD11: n/a | AE11: n/a | AF11: 1 | AG11: n/a | AH11: n/a | AJ11: n/a | AK11: n/a | AL11: n/a | AM11: 4.49 | AN11: 0.444 | AO11: n/a | AP11: 0.376
A12: Indonesia | B12: Moderate | C12: 30023 | D12: 1270248 | E12: 147091 | F12: =C12+D12+E12 -> 1447362 | G12: 0.566 | H12: 0.5329 | I12: 0.8389 | J12: 0.6645 | K12: 9.8% (2023) | L12: 10.3% (2011) | M12: n/a | N12: n/a | O12: 1 | P12: 0.61 | Q12: 76 | R12: 0.9 | S12: 0.57 | T12: 0.99 | U12: 23 | V12: 0.85 | W12: n/a | X12: 0 | Y12: 256 | Z12: 0.04 | AB12: n/a | AC12: n/a | AD12: n/a | AE12: n/a | AF12: n/a | AG12: n/a | AH12: n/a | AJ12: n/a | AK12: n/a | AL12: n/a | AM12: 4.75 | AN12: 0.435 | AO12: n/a | AP12: 0.267
A13: Pakistan | B13: Moderate | C13: 93280 | D13: 2650954 | E13: 202223 | F13: =C13+D13+E13 -> 2946457 | G13: 0.8628 | H13: 0.923 | I13: 0.7823 | J13: 0.8451 | K13: 51.5% (2019) | L13: 34.3% (2019) | M13: 45.2% (2019, serum) | N13: 22.1% (2019) | O13: 0.25 | P13: 0.9 | Q13: 340 | R13: <1% | S13: 0.65 | T13: 0.98 | U13: 60 | V13: 0.52 | X13: n/a | Y13: n/a | Z13: n/a | AB13: n/a | AC13: n/a | AD13: n/a | AE13: n/a | AF13: 1 | AG13: n/a | AH13: n/a | AJ13: n/a | AK13: n/a | AL13: n/a | AM13: 3.95 | AN13: 0.603 | AO13: n/a | AP13: 0.465
A14: Tanzania | B14: Moderate | C14: 31614 | D14: 804646 | E14: 60295 | F14: =C14+D14+E14 -> 896555 | G14: 0.96 | H14: 0.65 | I14: 0.57 | J14: 0.69 | K14: 0.05 | L14: 0.3 | M14: 0.52 | N14: n/a | O14: 1 | P14: 0.529 | Q14: 25 | R14: 0.79 | S14: 1 | T14: n/a | U14: 22 | V14: 0.38 | X14: n/a | Y14: 370 | Z14: n/a | AB14: n/a | AC14: n/a | AD14: n/a | AE14: n/a | AF14: 1 | AG14: n/a | AH14: n/a | AJ14: n/a | AK14: n/a | AL14: n/a | AM14: 3.37 | AN14: 0.738 | AO14: n/a | AP14: 0.37
A15: Moderate subtotal | C15: =SUM(C11:C14) -> 166207 | D15: =SUM(D11:D14) -> 5750892 | E15: =SUM(E11:E14) -> 577634 | F15: =C15+D15+E15 -> 6494733
A16: All 8 countries | C16: =SUM(C6:C9)+SUM(C11:C14) -> 1019634 | D16: =SUM(D6:D9)+SUM(D11:D14) -> 22949513 | E16: =SUM(E6:E9)+SUM(E11:E14) -> 1851528 | F16: =SUM(F6:F9)+SUM(F11:F14) -> 25820675
A18: Notes & sources
A19: • DALYs = all ages, GBD/IHME
A20: • % inadequate intake: BLACK = WFP-MIMI (HungerMap, HCES-based) for Ethiopia, Nigeria, India (VA), Bangladesh. PURPLE = ISI - India (Iron, Folate, Zinc) BLUE italic = Passarelli et al. 2024
A21: • Biomarker deficiency = most recent NATIONAL survey in WHO VMNIS. Cell shows prevalence (survey year); hover for population group. VA = serum retinol (preschool children); iron = ferritin (WRA); folate = RBC folate (WRA), EXCEPT India = serum folate (labeled in-cell as 'serum'; see cell comment for detail); zinc = serum/plasma zinc (preschool children).
A22: • Nigeria = NFCMS 2021 / Project MAP national survey
A23: • Ethiopia = National Nutrition Survey 2021/22

Sheet Definitions
A3: Definitions
A5: Coverage: use of a vehicle, whether fortifiable, or not.
A6: Consolidation: the share of that vehicle produced by industrial-scale facilities and therefore deemed fortifiable. In the case of DFS, this variable is used to indicate the % of the iodized salt industry that is amenable to DFS with iron or folic acid in addition to iodine.
A7: Compliance: the share of fortifiable product that is actually fortified and meets standard. For now, we assume 100% of all fortifiable foods are being fortified, but may want to refine with that nuance later.
A9: Effective Coverage: Coverage x Consolidation x Compliance.
A10: Reach: the population figure at each stage of that cascade, i.e. reach of coverage, reach of fortifiable (coverage x consolidation), and effective reach (the number of people consuming a fortifiable vehicle that has actually been fortified to standard).

Sheet Sources
A1: LSFF background data — sources & document management
A2: This workbook is the single live file for LSFF background data (current state). Source files below are dated, read-only INPUTS — not living parallel documents. When a source issues a new release, re-run the same alignment into this file, note what changed, and re-archive the source with its date. One update path, one live file.
A4: Source | B4: Date / version | C4: Status | D4: What it feeds | E4: Columns / indicators used | F4: Notes
A5: M4N (Millers for Nutrition) | B5: 20260909 | C5: Input — archived | D5: Current-state vehicle data (wheat, oil, rice) | E5: Col C = consolidation; Col D = consumption; Col F = 2026 compliance | F5: Reach & effective coverage (other cols) are downstream/out of scope and NOT used. Not a live companion file; current-state only (no forward-looking pathways).
A6: IHME — Input data to models | B6: 20260416 | C6: Input — archived | D6: Stratified vehicle sheets; national coverage & consumption | E6: Per-capita consumption & coverage by stratum (zone/region, wealth quintile, urban/rural), WRA | F6: Projections (2030/2035) intentionally excluded from this file. National values reconciled to the cover sheet.
A7: WFP-MIMI (HungerMap, HCES-based) | B7: 2024–25 | C7: Input | D7: % inadequate intake | E7: VA, iron, folate, zinc (Ethiopia, Nigeria, India VA, Bangladesh) | F7: Method differs from Passarelli; treated distinctly (see cover-sheet note).
A8: ISI — India | B8: 2023–24 | C8: Input | D8: % inadequate intake (India) | E8: India iron, folate, zinc | F8: India zinc added (was 85.3% → 72.2%).
A9: Passarelli et al. 2024 (Lancet GH) | B9: 2024 | C9: Input | D9: % inadequate intake (diet-only, upper-bound) | E9: Kenya, Indonesia, Pakistan, Tanzania where MIMI not shown | F9: Diet-only, upper-bound; shown where MIMI unavailable.
A10: GBD 2023 | B10: 2023 | C10: Input | D10: Burden (DALYs) by nutrient | E10: VA, iron, folate DALYs | F10: Anchored to GAIN GBD 2023 series.
A11: Ethiopia National Nutrition Survey | B11: 2021-22 | C11: Input | D11: MN biomarkers | F11: Ethiopian Public Health Institute (EPHI). 2025. Ethiopia Food and Nutrition Strategy Baseline
A12: Nigeria NFCMS | B12: 2021 | C12: Input | D12: MN biomarkers | E12: MN biomarkers and Per-capita consumption by wealth quintile / residence | F12: FMOHSW, IITA, Gates Foundation, NSN, GroundWork. Nigeria Micronutrient Biomarkers Analysis: National Level Infographic. Abuja, Nigeria; 2026
A14: UPDATE LOG (add a row every time this file changes; bump the LAST UPDATED date on the cover sheet)
A15: Date | B15: What changed | C15: By
A16: 11 Sep 2026 | B16: Established single LSFF background data file: national cover sheet + 5 stratified country sheets; aligned wheat/oil/rice consolidation, consumption and 2026 compliance to M4N (cols C/D/F); India zinc inadequacy updated to 72.2% (ISI); added Sources tab and scope note. | C16: JG
A17: 11 Sep 2026 | B17: Linked each country sheet National row to the cover sheet (live formulas). Cover sheet is the single edit point for national values; National rows on country sheets now mirror it automatically. | C17: JG
A18: 11 Sep 2026 | B18: Country tabs rebuilt as full mirrors of the cover: added IHME stratified biomarker & % inadequate (iron/VA/folate) alongside vehicle strata; created tabs for all 8 countries; National row links to cover (cover overrules, IHME national not used); empty IHME strata dropped. Strata not yet reconciled to cover national (to clean up). | C18: JG
A19: 11 Sep 2026 | B19: Ethiopia tab rebuilt from the 2022 Ethiopia National Nutrition Survey (FNS baseline upload): stratified biomarker (incl. zinc, B12, vit D) and wheat/oil/salt intake & coverage by region, urban/rural, wealth quintile. National still links to cover. | C19: JG
A20: 12 Sept 2026 | B20: Created a new sheet titled 'reach' which calculates the reach of fortification based on coverage (number of people using the vehicle), consolidated coverage (number of people using the industrially produced 'fortifiable' vehicle) and 'effective reach' (number of people using the fortifiable vehicle which has been fortified to standard). This sheet is linked to the first sheet on this file (columns O-AL) so those cells all need to be completed. For DFS, I suggest that we do not refer to salt, but only that segment of the population with access DFS. | C20: JG
A21: 12 Sep 2026 | B21: Added three new 'Additional (survey)' columns to the Burden x Vehicle Matrix tab and each of the 8 country stratified tabs: Cost of a Healthy Diet (CoHD, PPP$/day + % unable to afford, World Bank Food Prices for Nutrition v4.0 / FAO CoAHD, 2024, all 8 countries), Minimum Dietary Diversity for Women (MDD-W, women 15-49; only Ethiopia, India, and Nigeria populated from the Oct 2026 strategy deck; Kenya, Bangladesh, Indonesia, Pakistan, Tanzania left n/a pending country-specific DHS/MICS/survey sourcing), and Anemia prevalence in women of reproductive age (WHO Global Health Observatory / WDI indicator SH.ANM.ALLW.ZS, 2023, all 8 countries, any anaemia not severe-only). Every populated cell carries a comment with its exact source and definition. | C21: JG
A22: 13 Sep 2026 | B22: Upgraded Anemia WRA and CoHD/MDD-W citations using newly uploaded primary sources: Ethiopia's anemia figure replaced with the direct national FNSBS 2021-2022 survey result (20%, was the WHO GHO modeled 23.1%); India's CoHD updated to the current SOFI 2026 figure ($4.11/35.5%, was an older $4.07/40.4% snapshot) and anemia/MDD-W citations tightened (NFHS-5 2021; Global Diet Quality Project 2025) per the 8 Sep 2026 India MN Indicators deck; Nigeria's anemia figure replaced with its own NFCMS 2021 survey result (25.4% non-preg/32.8% preg, was the WHO GHO modeled 37.9%), since a better direct source was already available and should have been used the first time. Kenya, Bangladesh, Indonesia, Pakistan, Tanzania anemia figures remain WHO GHO modeled estimates pending equivalent direct national sources. | C22: JG
A23: 13 Sep 2026 | B23: Updated Ethiopia and Nigeria CoHD to genuine SOFI 2026 figures (Annex Table A1.5/A1.6, 2025 data), now sourced from the actual SOFI 2026 PDF rather than the 2024-vintage World Bank Food Prices for Nutrition snapshot used previously. Ethiopia: $4.75/day, 67.9% unable to afford (was $4.78/54.2%). Nigeria: $4.17/day, 80.5% unable to afford (was $4.72/79.3%). India's existing SOFI 2026 figures ($4.11/35.5%) independently confirmed against the same annex tables, unchanged. All 8 countries' CoHD figures are now consistent in intent (SOFI 2026 where confirmed), though Kenya, Bangladesh, Indonesia, Pakistan, Tanzania still reflect the 2024 World Bank vintage pending the same confirmation. | C23: JG
A24: 13 Sep 2026 | B24: Added a source comment to India's Folate insufficiency cell (Burden x Vehicle Matrix, row 7 col M) confirming it is serum folate, not RBC folate as the column's general legend states — a documented exception. Ethiopia's Folate insufficiency (63.0%, EPHI 2022) confirmed as the value to use going forward over the alternate 58.5% figure pulled directly from FNSBS Table 5.7's <748 nmol/L cutoff; no change to the cell itself since 63.0% was already there, only downstream materials updated to match. | C24: JG
A25: 13 Sep 2026 | B25: Confirmed and tightened the citation on Ethiopia's Folate insufficiency cell (63.0%): sourced to Figure 5.7 specifically in the Ethiopia FNSBS 2021-2022 report (EPHI, Feb 2025), a three-category Sufficiency/Insufficiency/Deficiency classification, distinct from the report's Table 5.7 NTD-risk cutoffs (<748/<906 nmol/L) used earlier in error. No value changed, only the source documentation. | C25: JG
A26: 13 Sep 2026 | B26: Added a new '% unable to afford' column immediately after CoHD (PPP$/day) in the Burden x Vehicle Matrix tab and all 8 country stratified tabs, populated for all 8 countries. Restyled the entire 'Additional (survey)' block (CoHD, % unable to afford, MDD-W, Anemia WRA) to match the sheet's existing convention: amber header fill/white bold Arial 8pt for headers, light green fill/Arial 8pt/thin gray border for data cells, matching the pre-existing B12/Vit D columns exactly. Converted purely-numeric MDD-W and Anemia WRA cells from raw numbers to fractions with 0.0% number format, consistent with how percentages are stored elsewhere in this sheet (compound pregnant/non-pregnant text cells left as text). Enabled text wrap and increased row height on all affected rows so multi-part values (e.g., 'X% non-preg; Y% preg') display on two lines instead of overflowing. Also fixed a copy error introduced during the 13 Sep SOFI 2026 update: Nigeria's stratified tab had its Anemia WRA cell overwritten with a CoHD value due to a hardcoded column index that didn't account for Nigeria's column layout; both cells are now correct and match the main tab. | C26: JG
A27: 13 Sep 2026 | B27: Made the Folate insufficiency biomarker method visible in-cell rather than only in comments: Ethiopia and Nigeria now read '...RBC)', India now reads '...serum)'. Updated the sheet's own legend (row 21) to document India as an explicit exception to the general 'folate = RBC folate' rule, so this is discoverable by reading the legend, not only by hovering on India's specific cell. No underlying values changed, only visible labeling. | C27: JG
A28: 46280 | B28: Updated Burden x Vehicle Matrix worksheet for Nigeria: Changed edible oil coverage to 90.3% and consolidation to 23.9%, based on email conversation between Jonathan and Alem on 9/15/26. | C28: KB
A29: 46293 | B29: India data updated by Kathy & Ruchika. Several modifications to the Burden x Vehicle sheet and Coverage over Time sheet. Changed per capita consumption for wheat, edible oil, rice, salt. Changed consolidation figures for oil, rice. In Coverage Over Time sheet, changed consolidation (2031 and 2035) for salt, rice, oil, wheat flour and changed compliance for rice (2031 and 2035) and oil. CHanged current wheat flour compliance from 5% to 50%. | C29: KB

Sheet Ethiopia (stratified)
A1: Ethiopia — national (linked to cover) + stratified detail
C3: Burden — DALYs | G3: % inadequate intake | K3: MN Biomarker | O3: Wheat flour | S3: Edible oil | W3: Rice | AA3: Maize flour | AE3: Salt | AI3: Bouillon | AM3: Additional (survey)
A4: Stratum | C4: VA | D4: Iron | E4: Folate | F4: Total | G4: VA | H4: Iron | I4: Folate | J4: Zinc | K4: VA deficiency | L4: Iron deficiency | M4: Folate insufficiency | N4: Zinc deficiency | O4: Cons | P4: Cov | Q4: g/cap | R4: Compl | S4: Cons | T4: Cov | U4: g/cap | V4: Compl | W4: Cons | X4: Cov | Y4: g/cap | Z4: Compl | AA4: Cons | AB4: Cov | AC4: g/cap | AD4: Compl | AE4: Cons | AF4: Cov | AG4: g/cap | AH4: Compl | AI4: Cons | AJ4: Cov | AK4: g/cap | AL4: Compl | AM4: B12 def | AN4: Vit D def | AO4: CoHD (PPP$/day) | AP4: % unable to afford | AQ4: MDD-W (%) | AR4: Anemia WRA (%)
A5: National | C5: =IF('Burden x Vehicle Matrix'!C6="","",'Burden x Vehicle Matrix'!C6) -> 64273 | D5: =IF('Burden x Vehicle Matrix'!D6="","",'Burden x Vehicle Matrix'!D6) -> 909668 | E5: =IF('Burden x Vehicle Matrix'!E6="","",'Burden x Vehicle Matrix'!E6) -> 191764 | F5: =IF('Burden x Vehicle Matrix'!F6="","",'Burden x Vehicle Matrix'!F6) -> 1165705 | G5: =IF('Burden x Vehicle Matrix'!G6="","",'Burden x Vehicle Matrix'!G6) -> 0.873 | H5: =IF('Burden x Vehicle Matrix'!H6="","",'Burden x Vehicle Matrix'!H6) -> 0.144 | I5: =IF('Burden x Vehicle Matrix'!I6="","",'Burden x Vehicle Matrix'!I6) -> 0.58 | J5: =IF('Burden x Vehicle Matrix'!J6="","",'Burden x Vehicle Matrix'!J6) -> 0.313 | ... AL5: =IF('Burden x Vehicle Matrix'!AL6="","",'Burden x Vehicle Matrix'!AL6) -> n/a | AM5: 0.09 | AN5: 0.34 | AO5: 4.75 | AP5: 0.679 | AQ5: 0.07 | AR5: 0.2
A6: Region
A7: Addis | L7: 0.08 | M7: 0.7 | P7: 0.53 | Q7: 21.41048 | T7: 0.96 | U7: 9.417328 | AF7: 0.98 | AG7: 6.825589 | AM7: 0.08 | AN7: 0.61
A8: Afar | L8: 0.19 | M8: 0.91 | P8: 0.38 | Q8: 86.23275 | T8: 0.79 | U8: 4.497056 | AF8: 0.96 | AG8: 6.019396 | AM8: 0.04
A9: Amhara | L9: 0.03 | M9: 0.56 | P9: 0.17 | Q9: 21.30075 | T9: 0.88 | U9: 5.867862 | AF9: 0.97 | AG9: 5.481077 | AM9: 0.08 | AN9: 0.47
A10: Benishangul-Gumuz | P10: 0.38 | Q10: 13.99703 | T10: 0.9 | U10: 9.64746 | AF10: 0.98 | AG10: 8.420136
A11: Dire Dawa | L11: 0.25 | M11: 0.85 | P11: 0.39 | Q11: 48.27154 | T11: 0.77 | U11: 10.3824 | AF11: 0.94 | AG11: 4.962971 | AM11: 0.19 | AN11: 0.11
A12: Gambela | L12: 0.07 | M12: 0.73 | P12: 0.29 | Q12: 29.32778 | T12: 0.9 | U12: 8.541496 | AF12: 0.98 | AG12: 11.81201 | AM12: 0.03 | AN12: 0.11
A13: Harari | L13: 0.18 | M13: 0.8 | P13: 0.64 | Q13: 37.91966 | T13: 0.91 | U13: 9.324589 | AF13: 0.97 | AG13: 9.085969 | AM13: 0.11 | AN13: 0.34
A14: Oromia | L14: 0.1 | M14: 0.48 | P14: 0.31 | Q14: 40.76837 | T14: 0.92 | U14: 7.278724 | AF14: 0.98 | AG14: 8.175828 | AM14: 0.13 | AN14: 0.32
A15: Sidama | L15: 0.03 | M15: 0.11 | P15: 0.33 | Q15: 14.60529 | T15: 0.92 | U15: 5.812991 | AF15: 0.97 | AG15: 7.444192 | AM15: 0.01 | AN15: 0.21
A16: SNNP | L16: 0.06 | M16: 0.39 | P16: 0.29 | Q16: 17.94918 | T16: 0.88 | U16: 7.253862 | AF16: 0.96 | AG16: 7.306291 | AM16: 0.07 | AN16: 0.21
A17: Somalia | L17: 0.48 | M17: 0.86 | P17: 0.68 | Q17: 145.7574 | T17: 0.79 | U17: 4.984524 | AF17: 0.83 | AG17: 5.262013 | AM17: 0.02 | AN17: 0.01
A18: Tigray | Q18: 25.1878 | U18: 4.194372 | AG18: 6.209738
A19: Location
A20: Urban | L20: 0.09 | M20: 0.63 | P20: 0.45 | Q20: 34.01923 | T20: 0.94 | U20: 9.169278 | AF20: 0.98 | AG20: 6.865382 | AM20: 0.07 | AN20: 0.33
A21: Rural | L21: 0.08 | M21: 0.43 | P21: 0.23 | Q21: 36.83984 | T21: 0.88 | U21: 5.446428 | AF21: 0.96 | AG21: 7.246491 | AM21: 0.1 | AN21: 0.34
A22: Wealth quintile
A23: Lowest | Q23: 64.70252 | U23: 4.385465 | AG23: 7.084152
A24: 2nd | Q24: 29.85205 | U24: 5.38305 | AG24: 7.235241
A25: 3rd | Q25: 23.55881 | U25: 5.78538 | AG25: 7.704005
A26: 4th | Q26: 32.09161 | U26: 6.990192 | AG26: 7.157051
A27: Wealthiest | Q27: 29.97842 | U27: 10.23495 | AG27: 6.504427

Sheet India (stratified)
A1: India — national (linked to cover) + stratified detail
C3: Burden — DALYs | G3: % inadequate intake | K3: MN Biomarker | O3: Wheat flour | S3: Edible oil | W3: Rice | AA3: Maize flour | AE3: Salt | AI3: Bouillon | AM3: Additional (survey)
A4: Stratum | C4: VA | D4: Iron | E4: Folate | F4: Total | G4: VA | H4: Iron | I4: Folate | J4: Zinc | K4: VA deficiency | L4: Iron deficiency | M4: Folate deficiency | N4: Zinc deficiency | O4: Cons | P4: Cov | Q4: g/cap | R4: Compl | S4: Cons | T4: Cov | U4: g/cap | V4: Compl | W4: Cons | X4: Cov | Y4: g/cap | Z4: Compl | AA4: Cons | AB4: Cov | AC4: g/cap | AD4: Compl | AE4: Cons | AF4: Cov | AG4: g/cap | AH4: Compl | AI4: Cons | AJ4: Cov | AK4: g/cap | AL4: Compl | AM4: CoHD (PPP$/day) | AN4: % unable to afford | AO4: MDD-W (%) | AP4: Anemia WRA (%)
A5: National | C5: =IF('Burden x Vehicle Matrix'!C7="","",'Burden x Vehicle Matrix'!C7) -> 286411 | D5: =IF('Burden x Vehicle Matrix'!D7="","",'Burden x Vehicle Matrix'!D7) -> 13693048 | E5: =IF('Burden x Vehicle Matrix'!E7="","",'Burden x Vehicle Matrix'!E7) -> 727963 | F5: =IF('Burden x Vehicle Matrix'!F7="","",'Burden x Vehicle Matrix'!F7) -> 14707422 | G5: =IF('Burden x Vehicle Matrix'!G7="","",'Burden x Vehicle Matrix'!G7) -> 0.975 | H5: =IF('Burden x Vehicle Matrix'!H7="","",'Burden x Vehicle Matrix'!H7) -> 0.57 | I5: =IF('Burden x Vehicle Matrix'!I7="","",'Burden x Vehicle Matrix'!I7) -> 0.39 | J5: =IF('Burden x Vehicle Matrix'!J7="","",'Burden x Vehicle Matrix'!J7) -> 0.722 | ... AL5: =IF('Burden x Vehicle Matrix'!AL7="","",'Burden x Vehicle Matrix'!AL7) -> n/a | AM5: 4.11 | AN5: 0.355 | AO5: 0.41 | AP5: 57.2% non-preg; 52.2% preg
A6: Subnational
A7: Delhi | G7: 0.97491026 | H7: 0.9205 | I7: 0.2346 | K7: 0.178 | L7: 0.383 | M7: 0.013 | P7: 0.99830323 | Q7: 135.50687 | T7: 0.99554896 | U7: 24.72538 | X7: 0.99554896 | Y7: 50.582054 | AF7: 0.99945933 | AG7: 5.7249126
A8: Haryana | G8: 0.98501171 | H8: 0.6753 | I8: 0.0727 | K8: 0.261 | L8: 0.589 | M8: 0.146 | P8: 0.99501044 | Q8: 210.59589 | T8: 0.96537161 | U8: 24.701723 | X8: 0.96537161 | Y8: 23.704321 | AF8: 0.99927944 | AG8: 6.5805559
A9: Himachal Pradesh | G9: 0.98279203 | H9: 0.6889 | I9: 0.0157 | K9: 0.059 | L9: 0.345 | M9: 0.046 | P9: 0.99903983 | Q9: 171.17984 | T9: 0.9993642 | U9: 27.433989 | X9: 0.9993642 | Y9: 119.70825 | AF9: 0.99986523 | AG9: 6.3492765
A10: Jammu & Kashmir | G10: 0.9917734 | H10: 0.9052 | I10: 0.2061 | K10: 0.087 | L10: 0.447 | M10: 0.059 | P10: 0.81623322 | Q10: 101.11095 | T10: 0.99984491 | U10: 26.21459 | X10: 0.99984491 | Y10: 198.62704 | AF10: 1 | AG10: 7.8017521
A11: Punjab | G11: 0.98369409 | H11: 0.7551 | I11: 0.1315 | K11: 0.172 | L11: 0.672 | M11: 0.098 | P11: 0.98674029 | Q11: 201.11957 | T11: 0.95752209 | U11: 25.125174 | X11: 0.95752209 | Y11: 25.024855 | AF11: 0.99991995 | AG11: 5.3594785
A12: Rajasthan | G12: 0.99259376 | H12: 0.3746 | I12: 0.1812 | L12: 0.443 | M12: 0.34 | P12: 0.98871273 | Q12: 269.42532 | T12: 0.8782537 | U12: 24.978884 | X12: 0.8782537 | Y12: 11.837494 | AF12: 0.99973142 | AG12: 5.9258881
A13: Uttarakhand | G13: 0.98599564 | H13: 0.9132 | I13: 0.1334 | K13: 0.143 | L13: 0.512 | M13: 0.176 | P13: 0.9952721 | Q13: 154.72092 | T13: 0.99676031 | U13: 25.595509 | X13: 0.99676031 | Y13: 116.34589 | AF13: 0.99991512 | AG13: 5.6148005
A14: Chhattisgarh | G14: 0.99637673 | H14: 0.9643 | I14: 0.2949 | K14: 0.266 | L14: 0.385 | M14: 0.437 | P14: 0.81999797 | Q14: 32.370083 | T14: 0.99807298 | U14: 30.217583 | X14: 0.99807298 | Y14: 298.26508 | AF14: 0.99857992 | AG14: 9.4691648
A15: Madhya Pradesh | G15: 0.99695663 | H15: 0.7389 | I15: 0.2184 | K15: 0.271 | L15: 0.459 | M15: 0.576 | P15: 0.99729818 | Q15: 199.76408 | T15: 0.99331289 | U15: 28.329092 | X15: 0.99331289 | Y15: 68.452438 | AF15: 0.99981821 | AG15: 6.4904704
A16: Uttar Pradesh | G16: 0.99132478 | H16: 0.8801 | I16: 0.3264 | K16: 0.171 | L16: 0.239 | M16: 0.061 | P16: 0.99767375 | Q16: 172.67108 | T16: 0.99586356 | U16: 26.458883 | X16: 0.99586356 | Y16: 100.34937 | AF16: 0.9997164 | AG16: 5.8716803
A17: Bihar | G17: 0.99874303 | H17: 0.7997 | I17: 0.2238 | K17: 0.235 | L17: 0.202 | M17: 0.061 | P17: 0.99566168 | Q17: 154.17398 | T17: 0.99802536 | U17: 30.528366 | X17: 0.99802536 | Y17: 166.84302 | AF17: 0.99998975 | AG17: 6.8589058
A18: Jharkhand | G18: 0.99790625 | H18: 0.9454 | I18: 0.516 | K18: 0.432 | L18: 0.138 | M18: 0.053 | P18: 0.94082326 | Q18: 101.85973 | T18: 0.99683678 | U18: 26.492937 | X18: 0.99683678 | Y18: 199.76546 | AF18: 0.99987215 | AG18: 6.6892138
A19: Odisha | G19: 0.99919052 | H19: 0.9671 | I19: 0.4444 | K19: 0.198 | L19: 0.304 | M19: 0.344 | P19: 0.71896535 | Q19: 29.280603 | T19: 0.99707222 | U19: 25.537979 | X19: 0.99707222 | Y19: 307.27029 | AF19: 0.99979395 | AG19: 8.1996546
A20: West Bengal | G20: 0.98948198 | H20: 0.9641 | I20: 0.4785 | K20: 0.05 | L20: 0.211 | M20: 0.003 | P20: 0.92922521 | Q20: 57.74398 | T20: 0.99945772 | U20: 29.27389 | X20: 0.99945772 | Y20: 228.04366 | AF20: 0.99989867 | AG20: 7.9891028
A21: Arunachal Pradesh | G21: 0.95782488 | H21: 0.9728 | I21: 0.3618 | K21: 0.148 | L21: 0.149 | M21: 0.38 | P21: 0.54268056 | Q21: 8.4553947 | T21: 0.99838412 | U21: 23.987877 | X21: 0.99838412 | Y21: 303.57135 | AF21: 1 | AG21: 7.0140443
A22: Assam | G22: 0.99802106 | H22: 0.9939 | I22: 0.6007 | K22: 0.214 | L22: 0.085 | M22: 0.599 | P22: 0.76488853 | Q22: 12.129931 | T22: 0.99969351 | U22: 25.014008 | X22: 0.99969351 | Y22: 260.26859 | AF22: 0.99998498 | AG22: 6.7042794
A23: Manipur | G23: 0.99936978 | H23: 0.9977 | I23: 0.6576 | K23: 0.171 | L23: 0.174 | M23: 0.064 | P23: 0.14629008 | Q23: 0.99895924 | T23: 0.99673659 | U23: 23.835381 | X23: 0.99673659 | Y23: 348.28726 | AF23: 1 | AG23: 5.394177
A24: Meghalaya | G24: 0.99893486 | H24: 0.9966 | I24: 0.6379 | K24: 0.063 | L24: 0.249 | M24: 0.261 | P24: 0.51974893 | Q24: 5.14641 | T24: 0.99631077 | U24: 24.534634 | X24: 0.99631077 | Y24: 265.21164 | AF24: 1 | AG24: 6.6521916
A25: Mizoram | G25: 0.99045828 | H25: 0.9953 | I25: 0.5412 | K25: 0.392 | L25: 0.042 | M25: 0.179 | P25: 0.025417931 | Q25: 0.203476 | T25: 1 | U25: 31.792122 | X25: 1 | Y25: 276.02771 | AF25: 1 | AG25: 6.5104995
A26: Nagaland | G26: 0.99930574 | H26: 0.9867 | I26: 0.502 | M26: 0.741 | P26: 0.1810482 | Q26: 2.0720932 | T26: 0.99950206 | U26: 12.726721 | X26: 0.99950206 | Y26: 284.05847 | AF26: 0.99984109 | AG26: 5.4241714
A27: Sikkim | G27: 0.99354652 | H27: 0.955 | I27: 0.1768 | K27: 0.027 | L27: 0.279 | M27: 0.001 | P27: 0.88930649 | Q27: 17.102821 | T27: 0.99929965 | U27: 36.918602 | X27: 0.99929965 | Y27: 264.86871 | AF27: 1 | AG27: 6.7844028
A28: Tripura | G28: 0.99628755 | H28: 0.987 | I28: 0.4583 | K28: 0.206 | L28: 0.16 | M28: 0.01 | P28: 0.61096954 | Q28: 8.6217899 | T28: 0.9999696 | U28: 29.807993 | X28: 0.9999696 | Y28: 313.04526 | AF28: 0.9999764 | AG28: 7.3307409
A29: Goa | G29: 1 | H29: 0.6319 | I29: 0.0464 | K29: 0.024 | L29: 0.119 | M29: 0.166 | P29: 0.98881573 | Q29: 50.705395 | T29: 0.99765569 | U29: 28.409346 | X29: 0.99765569 | Y29: 194.93857 | AF29: 1 | AG29: 7.1598425
A30: Gujarat | G30: 0.99840182 | H30: 0.8629 | I30: 0.2724 | K30: 0.146 | L30: 0.557 | M30: 0.394 | P30: 0.9885518 | Q30: 140.70927 | T30: 0.9878878 | U30: 39.361961 | X30: 0.9878878 | Y30: 63.120476 | AF30: 0.99918032 | AG30: 6.1376042
A31: Maharashtra | G31: 0.99123054 | H31: 0.9172 | I31: 0.3509 | K31: 0.094 | L31: 0.49 | M31: 0.422 | P31: 0.99242949 | Q31: 123.98665 | T31: 0.99523258 | U31: 31.665016 | X31: 0.99523258 | Y31: 87.642471 | AF31: 0.99972642 | AG31: 5.9565206
A32: Andhra Pradesh | G32: 0.98720199 | H32: 0.9817 | I32: 0.3905 | K32: 0.208 | L32: 0.13 | M32: 0.627 | P32: 0.71570253 | Q32: 9.0448027 | T32: 0.99763185 | U32: 31.096489 | X32: 0.99763185 | Y32: 245.79788 | AF32: 0.99895918 | AG32: 7.3604674
A33: Karnataka | G33: 0.99292633 | H33: 0.9097 | I33: 0.3627 | K33: 0.096 | L33: 0.501 | M33: 0.36 | P33: 0.88913155 | Q33: 24.032042 | T33: 0.99884093 | U33: 28.459291 | X33: 0.99884093 | Y33: 150.68262 | AF33: 0.99988496 | AG33: 6.8505273
A34: Kerala | G34: 0.98928787 | H34: 0.8741 | I34: 0.4512 | K34: 0.171 | L34: 0.352 | M34: 0.184 | P34: 0.9323954 | Q34: 19.322989 | T34: 0.99557847 | U34: 21.453846 | X34: 0.99557847 | Y34: 178.14754 | AF34: 0.99909311 | AG34: 6.3172116
A35: Tamil Nadu | G35: 0.99574997 | H35: 0.9713 | I35: 0.4493 | K35: 0.131 | L35: 0.417 | M35: 0.239 | P35: 0.79021639 | Q35: 11.804247 | T35: 0.99681062 | U35: 27.575655 | X35: 0.99681062 | Y35: 208.96272 | AF35: 0.99910057 | AG35: 6.5872703
A36: Telangana | H36: 0.9815 | I36: 0.4605 | K36: 0.265 | L36: 0.334 | M36: 0.468 | P36: 0.85462987 | Q36: 15.28593 | T36: 0.9990347 | U36: 33.207897 | X36: 0.9990347 | Y36: 274.41928 | AF36: 1 | AG36: 7.4469528

Sheet Kenya (stratified)
A1: Kenya — national (linked to cover) + stratified detail
C3: Burden — DALYs | G3: % inadequate intake | K3: MN Biomarker | O3: Wheat flour | S3: Edible oil | W3: Rice | AA3: Maize flour | AE3: Salt | AI3: Bouillon | AM3: Additional (survey)
A4: Stratum | C4: VA | D4: Iron | E4: Folate | F4: Total | G4: VA | H4: Iron | I4: Folate | J4: Zinc | K4: VA deficiency | L4: Iron deficiency | M4: Folate insufficiency | N4: Zinc deficiency | O4: Cons | P4: Cov | Q4: g/cap | R4: Compl | S4: Cons | T4: Cov | U4: g/cap | V4: Compl | W4: Cons | X4: Cov | Y4: g/cap | Z4: Compl | AA4: Cons | AB4: Cov | AC4: g/cap | AD4: Compl | AE4: Cons | AF4: Cov | AG4: g/cap | AH4: Compl | AI4: Cons | AJ4: Cov | AK4: g/cap | AL4: Compl | AM4: CoHD (PPP$/day) | AN4: % unable to afford | AO4: MDD-W (%) | AP4: Anemia WRA (%)
A5: National | C5: =IF('Burden x Vehicle Matrix'!C8="","",'Burden x Vehicle Matrix'!C8) -> 9680 | D5: =IF('Burden x Vehicle Matrix'!D8="","",'Burden x Vehicle Matrix'!D8) -> 289102 | E5: =IF('Burden x Vehicle Matrix'!E8="","",'Burden x Vehicle Matrix'!E8) -> 17997 | F5: =IF('Burden x Vehicle Matrix'!F8="","",'Burden x Vehicle Matrix'!F8) -> 316779 | G5: =IF('Burden x Vehicle Matrix'!G8="","",'Burden x Vehicle Matrix'!G8) -> 0.5265 | H5: =IF('Burden x Vehicle Matrix'!H8="","",'Burden x Vehicle Matrix'!H8) -> 0.7805 | I5: =IF('Burden x Vehicle Matrix'!I8="","",'Burden x Vehicle Matrix'!I8) -> 0.4553 | J5: =IF('Burden x Vehicle Matrix'!J8="","",'Burden x Vehicle Matrix'!J8) -> 0.5007 | ... AL5: =IF('Burden x Vehicle Matrix'!AL8="","",'Burden x Vehicle Matrix'!AL8) -> n/a | AM5: 4.26 | AN5: 0.77 | AO5: n/a | AP5: 0.322
A6: Residence
A7: Rural | K7: 0.018 | L7: 0.214 | M7: 0.251
A8: Urban | K8: 0.004 | L8: 0.212 | M8: 0.406

Sheet Nigeria (stratified)
A1: Nigeria — national (linked to cover) + stratified detail
C3: Burden — DALYs | G3: % inadequate intake | K3: MN Biomarker | O3: Wheat flour | S3: Edible oil | W3: Rice | AA3: Maize flour | AE3: Salt | AI3: Bouillon | AM3: Additional (survey)
A4: Stratum | C4: VA | D4: Iron | E4: Folate | F4: Total | G4: VA | H4: Iron | I4: Folate | J4: Zinc | K4: VA deficiency | L4: Iron deficiency | M4: Folate insufficiency | N4: Zinc deficiency | O4: Cons | P4: Cov | Q4: g/cap | R4: Compl | S4: Cons | T4: Cov | U4: g/cap | V4: Compl | W4: Cons | X4: Cov | Y4: g/cap | Z4: Compl | AA4: Cons | AB4: Cov | AC4: g/cap | AD4: Compl | AE4: Cons | AF4: Cov | AG4: g/cap | AH4: Compl | AI4: Cons | AJ4: Cov | AK4: g/cap | AL4: Compl | AM4: CoHD (PPP$/day) | AN4: % unable to afford | AO4: MDD-W (%) | AP4: Anemia WRA (%)
A5: National | C5: =IF('Burden x Vehicle Matrix'!C9="","",'Burden x Vehicle Matrix'!C9) -> 493063 | D5: =IF('Burden x Vehicle Matrix'!D9="","",'Burden x Vehicle Matrix'!D9) -> 2306803 | E5: =IF('Burden x Vehicle Matrix'!E9="","",'Burden x Vehicle Matrix'!E9) -> 336170 | F5: =IF('Burden x Vehicle Matrix'!F9="","",'Burden x Vehicle Matrix'!F9) -> 3136036 | G5: =IF('Burden x Vehicle Matrix'!G9="","",'Burden x Vehicle Matrix'!G9) -> 0.093 | H5: =IF('Burden x Vehicle Matrix'!H9="","",'Burden x Vehicle Matrix'!H9) -> 0.569 | I5: =IF('Burden x Vehicle Matrix'!I9="","",'Burden x Vehicle Matrix'!I9) -> 0.568 | J5: =IF('Burden x Vehicle Matrix'!J9="","",'Burden x Vehicle Matrix'!J9) -> 0.744 | ... AL5: =IF('Burden x Vehicle Matrix'!AL9="","",'Burden x Vehicle Matrix'!AL9) -> n/a | AM5: 4.17 | AN5: 0.805 | AO5: 27.7 non-preg; 28.8 preg | AP5: 25.4% non-preg; 32.8% preg
A6: Zone
A7: North Central | G7: 0.282 | H7: 0.589 | I7: 0.971 | K7: 0.159 | L7: 0.092 | M7: 0.586 | N7: 0.128 | P7: 0.127 | Q7: 29 | T7: 0.782 | U7: 22.5 | X7: 0.579 | Y7: 70 | AB7: 0.844 | AC7: 53.7 | AF7: 0.994 | AG7: 3.5 | AJ7: 0.996 | AK7: 4.8
A8: North East | G8: 0.406 | H8: 0.427 | I8: 0.994 | K8: 0.329 | L8: 0.161 | M8: 0.735 | N8: 0.148 | P8: 0.443 | Q8: 28.9 | T8: 0.87 | U8: 32.7 | X8: 0.496 | Y8: 48.7 | AB8: 0.812 | AC8: 81.8 | AF8: 0.99 | AG8: 3.3 | AJ8: 0.959 | AK8: 8.5
A9: North West | G9: 0.483 | H9: 0.307 | I9: 0.984 | K9: 0.508 | L9: 0.099 | M9: 0.522 | N9: 0.354 | P9: 0.405 | Q9: 35.8 | T9: 0.935 | U9: 41.2 | X9: 0.479 | Y9: 58.4 | AB9: 0.848 | AC9: 76.1 | AF9: 0.99 | AG9: 3.7 | AJ9: 0.981 | AK9: 9.1
A10: South East | G10: 0.013 | H10: 0.463 | I10: 0.905 | K10: 0.072 | L10: 0.103 | M10: 0.206 | N10: 0.046 | P10: 0.099 | Q10: 48.2 | T10: 0.541 | U10: 17.6 | X10: 0.509 | Y10: 64.8 | AB10: 0.177 | AC10: 2.5 | AF10: 0.999 | AG10: 5.4 | AJ10: 0.968 | AK10: 3.9
A11: South South | G11: 0.038 | H11: 0.547 | I11: 0.925 | K11: 0.196 | L11: 0.125 | M11: 0.205 | N11: 0.119 | P11: 0.092 | Q11: 43 | T11: 0.459 | U11: 14.2 | X11: 0.512 | Y11: 59.8 | AB11: 0.07 | AC11: 0.4 | AF11: 1 | AG11: 4.8 | AJ11: 0.998 | AK11: 4.8
A12: South West | G12: 0.067 | H12: 0.531 | I12: 0.888 | K12: 0.198 | L12: 0.053 | M12: 0.12 | N12: 0.124 | P12: 0.287 | Q12: 55.6 | T12: 0.529 | U12: 14.7 | X12: 0.663 | Y12: 73 | AB12: 0.208 | AC12: 2.4 | AF12: 0.992 | AG12: 3.6 | AJ12: 0.982 | AK12: 2.7
A13: Wealth quintile
A14: Poorest | G14: 0.421 | H14: 0.359 | I14: 0.929 | P14: 0.191 | Q14: 16.1 | T14: 0.808 | U14: 31.6 | X14: 0.336 | Y14: 34.1 | AB14: 0.757 | AC14: 69.6 | AF14: 0.995 | AG14: 4.2 | AJ14: 0.963 | AK14: 8.4
A15: Second | G15: 0.403 | H15: 0.333 | I15: 0.98 | P15: 0.253 | Q15: 23.4 | T15: 0.787 | U15: 32.1 | X15: 0.448 | Y15: 52.4 | AB15: 0.674 | AC15: 76.7 | AF15: 0.997 | AG15: 4 | AJ15: 0.981 | AK15: 8
A16: Third | G16: 0.197 | H16: 0.5021 | I16: 0.944 | P16: 0.305 | Q16: 38.2 | T16: 0.68 | U16: 24.9 | X16: 0.546 | Y16: 60.7 | AB16: 0.525 | AC16: 43.6 | AF16: 0.995 | AG16: 3.8 | AJ16: 0.992 | AK16: 5.9
A17: Fourth | G17: 0.19 | H17: 0.528 | I17: 0.967 | P17: 0.333 | Q17: 49.3 | T17: 0.708 | U17: 23.2 | X17: 0.633 | Y17: 73.7 | AB17: 0.496 | AC17: 28.5 | AF17: 0.994 | AG17: 3.7 | AJ17: 0.986 | AK17: 4.9
A18: Wealthiest | G18: 0.12 | H18: 0.537 | I18: 0.941 | P18: 0.353 | Q18: 62.4 | T18: 0.702 | U18: 23.5 | X18: 0.676 | Y18: 79.5 | AB18: 0.366 | AC18: 12.6 | AF18: 0.985 | AG18: 3.8 | AJ18: 0.986 | AK18: 4.6

Sheet Bangladesh (stratified)
A1: Bangladesh — national (linked to cover) + stratified detail
C3: Burden — DALYs | G3: % inadequate intake | K3: MN Biomarker | O3: Wheat flour | S3: Edible oil | W3: Rice | AA3: Maize flour | AE3: Salt | AI3: Bouillon | AM3: Additional (survey)
A4: Stratum | C4: VA | D4: Iron | E4: Folate | F4: Total | G4: VA | H4: Iron | I4: Folate | J4: Zinc | K4: VA deficiency | L4: Iron deficiency | M4: Folate insufficiency | N4: Zinc deficiency | O4: Cons | P4: Cov | Q4: g/cap | R4: Compl | S4: Cons | T4: Cov | U4: g/cap | V4: Compl | W4: Cons | X4: Cov | Y4: g/cap | Z4: Compl | AA4: Cons | AB4: Cov | AC4: g/cap | AD4: Compl | AE4: Cons | AF4: Cov | AG4: g/cap | AH4: Compl | AI4: Cons | AJ4: Cov | AK4: g/cap | AL4: Compl | AM4: CoHD (PPP$/day) | AN4: % unable to afford | AO4: MDD-W (%) | AP4: Anemia WRA (%)
A5: National | C5: =IF('Burden x Vehicle Matrix'!C11="","",'Burden x Vehicle Matrix'!C11) -> 11290 | D5: =IF('Burden x Vehicle Matrix'!D11="","",'Burden x Vehicle Matrix'!D11) -> 1025044 | E5: =IF('Burden x Vehicle Matrix'!E11="","",'Burden x Vehicle Matrix'!E11) -> 168025 | F5: =IF('Burden x Vehicle Matrix'!F11="","",'Burden x Vehicle Matrix'!F11) -> 1204359 | G5: =IF('Burden x Vehicle Matrix'!G11="","",'Burden x Vehicle Matrix'!G11) -> 0.749 | H5: =IF('Burden x Vehicle Matrix'!H11="","",'Burden x Vehicle Matrix'!H11) -> 0.615 | I5: =IF('Burden x Vehicle Matrix'!I11="","",'Burden x Vehicle Matrix'!I11) -> 0.42 | J5: =IF('Burden x Vehicle Matrix'!J11="","",'Burden x Vehicle Matrix'!J11) -> 0.61 | ... AL5: =IF('Burden x Vehicle Matrix'!AL11="","",'Burden x Vehicle Matrix'!AL11) -> n/a | AM5: 4.49 | AN5: 0.444 | AO5: n/a | AP5: 0.376
A6: Division
A7: Dhaka | M7: 0.125
A8: Chattogram | M8: 0.152
A9: Rajshahi | M9: 0.049
A10: Khulna | M10: 0.029
A11: Barishal | M11: 0.111
A12: Rangpur | M12: 0.2
A13: Mymensingh | M13: 0.12
A14: Sylhet | M14: 0.091
A15: Residence
A16: Rural | L16: 0.116
A17: Urban | L17: 0.19

Sheet Indonesia (stratified)
A1: Indonesia — national (linked to cover) + stratified detail
C3: Burden — DALYs | G3: % inadequate intake | K3: MN Biomarker | O3: Wheat flour | S3: Edible oil | W3: Rice | AA3: Maize flour | AE3: Salt | AI3: Bouillon | AM3: Additional (survey)
A4: Stratum | C4: VA | D4: Iron | E4: Folate | F4: Total | G4: VA | H4: Iron | I4: Folate | J4: Zinc | K4: VA deficiency | L4: Iron deficiency | M4: Folate insufficiency | N4: Zinc deficiency | O4: Cons | P4: Cov | Q4: g/cap | R4: Compl | S4: Cons | T4: Cov | U4: g/cap | V4: Compl | W4: Cons | X4: Cov | Y4: g/cap | Z4: Compl | AA4: Cons | AB4: Cov | AC4: g/cap | AD4: Compl | AE4: Cons | AF4: Cov | AG4: g/cap | AH4: Compl | AI4: Cons | AJ4: Cov | AK4: g/cap | AL4: Compl | AM4: CoHD (PPP$/day) | AN4: % unable to afford | AO4: MDD-W (%) | AP4: Anemia WRA (%)
A5: National | C5: =IF('Burden x Vehicle Matrix'!C12="","",'Burden x Vehicle Matrix'!C12) -> 30023 | D5: =IF('Burden x Vehicle Matrix'!D12="","",'Burden x Vehicle Matrix'!D12) -> 1270248 | E5: =IF('Burden x Vehicle Matrix'!E12="","",'Burden x Vehicle Matrix'!E12) -> 147091 | F5: =IF('Burden x Vehicle Matrix'!F12="","",'Burden x Vehicle Matrix'!F12) -> 1447362 | G5: =IF('Burden x Vehicle Matrix'!G12="","",'Burden x Vehicle Matrix'!G12) -> 0.566 | H5: =IF('Burden x Vehicle Matrix'!H12="","",'Burden x Vehicle Matrix'!H12) -> 0.5329 | I5: =IF('Burden x Vehicle Matrix'!I12="","",'Burden x Vehicle Matrix'!I12) -> 0.8389 | J5: =IF('Burden x Vehicle Matrix'!J12="","",'Burden x Vehicle Matrix'!J12) -> 0.6645 | ... AL5: =IF('Burden x Vehicle Matrix'!AL12="","",'Burden x Vehicle Matrix'!AL12) -> n/a | AM5: 4.75 | AN5: 0.435 | AO5: n/a | AP5: 0.267
A6: (no stratified data available in IHME source; national only)

Sheet Pakistan (stratified)
A1: Pakistan — national (linked to cover) + stratified detail
C3: Burden — DALYs | G3: % inadequate intake | K3: MN Biomarker | O3: Wheat flour | S3: Edible oil | W3: Rice | AA3: Maize flour | AE3: Salt | AI3: Bouillon | AM3: Additional (survey)
A4: Stratum | C4: VA | D4: Iron | E4: Folate | F4: Total | G4: VA | H4: Iron | I4: Folate | J4: Zinc | K4: VA deficiency | L4: Iron deficiency | M4: Folate insufficiency | N4: Zinc deficiency | O4: Cons | P4: Cov | Q4: g/cap | R4: Compl | S4: Cons | T4: Cov | U4: g/cap | V4: Compl | W4: Cons | X4: Cov | Y4: g/cap | Z4: Compl | AA4: Cons | AB4: Cov | AC4: g/cap | AD4: Compl | AE4: Cons | AF4: Cov | AG4: g/cap | AH4: Compl | AI4: Cons | AJ4: Cov | AK4: g/cap | AL4: Compl | AM4: CoHD (PPP$/day) | AN4: % unable to afford | AO4: MDD-W (%) | AP4: Anemia WRA (%)
A5: National | C5: =IF('Burden x Vehicle Matrix'!C13="","",'Burden x Vehicle Matrix'!C13) -> 93280 | D5: =IF('Burden x Vehicle Matrix'!D13="","",'Burden x Vehicle Matrix'!D13) -> 2650954 | E5: =IF('Burden x Vehicle Matrix'!E13="","",'Burden x Vehicle Matrix'!E13) -> 202223 | F5: =IF('Burden x Vehicle Matrix'!F13="","",'Burden x Vehicle Matrix'!F13) -> 2946457 | G5: =IF('Burden x Vehicle Matrix'!G13="","",'Burden x Vehicle Matrix'!G13) -> 0.8628 | H5: =IF('Burden x Vehicle Matrix'!H13="","",'Burden x Vehicle Matrix'!H13) -> 0.923 | I5: =IF('Burden x Vehicle Matrix'!I13="","",'Burden x Vehicle Matrix'!I13) -> 0.7823 | J5: =IF('Burden x Vehicle Matrix'!J13="","",'Burden x Vehicle Matrix'!J13) -> 0.8451 | ... AL5: =IF('Burden x Vehicle Matrix'!AL13="","",'Burden x Vehicle Matrix'!AL13) -> n/a | AM5: 3.95 | AN5: 0.603 | AO5: n/a | AP5: 0.465
A6: Residence
A7: Rural | K7: 0.293 | L7: 0.187
A8: Urban | L8: 0.174
A10: Will add stratified data when available

Sheet Tanzania (stratified)
A1: Tanzania — national (linked to cover) + stratified detail
C3: Burden — DALYs | G3: % inadequate intake | K3: MN Biomarker | O3: Wheat flour | S3: Edible oil | W3: Rice | AA3: Maize flour | AE3: Salt | AI3: Bouillon | AM3: Additional (survey)
A4: Stratum | C4: VA | D4: Iron | E4: Folate | F4: Total | G4: VA | H4: Iron | I4: Folate | J4: Zinc | K4: VA deficiency | L4: Iron deficiency | M4: Folate insufficiency | N4: Zinc deficiency | O4: Cons | P4: Cov | Q4: g/cap | R4: Compl | S4: Cons | T4: Cov | U4: g/cap | V4: Compl | W4: Cons | X4: Cov | Y4: g/cap | Z4: Compl | AA4: Cons | AB4: Cov | AC4: g/cap | AD4: Compl | AE4: Cons | AF4: Cov | AG4: g/cap | AH4: Compl | AI4: Cons | AJ4: Cov | AK4: g/cap | AL4: Compl | AM4: CoHD (PPP$/day) | AN4: % unable to afford | AO4: MDD-W (%) | AP4: Anemia WRA (%)
A5: National | C5: =IF('Burden x Vehicle Matrix'!C14="","",'Burden x Vehicle Matrix'!C14) -> 31614 | D5: =IF('Burden x Vehicle Matrix'!D14="","",'Burden x Vehicle Matrix'!D14) -> 804646 | E5: =IF('Burden x Vehicle Matrix'!E14="","",'Burden x Vehicle Matrix'!E14) -> 60295 | F5: =IF('Burden x Vehicle Matrix'!F14="","",'Burden x Vehicle Matrix'!F14) -> 896555 | G5: =IF('Burden x Vehicle Matrix'!G14="","",'Burden x Vehicle Matrix'!G14) -> 0.96 | H5: =IF('Burden x Vehicle Matrix'!H14="","",'Burden x Vehicle Matrix'!H14) -> 0.65 | I5: =IF('Burden x Vehicle Matrix'!I14="","",'Burden x Vehicle Matrix'!I14) -> 0.57 | J5: =IF('Burden x Vehicle Matrix'!J14="","",'Burden x Vehicle Matrix'!J14) -> 0.69 | ... AL5: =IF('Burden x Vehicle Matrix'!AL14="","",'Burden x Vehicle Matrix'!AL14) -> n/a | AM5: 3.37 | AN5: 0.738 | AO5: n/a | AP5: 0.388
A7: Will add stratified data when available

Sheet Coverage Over Time
A1: Effective Coverage Over Time — 8 Core LSFF Countries | G1: Updated 30 Sep 2026 using the Sept 25 vehicle-data revision (Ethiopia/India/Nigeria full vehicle set; Tanzania/Pakistan/Bangladesh DFS only). Kenya and Indonesia not yet covered by this source — still pending. | N1: LAST UPDATED: 30 September 2026
A3: Edit the trend data for 2028 and 2031 on this sheet - all values used to calculate 'effective coverage' and 'reach' on the next Tab
A5: Effective coverage = Coverage x Consolidation x Compliance. 'Current' Coverage, Consolidation and Compliance are LIVE formulas linked to the 'Burden x Vehicle Matrix' tab in this same workbook, so they update automatically whenever that tab changes; these cells are locked to prevent accidental overwrites. The 2028 and 2031 columns are unlocked placeholders: enter Coverage, Consolidation and Compliance as new data becomes available, and Effective Coverage recalculates automatically. Vehicles marked n/a are not fortified / not applicable in that country as of the current data. Pakistan wheat flour compliance is reported as '<1%' in the matrix tab and will show as n/a here until a numeric value is entered.
A7: Country | B7: Vehicle | C7: Current Coverage | D7: Current Consolidation | E7: Current Compliance | F7: Current Effective Coverage | G7: 2031 Coverage | H7: 2031 Consolidation | I7: 2031 Compliance | J7: 2031 Effective Coverage | K7: 2035 Coverage | L7: 2035 Consolidation | M7: 2035 Compliance | N7: 2035 Effective Coverage
A8: Nigeria | B8: Wheat flour | C8: ='Burden x Vehicle Matrix'!P9 -> 0.28 | D8: ='Burden x Vehicle Matrix'!O9 -> 1 | E8: ='Burden x Vehicle Matrix'!R9 -> 0.63 | F8: =IF(OR(ISTEXT(C8),ISTEXT(D8),ISTEXT(E8)),"n/a",C8*D8*E8) -> 0.1764 | G8: 0.28 | H8: 1 | I8: 0.8 | J8: =IF(OR(ISTEXT(G8),ISTEXT(H8),ISTEXT(I8)),"n/a",G8*H8*I8) -> 0.224 | K8: 0.28 | L8: 1 | M8: 0.85 | N8: =IF(OR(ISTEXT(K8),ISTEXT(L8),ISTEXT(M8)),"n/a",K8*L8*M8) -> 0.238
A9: Nigeria | B9: Edible oil | C9: ='Burden x Vehicle Matrix'!T9 -> 0.903 | D9: ='Burden x Vehicle Matrix'!S9 -> 0.329 | E9: ='Burden x Vehicle Matrix'!V9 -> 0.6 | F9: =IF(OR(ISTEXT(C9),ISTEXT(D9),ISTEXT(E9)),"n/a",C9*D9*E9) -> 0.1782522 | G9: 0.903 | H9: 0.5 | I9: 0.8 | J9: =IF(OR(ISTEXT(G9),ISTEXT(H9),ISTEXT(I9)),"n/a",G9*H9*I9) -> 0.3612 | K9: 0.903 | L9: 0.5 | M9: 0.85 | N9: =IF(OR(ISTEXT(K9),ISTEXT(L9),ISTEXT(M9)),"n/a",K9*L9*M9) -> 0.383775
A10: Nigeria | B10: Rice | C10: ='Burden x Vehicle Matrix'!X9 -> 0.54 | D10: ='Burden x Vehicle Matrix'!W9 -> n/a | E10: ='Burden x Vehicle Matrix'!Z9 -> n/a | F10: =IF(OR(ISTEXT(C10),ISTEXT(D10),ISTEXT(E10)),"n/a",C10*D10*E10) -> n/a | G10: 0.54 | H10: 0.7 | I10: 0.5 | J10: =IF(OR(ISTEXT(G10),ISTEXT(H10),ISTEXT(I10)),"n/a",G10*H10*I10) -> 0.189 | K10: 0.54 | L10: 0.9 | M10: 0.85 | N10: =IF(OR(ISTEXT(K10),ISTEXT(L10),ISTEXT(M10)),"n/a",K10*L10*M10) -> 0.4131
A11: Nigeria | B11: Maize flour | C11: ='Burden x Vehicle Matrix'!AB9 -> 0.574 | D11: ='Burden x Vehicle Matrix'!AA9 -> 0.05 | E11: ='Burden x Vehicle Matrix'!AD9 -> n/a | F11: =IF(OR(ISTEXT(C11),ISTEXT(D11),ISTEXT(E11)),"n/a",C11*D11*E11) -> n/a | G11: 0.574 | H11: 0.05 | I11: n/a | J11: =IF(OR(ISTEXT(G11),ISTEXT(H11),ISTEXT(I11)),"n/a",G11*H11*I11) -> n/a | N11: =IF(OR(ISTEXT(K11),ISTEXT(L11),ISTEXT(M11)),"n/a",K11*L11*M11) -> 0
A12: Nigeria | B12: Salt | C12: ='Burden x Vehicle Matrix'!AF9 -> 0.992 | D12: ='Burden x Vehicle Matrix'!AE9 -> n/a | E12: ='Burden x Vehicle Matrix'!AH9 -> n/a | F12: =IF(OR(ISTEXT(C12),ISTEXT(D12),ISTEXT(E12)),"n/a",C12*D12*E12) -> n/a | G12: 0.992 | H12: 0.9 | I12: 0.92 | J12: =IF(OR(ISTEXT(G12),ISTEXT(H12),ISTEXT(I12)),"n/a",G12*H12*I12) -> 0.821376 | K12: 0.992 | L12: 0.9 | M12: 0.95 | N12: =IF(OR(ISTEXT(K12),ISTEXT(L12),ISTEXT(M12)),"n/a",K12*L12*M12) -> 0.84816
A13: Nigeria | B13: Bouillon | C13: ='Burden x Vehicle Matrix'!AJ9 -> 0.981 | D13: ='Burden x Vehicle Matrix'!AI9 -> n/a | E13: ='Burden x Vehicle Matrix'!AL9 -> n/a | F13: =IF(OR(ISTEXT(C13),ISTEXT(D13),ISTEXT(E13)),"n/a",C13*D13*E13) -> n/a | G13: 0.981 | H13: 0.7 | I13: 0.7 | J13: =IF(OR(ISTEXT(G13),ISTEXT(H13),ISTEXT(I13)),"n/a",G13*H13*I13) -> 0.48069 | K13: 0.981 | L13: 1 | M13: 0.85 | N13: =IF(OR(ISTEXT(K13),ISTEXT(L13),ISTEXT(M13)),"n/a",K13*L13*M13) -> 0.83385
A14: Ethiopia | B14: Wheat flour | C14: ='Burden x Vehicle Matrix'!P6 -> 0.4 | D14: ='Burden x Vehicle Matrix'!O6 -> 0.6 | E14: ='Burden x Vehicle Matrix'!R6 -> 0.4 | F14: =IF(OR(ISTEXT(C14),ISTEXT(D14),ISTEXT(E14)),"n/a",C14*D14*E14) -> 0.096 | G14: 0.4 | H14: 0.75 | I14: 0.8 | J14: =IF(OR(ISTEXT(G14),ISTEXT(H14),ISTEXT(I14)),"n/a",G14*H14*I14) -> 0.24 | K14: 0.4 | L14: 0.75 | M14: 0.85 | N14: =IF(OR(ISTEXT(K14),ISTEXT(L14),ISTEXT(M14)),"n/a",K14*L14*M14) -> 0.255
A15: Ethiopia | B15: Edible oil | C15: ='Burden x Vehicle Matrix'!T6 -> 0.9 | D15: ='Burden x Vehicle Matrix'!S6 -> 1 | E15: ='Burden x Vehicle Matrix'!V6 -> 0.5 | F15: =IF(OR(ISTEXT(C15),ISTEXT(D15),ISTEXT(E15)),"n/a",C15*D15*E15) -> 0.45 | G15: 0.9 | H15: 1 | I15: 0.8 | J15: =IF(OR(ISTEXT(G15),ISTEXT(H15),ISTEXT(I15)),"n/a",G15*H15*I15) -> 0.72 | K15: 0.9 | L15: 1 | M15: 0.85 | N15: =IF(OR(ISTEXT(K15),ISTEXT(L15),ISTEXT(M15)),"n/a",K15*L15*M15) -> 0.765
A16: Ethiopia | B16: Rice | C16: ='Burden x Vehicle Matrix'!X6 -> n/a | D16: ='Burden x Vehicle Matrix'!W6 -> n/a | E16: ='Burden x Vehicle Matrix'!Z6 -> n/a | F16: =IF(OR(ISTEXT(C16),ISTEXT(D16),ISTEXT(E16)),"n/a",C16*D16*E16) -> n/a | J16: =IF(OR(ISTEXT(G16),ISTEXT(H16),ISTEXT(I16)),"n/a",G16*H16*I16) -> 0 | N16: =IF(OR(ISTEXT(K16),ISTEXT(L16),ISTEXT(M16)),"n/a",K16*L16*M16) -> 0
A17: Ethiopia | B17: Maize flour | C17: ='Burden x Vehicle Matrix'!AB6 -> n/a | D17: ='Burden x Vehicle Matrix'!AA6 -> n/a | E17: ='Burden x Vehicle Matrix'!AD6 -> n/a | F17: =IF(OR(ISTEXT(C17),ISTEXT(D17),ISTEXT(E17)),"n/a",C17*D17*E17) -> n/a | J17: =IF(OR(ISTEXT(G17),ISTEXT(H17),ISTEXT(I17)),"n/a",G17*H17*I17) -> 0 | N17: =IF(OR(ISTEXT(K17),ISTEXT(L17),ISTEXT(M17)),"n/a",K17*L17*M17) -> 0
A18: Ethiopia | B18: Salt | C18: ='Burden x Vehicle Matrix'!AF6 -> 0.98 | D18: ='Burden x Vehicle Matrix'!AE6 -> 0.95 | E18: ='Burden x Vehicle Matrix'!AH6 -> 0 | F18: =IF(OR(ISTEXT(C18),ISTEXT(D18),ISTEXT(E18)),"n/a",C18*D18*E18) -> 0 | G18: 0.98 | H18: 0.95 | I18: 0.8 | J18: =IF(OR(ISTEXT(G18),ISTEXT(H18),ISTEXT(I18)),"n/a",G18*H18*I18) -> 0.7448 | K18: 0.98 | L18: 0.95 | M18: 0.85 | N18: =IF(OR(ISTEXT(K18),ISTEXT(L18),ISTEXT(M18)),"n/a",K18*L18*M18) -> 0.79135
A19: Ethiopia | B19: Bouillon | C19: ='Burden x Vehicle Matrix'!AJ6 -> n/a | D19: ='Burden x Vehicle Matrix'!AI6 -> n/a | E19: ='Burden x Vehicle Matrix'!AL6 -> n/a | F19: =IF(OR(ISTEXT(C19),ISTEXT(D19),ISTEXT(E19)),"n/a",C19*D19*E19) -> n/a | J19: =IF(OR(ISTEXT(G19),ISTEXT(H19),ISTEXT(I19)),"n/a",G19*H19*I19) -> 0 | N19: =IF(OR(ISTEXT(K19),ISTEXT(L19),ISTEXT(M19)),"n/a",K19*L19*M19) -> 0
A20: India | B20: Wheat flour | C20: ='Burden x Vehicle Matrix'!P7 -> 0.927 | D20: ='Burden x Vehicle Matrix'!O7 -> 0.15 | E20: 0.5 | F20: =IF(OR(ISTEXT(C20),ISTEXT(D20),ISTEXT(E20)),"n/a",C20*D20*E20) -> 0.069525 | G20: 0.927 | H20: 0.15 | I20: 0.5 | J20: =IF(OR(ISTEXT(G20),ISTEXT(H20),ISTEXT(I20)),"n/a",G20*H20*I20) -> 0.069525 | K20: 0.927 | L20: 0.15 | M20: 0.85 | N20: =IF(OR(ISTEXT(K20),ISTEXT(L20),ISTEXT(M20)),"n/a",K20*L20*M20) -> 0.1181925
A21: India | B21: Edible oil | C21: ='Burden x Vehicle Matrix'!T7 -> 0.999 | D21: ='Burden x Vehicle Matrix'!S7 -> 0.74 | E21: ='Burden x Vehicle Matrix'!V7 -> 0.5 | F21: =IF(OR(ISTEXT(C21),ISTEXT(D21),ISTEXT(E21)),"n/a",C21*D21*E21) -> 0.36963 | G21: 0.999 | H21: 0.625 | I21: 0.75 | J21: =IF(OR(ISTEXT(G21),ISTEXT(H21),ISTEXT(I21)),"n/a",G21*H21*I21) -> 0.46828125 | K21: 0.999 | L21: 0.625 | M21: 0.85 | N21: =IF(OR(ISTEXT(K21),ISTEXT(L21),ISTEXT(M21)),"n/a",K21*L21*M21) -> 0.53071875
A22: India | B22: Rice | C22: ='Burden x Vehicle Matrix'!X7 -> 0.988 | D22: ='Burden x Vehicle Matrix'!W7 -> 0.5 | E22: ='Burden x Vehicle Matrix'!Z7 -> 0.5 | F22: =IF(OR(ISTEXT(C22),ISTEXT(D22),ISTEXT(E22)),"n/a",C22*D22*E22) -> 0.247 | G22: 0.988 | H22: 0.480645 | I22: 0.75 | J22: =IF(OR(ISTEXT(G22),ISTEXT(H22),ISTEXT(I22)),"n/a",G22*H22*I22) -> 0.35615794 | K22: 0.988 | L22: 0.528711 | M22: 0.85 | N22: =IF(OR(ISTEXT(K22),ISTEXT(L22),ISTEXT(M22)),"n/a",K22*L22*M22) -> 0.4440115
A23: India | B23: Maize flour | C23: ='Burden x Vehicle Matrix'!AB7 -> n/a | D23: ='Burden x Vehicle Matrix'!AA7 -> n/a | E23: ='Burden x Vehicle Matrix'!AD7 -> n/a | F23: =IF(OR(ISTEXT(C23),ISTEXT(D23),ISTEXT(E23)),"n/a",C23*D23*E23) -> n/a | J23: =IF(OR(ISTEXT(G23),ISTEXT(H23),ISTEXT(I23)),"n/a",G23*H23*I23) -> 0 | N23: =IF(OR(ISTEXT(K23),ISTEXT(L23),ISTEXT(M23)),"n/a",K23*L23*M23) -> 0
A24: India | B24: Salt | C24: ='Burden x Vehicle Matrix'!AF7 -> 1 | D24: ='Burden x Vehicle Matrix'!AE7 -> 0.035 | E24: ='Burden x Vehicle Matrix'!AH7 -> 0.33 | F24: =IF(OR(ISTEXT(C24),ISTEXT(D24),ISTEXT(E24)),"n/a",C24*D24*E24) -> 0.01155 | G24: 1 | H24: 0.19639713 | I24: 0.5 | J24: =IF(OR(ISTEXT(G24),ISTEXT(H24),ISTEXT(I24)),"n/a",G24*H24*I24) -> 0.098198564 | K24: 1 | L24: 0.33184342 | M24: 0.85 | N24: =IF(OR(ISTEXT(K24),ISTEXT(L24),ISTEXT(M24)),"n/a",K24*L24*M24) -> 0.28206691
A25: India | B25: Bouillon | C25: ='Burden x Vehicle Matrix'!AJ7 -> n/a | D25: ='Burden x Vehicle Matrix'!AI7 -> n/a | E25: ='Burden x Vehicle Matrix'!AL7 -> n/a | F25: =IF(OR(ISTEXT(C25),ISTEXT(D25),ISTEXT(E25)),"n/a",C25*D25*E25) -> n/a | J25: =IF(OR(ISTEXT(G25),ISTEXT(H25),ISTEXT(I25)),"n/a",G25*H25*I25) -> 0 | N25: =IF(OR(ISTEXT(K25),ISTEXT(L25),ISTEXT(M25)),"n/a",K25*L25*M25) -> 0
A26: Kenya | B26: Wheat flour | C26: ='Burden x Vehicle Matrix'!P8 -> 0.47 | D26: ='Burden x Vehicle Matrix'!O8 -> 0.95 | E26: ='Burden x Vehicle Matrix'!R8 -> 0.6 | F26: =IF(OR(ISTEXT(C26),ISTEXT(D26),ISTEXT(E26)),"n/a",C26*D26*E26) -> 0.2679 | I26: 0.85 | J26: =IF(OR(ISTEXT(G26),ISTEXT(H26),ISTEXT(I26)),"n/a",G26*H26*I26) -> 0 | M26: 0.85 | N26: =IF(OR(ISTEXT(K26),ISTEXT(L26),ISTEXT(M26)),"n/a",K26*L26*M26) -> 0
A27: Kenya | B27: Edible oil | C27: ='Burden x Vehicle Matrix'!T8 -> 0.69 | D27: ='Burden x Vehicle Matrix'!S8 -> 0.95 | E27: ='Burden x Vehicle Matrix'!V8 -> 0.55 | F27: =IF(OR(ISTEXT(C27),ISTEXT(D27),ISTEXT(E27)),"n/a",C27*D27*E27) -> 0.360525 | I27: 0.85 | J27: =IF(OR(ISTEXT(G27),ISTEXT(H27),ISTEXT(I27)),"n/a",G27*H27*I27) -> 0 | M27: 0.85 | N27: =IF(OR(ISTEXT(K27),ISTEXT(L27),ISTEXT(M27)),"n/a",K27*L27*M27) -> 0
A28: Kenya | B28: Rice | C28: ='Burden x Vehicle Matrix'!X8 -> n/a | D28: ='Burden x Vehicle Matrix'!W8 -> 0.74 | E28: ='Burden x Vehicle Matrix'!Z8 -> n/a | F28: =IF(OR(ISTEXT(C28),ISTEXT(D28),ISTEXT(E28)),"n/a",C28*D28*E28) -> n/a | I28: 0.03 | J28: =IF(OR(ISTEXT(G28),ISTEXT(H28),ISTEXT(I28)),"n/a",G28*H28*I28) -> 0 | M28: 0.05 | N28: =IF(OR(ISTEXT(K28),ISTEXT(L28),ISTEXT(M28)),"n/a",K28*L28*M28) -> 0
A29: Kenya | B29: Maize flour | C29: ='Burden x Vehicle Matrix'!AB8 -> 0.74 | D29: ='Burden x Vehicle Matrix'!AA8 -> 0.5 | E29: ='Burden x Vehicle Matrix'!AD8 -> 0.64 | F29: =IF(OR(ISTEXT(C29),ISTEXT(D29),ISTEXT(E29)),"n/a",C29*D29*E29) -> 0.2368 | I29: 0.7 | J29: =IF(OR(ISTEXT(G29),ISTEXT(H29),ISTEXT(I29)),"n/a",G29*H29*I29) -> 0 | M29: 0.7 | N29: =IF(OR(ISTEXT(K29),ISTEXT(L29),ISTEXT(M29)),"n/a",K29*L29*M29) -> 0
A30: Kenya | B30: Salt | C30: ='Burden x Vehicle Matrix'!AF8 -> n/a | D30: ='Burden x Vehicle Matrix'!AE8 -> n/a | E30: ='Burden x Vehicle Matrix'!AH8 -> n/a | F30: =IF(OR(ISTEXT(C30),ISTEXT(D30),ISTEXT(E30)),"n/a",C30*D30*E30) -> n/a | J30: =IF(OR(ISTEXT(G30),ISTEXT(H30),ISTEXT(I30)),"n/a",G30*H30*I30) -> 0 | N30: =IF(OR(ISTEXT(K30),ISTEXT(L30),ISTEXT(M30)),"n/a",K30*L30*M30) -> 0
A31: Kenya | B31: Bouillon | C31: ='Burden x Vehicle Matrix'!AJ8 -> n/a | D31: ='Burden x Vehicle Matrix'!AI8 -> n/a | E31: ='Burden x Vehicle Matrix'!AL8 -> n/a | F31: =IF(OR(ISTEXT(C31),ISTEXT(D31),ISTEXT(E31)),"n/a",C31*D31*E31) -> n/a | J31: =IF(OR(ISTEXT(G31),ISTEXT(H31),ISTEXT(I31)),"n/a",G31*H31*I31) -> 0 | N31: =IF(OR(ISTEXT(K31),ISTEXT(L31),ISTEXT(M31)),"n/a",K31*L31*M31) -> 0
A32: Bangladesh | B32: Wheat flour | C32: ='Burden x Vehicle Matrix'!P11 -> 0.61 | D32: ='Burden x Vehicle Matrix'!O11 -> 0.49 | E32: ='Burden x Vehicle Matrix'!R11 -> 0.01 | F32: =IF(OR(ISTEXT(C32),ISTEXT(D32),ISTEXT(E32)),"n/a",C32*D32*E32) -> 0.002989 | I32: 0.02 | J32: =IF(OR(ISTEXT(G32),ISTEXT(H32),ISTEXT(I32)),"n/a",G32*H32*I32) -> 0 | M32: 0.1 | N32: =IF(OR(ISTEXT(K32),ISTEXT(L32),ISTEXT(M32)),"n/a",K32*L32*M32) -> 0
A33: Bangladesh | B33: Edible oil | C33: ='Burden x Vehicle Matrix'!T11 -> 1 | D33: ='Burden x Vehicle Matrix'!S11 -> 0.34 | E33: ='Burden x Vehicle Matrix'!V11 -> 0.98 | F33: =IF(OR(ISTEXT(C33),ISTEXT(D33),ISTEXT(E33)),"n/a",C33*D33*E33) -> 0.3332 | I33: 0.98 | J33: =IF(OR(ISTEXT(G33),ISTEXT(H33),ISTEXT(I33)),"n/a",G33*H33*I33) -> 0 | M33: 0.98 | N33: =IF(OR(ISTEXT(K33),ISTEXT(L33),ISTEXT(M33)),"n/a",K33*L33*M33) -> 0
A34: Bangladesh | B34: Rice | C34: ='Burden x Vehicle Matrix'!X11 -> 1 | D34: ='Burden x Vehicle Matrix'!W11 -> n/a | E34: ='Burden x Vehicle Matrix'!Z11 -> 0.03 | F34: =IF(OR(ISTEXT(C34),ISTEXT(D34),ISTEXT(E34)),"n/a",C34*D34*E34) -> n/a | I34: 0.05 | J34: =IF(OR(ISTEXT(G34),ISTEXT(H34),ISTEXT(I34)),"n/a",G34*H34*I34) -> 0 | M34: 0.1 | N34: =IF(OR(ISTEXT(K34),ISTEXT(L34),ISTEXT(M34)),"n/a",K34*L34*M34) -> 0
A35: Bangladesh | B35: Maize flour | C35: ='Burden x Vehicle Matrix'!AB11 -> n/a | D35: ='Burden x Vehicle Matrix'!AA11 -> 0 | E35: ='Burden x Vehicle Matrix'!AD11 -> n/a | F35: =IF(OR(ISTEXT(C35),ISTEXT(D35),ISTEXT(E35)),"n/a",C35*D35*E35) -> n/a | J35: =IF(OR(ISTEXT(G35),ISTEXT(H35),ISTEXT(I35)),"n/a",G35*H35*I35) -> 0 | N35: =IF(OR(ISTEXT(K35),ISTEXT(L35),ISTEXT(M35)),"n/a",K35*L35*M35) -> 0
A36: Bangladesh | B36: Salt | C36: ='Burden x Vehicle Matrix'!AF11 -> 1 | D36: ='Burden x Vehicle Matrix'!AE11 -> n/a | E36: ='Burden x Vehicle Matrix'!AH11 -> n/a | F36: =IF(OR(ISTEXT(C36),ISTEXT(D36),ISTEXT(E36)),"n/a",C36*D36*E36) -> n/a | G36: 0.98 | H36: 1 | J36: 0.76 | K36: 0.98 | L36: 1 | N36: 0.85
A37: Bangladesh | B37: Bouillon | C37: ='Burden x Vehicle Matrix'!AJ11 -> n/a | D37: ='Burden x Vehicle Matrix'!AI11 -> 0 | E37: ='Burden x Vehicle Matrix'!AL11 -> n/a | F37: =IF(OR(ISTEXT(C37),ISTEXT(D37),ISTEXT(E37)),"n/a",C37*D37*E37) -> n/a | J37: =IF(OR(ISTEXT(G37),ISTEXT(H37),ISTEXT(I37)),"n/a",G37*H37*I37) -> 0 | N37: =IF(OR(ISTEXT(K37),ISTEXT(L37),ISTEXT(M37)),"n/a",K37*L37*M37) -> 0
A38: Indonesia | B38: Wheat flour | C38: ='Burden x Vehicle Matrix'!P12 -> 0.61 | D38: ='Burden x Vehicle Matrix'!O12 -> 1 | E38: ='Burden x Vehicle Matrix'!R12 -> 0.9 | F38: =IF(OR(ISTEXT(C38),ISTEXT(D38),ISTEXT(E38)),"n/a",C38*D38*E38) -> 0.549 | I38: 0.95 | J38: =IF(OR(ISTEXT(G38),ISTEXT(H38),ISTEXT(I38)),"n/a",G38*H38*I38) -> 0 | M38: 0.95 | N38: =IF(OR(ISTEXT(K38),ISTEXT(L38),ISTEXT(M38)),"n/a",K38*L38*M38) -> 0
A39: Indonesia | B39: Edible oil | C39: ='Burden x Vehicle Matrix'!T12 -> 0.99 | D39: ='Burden x Vehicle Matrix'!S12 -> 0.57 | E39: ='Burden x Vehicle Matrix'!V12 -> 0.85 | F39: =IF(OR(ISTEXT(C39),ISTEXT(D39),ISTEXT(E39)),"n/a",C39*D39*E39) -> 0.479655 | I39: 0.85 | J39: =IF(OR(ISTEXT(G39),ISTEXT(H39),ISTEXT(I39)),"n/a",G39*H39*I39) -> 0 | M39: 0.85 | N39: =IF(OR(ISTEXT(K39),ISTEXT(L39),ISTEXT(M39)),"n/a",K39*L39*M39) -> 0
A40: Indonesia | B40: Rice | C40: ='Burden x Vehicle Matrix'!X12 -> 0 | D40: ='Burden x Vehicle Matrix'!W12 -> n/a | E40: ='Burden x Vehicle Matrix'!Z12 -> 0.04 | F40: =IF(OR(ISTEXT(C40),ISTEXT(D40),ISTEXT(E40)),"n/a",C40*D40*E40) -> n/a | I40: 0.1 | J40: =IF(OR(ISTEXT(G40),ISTEXT(H40),ISTEXT(I40)),"n/a",G40*H40*I40) -> 0 | M40: 0.2 | N40: =IF(OR(ISTEXT(K40),ISTEXT(L40),ISTEXT(M40)),"n/a",K40*L40*M40) -> 0
A41: Indonesia | B41: Maize flour | C41: ='Burden x Vehicle Matrix'!AB12 -> n/a | D41: ='Burden x Vehicle Matrix'!AA12 -> 0 | E41: ='Burden x Vehicle Matrix'!AD12 -> n/a | F41: =IF(OR(ISTEXT(C41),ISTEXT(D41),ISTEXT(E41)),"n/a",C41*D41*E41) -> n/a | J41: =IF(OR(ISTEXT(G41),ISTEXT(H41),ISTEXT(I41)),"n/a",G41*H41*I41) -> 0 | N41: =IF(OR(ISTEXT(K41),ISTEXT(L41),ISTEXT(M41)),"n/a",K41*L41*M41) -> 0
A42: Indonesia | B42: Salt | C42: ='Burden x Vehicle Matrix'!AF12 -> n/a | D42: ='Burden x Vehicle Matrix'!AE12 -> n/a | E42: ='Burden x Vehicle Matrix'!AH12 -> n/a | F42: =IF(OR(ISTEXT(C42),ISTEXT(D42),ISTEXT(E42)),"n/a",C42*D42*E42) -> n/a | J42: =IF(OR(ISTEXT(G42),ISTEXT(H42),ISTEXT(I42)),"n/a",G42*H42*I42) -> 0 | N42: =IF(OR(ISTEXT(K42),ISTEXT(L42),ISTEXT(M42)),"n/a",K42*L42*M42) -> 0
